Workbook

Sheet グローバルリゾート全体収支
A1: 2026年度グローバルリゾート/レジデンス 全体 収支報告
A3: 部門 | B3: 施設 | C3: 内訳 | E3: 1月 | F3: 2月 | G3: 3月 | H3: 4月 | I3: 5月 | J3: 6月 | K3: 7月 | L3: 8月 | M3: 9月 | N3: 10月 | O3: 11月 | P3: 12月 | Q3: 計
A4: ホテル | B4: デルーネ ビュー 本川 天神 玖波 | C4: 売上 | D4: de Lune | E4: =ホテル部門→!B17 -> 6712201 | F4: =ホテル部門→!C17 -> 6486426 | G4: =ホテル部門→!D17 -> 9961885 | H4: =ホテル部門→!E17 -> 8310821 | I4: =ホテル部門→!F17 -> 9884840 | J4: =ホテル部門→!G17 -> 4996865 | K4: =ホテル部門→!H17 -> 1386977 | L4: =ホテル部門→!I17 -> 2069324 | ... P4: =ホテル部門→!M17 -> 147350 | Q4: =SUM(E4:P4) -> 51711522
D5: VIEW | E5: =ホテル部門→!B40 -> 1319475 | F5: =ホテル部門→!C40 -> 1757661 | G5: =ホテル部門→!D40 -> 2882218 | H5: =ホテル部門→!E40 -> 2904045 | I5: =ホテル部門→!F40 -> 3017659 | J5: =ホテル部門→!G40 -> 2196076 | K5: =ホテル部門→!H40 -> 492989 | L5: =ホテル部門→!I40 -> 716260 | ... P5: =ホテル部門→!M40 -> 0 | Q5: =SUM(E5:P5) -> 16024147
D6: 本川 | E6: =ホテル部門→!B59 -> 638232 | F6: =ホテル部門→!C59 -> 1033872 | G6: =ホテル部門→!D59 -> 1357093 | H6: =ホテル部門→!E59 -> 1955058 | I6: =ホテル部門→!F59 -> 1887446 | J6: =ホテル部門→!G59 -> 276276 | K6: =ホテル部門→!H59 -> 417182 | L6: =ホテル部門→!I59 -> 435946 | ... P6: =ホテル部門→!M59 -> 0 | Q6: =SUM(E6:P6) -> 8365293
D7: 天神 | E7: =ホテル部門→!B73 -> 100300 | F7: =ホテル部門→!C73 -> 108270 | G7: =ホテル部門→!D73 -> 189640 | H7: =ホテル部門→!E73 -> 56700 | I7: =ホテル部門→!F73 -> 289480 | J7: =ホテル部門→!G73 -> 72400 | K7: =ホテル部門→!H73 -> 16200 | L7: =ホテル部門→!I73 -> 0 | ... P7: =ホテル部門→!M73 -> 0 | Q7: =SUM(E7:P7) -> 832990
D8: 玖波 | E8: =ホテル部門→!B87 -> 138750 | F8: =ホテル部門→!C87 -> 406500 | G8: =ホテル部門→!D87 -> 794600 | H8: =ホテル部門→!E87 -> 331500 | I8: =ホテル部門→!F87 -> 303810 | J8: =ホテル部門→!G87 -> 190750 | K8: =ホテル部門→!H87 -> 96000 | L8: =ホテル部門→!I87 -> 35000 | ... P8: =ホテル部門→!M87 -> 0 | Q8: =SUM(E8:P8) -> 2336510
D9: 売上合計 | E9: =SUM(E4:E8) -> 8908958 | F9: =SUM(F4:F8) -> 9792729 | G9: =SUM(G4:G8) -> 15185436 | H9: =SUM(H4:H8) -> 13558124 | I9: =SUM(I4:I8) -> 15383235 | J9: =SUM(J4:J8) -> 7732367 | K9: =SUM(K4:K8) -> 2409348 | L9: =SUM(L4:L8) -> 3256530 | ... Q9: =SUM(Q4:Q8) -> 79270462
C10: 経費 | D10: de Lune | E10: 1532400 | F10: 1262197
D11: VIEW | E11: 257028 | F11: 291700
D12: 本川 | E12: 104577 | F12: 149077
D13: 天神 | E13: 16596 | F13: 1005193
D14: 玖波
D15: リゾート | E15: 9211951 | F15: 27179756 | Q15: =SUM(E15:P15) -> 36391707
D16: 経費合計 | E16: =SUM(E10:E15) -> 11122552 | F16: =SUM(F10:F15) -> 29887923 | G16: =SUM(G10:G15) -> 0 | H16: =SUM(H10:H15) -> 0 | I16: =SUM(I10:I15) -> 0 | J16: =SUM(J10:J15) -> 0 | K16: =SUM(K10:K15) -> 0 | L16: =SUM(L10:L15) -> 0 | ... Q16: =SUM(Q10:Q15) -> 36391707
C17: 差引収支 | E17: =E9-E16 -> -2213594 | F17: =F9-F16 -> -20095194 | G17: =G9-G16 -> 15185436 | H17: =H9-H16 -> 13558124 | I17: =I9-I16 -> 15383235 | J17: =J9-J16 -> 7732367 | K17: =K9-K16 -> 2409348 | L17: =L9-L16 -> 3256530 | ... P17: =P9-P16 -> 147350 | Q17: =SUM(Q4:Q8)-SUM(Q10:Q15) -> 42878755
B18: 弥山 | C18: 売上 | E18: =弥山!B4 -> 2906901 | F18: =弥山!C4 -> 4965898 | G18: =弥山!D4 -> 6807485 | H18: =弥山!E4 -> 4004248 | I18: =弥山!F4 -> 6175495 | J18: =弥山!G4 -> 2105073 | K18: =弥山!H4 -> 1056902 | L18: =弥山!I4 -> 1697508 | ... P18: =弥山!M4 -> 20000 | Q18: =SUM(E18:P18) -> 31554666
C19: 経費 | E19: 2280539 | F19: 3403055 | Q19: =SUM(E19:P19) -> 5683594
C20: 差引収支 | E20: =E18-E19 -> 626362 | F20: =F18-F19 -> 1562843 | G20: =G18-G19 -> 6807485 | H20: =H18-H19 -> 4004248 | I20: =I18-I19 -> 6175495 | J20: =J18-J19 -> 2105073 | K20: =K18-K19 -> 1056902 | L20: =L18-L19 -> 1697508 | ... Q20: =Q18-Q19 -> 25871072
B21: 温井 | C21: 売上 | E21: =温井!D3 -> 7428554 | F21: =温井!E3 -> 7562227 | G21: =温井!F3 -> 3799283 | H21: =温井!G3 -> 2330934 | I21: =温井!H3 -> 4784742 | J21: =温井!I3 -> 2087208 | K21: =温井!J3 -> 1038480 | L21: =温井!K3 -> 1446637 | ... P21: =温井!O3 -> 0 | Q21: =SUM(E21:P21) -> 30755817
C22: 経費 | E22: 8916981 | F22: 7426432 | Q22: =SUM(E22:P22) -> 16343413
C23: 差引収支 | E23: =E21-E22 -> -1488427 | F23: =F21-F22 -> 135795 | G23: =G21-G22 -> 3799283 | H23: =H21-H22 -> 2330934 | I23: =I21-I22 -> 4784742 | J23: =J21-J22 -> 2087208 | K23: =K21-K22 -> 1038480 | L23: =L21-L22 -> 1446637 | ... Q23: =Q21-Q22 -> 14412404
B24: いこいの村 | C24: 売上 | E24: =いこいの村!D3 -> 8292624 | F24: =いこいの村!E3 -> 8535484 | G24: =いこいの村!F3 -> 4929332 | H24: =いこいの村!G3 -> 6092392 | I24: =いこいの村!H3 -> 3646914 | J24: =いこいの村!I3 -> 1303991 | K24: =いこいの村!J3 -> 1869506 | L24: =いこいの村!K3 -> 948336 | ... P24: =いこいの村!O3 -> 0 | Q24: =SUM(E24:P24) -> 37827062
C25: 経費 | E25: =いこいの村!C87 -> 5778007 | F25: =いこいの村!D87 -> 5913951 | G25: =いこいの村!E87 -> 0 | H25: =いこいの村!F87 -> 0 | I25: =いこいの村!G87 -> 0 | J25: =いこいの村!H87 -> 0 | K25: =いこいの村!I87 -> 0 | L25: =いこいの村!J87 -> 0 | ... P25: =いこいの村!N87 -> 0 | Q25: =SUM(E25:P25) -> 11691958
C26: 差引収支 | E26: =E24-E25 -> 2514617 | F26: =F24-F25 -> 2621533 | G26: =G24-G25 -> 4929332 | H26: =H24-H25 -> 6092392 | I26: =I24-I25 -> 3646914 | J26: =J24-J25 -> 1303991 | K26: =K24-K25 -> 1869506 | L26: =L24-L25 -> 948336 | ... Q26: =Q24-Q25 -> 26135104
A27: マンスリー | B27: TAKAYA SAIJO壱番館 SIJO弐番館 Otake | C27: 売上 | D27: TAKAYA | E27: =マンスリー部門!B4 -> 251000 | F27: =マンスリー部門!C4 -> 308000 | G27: =マンスリー部門!D4 -> 651000 | H27: =マンスリー部門!E4 -> 455000 | I27: =マンスリー部門!F4 -> 272000 | J27: =マンスリー部門!G4 -> 195000 | K27: =マンスリー部門!H4 -> 78000 | L27: =マンスリー部門!I4 -> 120000 | ... P27: =マンスリー部門!M4 -> 0 | Q27: =SUM(E27:P27) -> 2330000
D28: 壱番館 | E28: =マンスリー部門!B19 -> 155000 | F28: =マンスリー部門!C19 -> 110500 | G28: =マンスリー部門!D19 -> 66000 | H28: =マンスリー部門!E19 -> 101400 | I28: =マンスリー部門!F19 -> 24000 | J28: =マンスリー部門!G19 -> 45000 | K28: =マンスリー部門!H19 -> 0 | L28: =マンスリー部門!I19 -> 0 | ... P28: =マンスリー部門!M19 -> 0 | Q28: =SUM(E28:P28) -> 501900
D29: 弐番館 | E29: =マンスリー部門!B34 -> 0 | F29: =マンスリー部門!C34 -> 42500 | G29: =マンスリー部門!D34 -> 0 | H29: =マンスリー部門!E34 -> 90000 | I29: =マンスリー部門!F34 -> 93000 | J29: =マンスリー部門!G34 -> 46000 | K29: =マンスリー部門!H34 -> 57000 | L29: =マンスリー部門!I34 -> 75000 | ... P29: =マンスリー部門!M34 -> 0 | Q29: =SUM(E29:P29) -> 403500
D30: Otake | E30: =マンスリー部門!B49 -> 77500 | F30: =マンスリー部門!C49 -> 77500 | G30: =マンスリー部門!D49 -> 80000 | H30: =マンスリー部門!E49 -> 105000 | I30: =マンスリー部門!F49 -> 77500 | J30: =マンスリー部門!G49 -> 72500 | K30: =マンスリー部門!H49 -> 0 | L30: =マンスリー部門!I49 -> 0 | ... P30: =マンスリー部門!M49 -> 0 | Q30: =SUM(E30:P30) -> 490000
D31: 合計 | E31: =SUM(E27:E30) -> 483500 | F31: =SUM(F27:F30) -> 538500 | G31: =SUM(G27:G30) -> 797000 | H31: =SUM(H27:H30) -> 751400 | I31: =SUM(I27:I30) -> 466500 | J31: =SUM(J27:J30) -> 358500 | K31: =SUM(K27:K30) -> 135000 | L31: =SUM(L27:L30) -> 195000 | ... Q31: =SUM(Q27:Q30) -> 3725400
C32: 経費 | Q32: =SUM(E32:P32) -> 0
C33: 差引収支 | E33: =E31-E32 -> 483500 | F33: =F31-F32 -> 538500 | G33: =G31-G32 -> 797000 | H33: =H31-H32 -> 751400 | I33: =I31-I32 -> 466500 | J33: =J31-J32 -> 358500 | K33: =K31-K32 -> 135000 | L33: =L31-L32 -> 195000 | ... P33: =P31-P32 -> 0 | Q33: =SUM(Q28:Q30)-Q32 -> 1395400
A34: 指定管理 | B34: 竹原（ﾚｽﾄﾗﾝ含む） | C34: 売上 | E34: =竹原!D3 -> 1247037 | F34: =竹原!E3 -> 1238472 | G34: =竹原!F3 -> 1370148 | H34: =竹原!G3 -> 1202444 | I34: =竹原!H3 -> 789000 | J34: =竹原!I3 -> 683000 | K34: =竹原!J3 -> 683000 | L34: =竹原!K3 -> 683000 | ... P34: =竹原!O3 -> 683000 | Q34: =SUM(E34:P34) -> 10628101
C35: 経費 | E35: =竹原!D48 -> 1603560 | F35: =竹原!E48 -> 1713674 | G35: =竹原!F48 -> 0 | H35: =竹原!G48 -> 0 | I35: =竹原!H48 -> 0 | J35: =竹原!I48 -> 0 | K35: =竹原!J48 -> 0 | L35: =竹原!K48 -> 0 | ... P35: =竹原!O48 -> 0 | Q35: =SUM(E35:P35) -> 3317234
C36: 差引収支 | E36: =E34-E35 -> -356523 | F36: =F34-F35 -> -475202 | G36: =G34-G35 -> 1370148 | H36: =H34-H35 -> 1202444 | I36: =I34-I35 -> 789000 | J36: =J34-J35 -> 683000 | K36: =K34-K35 -> 683000 | L36: =L34-L35 -> 683000 | ... Q36: =Q34-Q35 -> 7310867
B37: フォレストヒルズガーデン | C37: 売上 | E37: =フォレストヒルズガーデン!B3 -> 5670857 | F37: =フォレストヒルズガーデン!C3 -> 5411304 | G37: =フォレストヒルズガーデン!D3 -> 6110445 | H37: =フォレストヒルズガーデン!E3 -> 5535949 | I37: =フォレストヒルズガーデン!F3 -> 7265723 | J37: =フォレストヒルズガーデン!G3 -> 5640457 | K37: =フォレストヒルズガーデン!H3 -> 4902843 | L37: =フォレストヒルズガーデン!I3 -> 5877492 | ... P37: =フォレストヒルズガーデン!M3 -> 4621833 | Q37: =SUM(E37:P37) -> 65185602
C38: 経費 | E38: 4318542 | F38: 4263820 | G38: 0 | H38: 0 | I38: 0 | J38: 0 | K38: 0 | L38: 0 | M38: 0 | N38: 0 | O38: 0 | P38: 0 | Q38: =SUM(E38:P38) -> 8582362
C39: 差引収支 | E39: =E37-E38 -> 1352315 | F39: =F37-F38 -> 1147484 | G39: =G37-G38 -> 6110445 | H39: =H37-H38 -> 5535949 | I39: =I37-I38 -> 7265723 | J39: =J37-J38 -> 5640457 | K39: =K37-K38 -> 4902843 | L39: =L37-L38 -> 5877492 | ... Q39: =Q37-Q38 -> 56603240
B40: グリーンシャワー | C40: 売上 | E40: =深入山GS!C51 -> 248917 | F40: =深入山GS!D51 -> 248917 | G40: =深入山GS!E51 -> 248917 | H40: =深入山GS!F51 -> 626997 | I40: =深入山GS!G51 -> 248917 | J40: =深入山GS!H51 -> 248917 | K40: =深入山GS!I51 -> 248917 | L40: =深入山GS!J51 -> 248917 | ... P40: =深入山GS!N51 -> 248917 | Q40: =SUM(E40:P40) -> 3365084
C41: 経費 | E41: =深入山GS!C60 -> 0 | F41: =深入山GS!D60 -> 0 | G41: =深入山GS!E60 -> 0 | H41: =深入山GS!F60 -> 0 | I41: =深入山GS!G60 -> 0 | J41: =深入山GS!H60 -> 0 | K41: =深入山GS!I60 -> 0 | L41: =深入山GS!J60 -> 0 | ... P41: =深入山GS!N60 -> 0 | Q41: =SUM(E41:P41) -> 0
...

Sheet 年間　全施設（客室単価・稼働率）
A1: 全施設 年間 宿泊実績・売上データ（客室単価・稼働率）
A2: 2026年1月ー12月まで
A3: 施設名 | B3: 販売客室数 | C3: 利用人数 | D3: 客室単価 | E3: 客単価 | F3: 稼働率 | G3: 客室売上 | H3: 総売上 | I3: 備考
A4: デルーネ | B4: =ホテル部門→!N23 -> 5013 | C4: =ホテル部門→!N24 -> 7359 | D4: =ホテル部門→!N25 -> 9487.8021 | E4: =ホテル部門→!N26 -> 6463.1542 | F4: =ホテル部門→!N22 -> 0.26929895 | G4: =ホテル部門→!N18 -> 47562352 | H4: =ホテル部門→!N17 -> 51711522
A5: ビュー | B5: =ホテル部門→!N46 -> 1668 | C5: =ホテル部門→!N47 -> 2314 | D5: =ホテル部門→!N48 -> 9586.3621 | E5: =ホテル部門→!N49 -> 6910.1348 | F5: =ホテル部門→!N45 -> 0.25388128 | G5: =ホテル部門→!N41 -> 15990052 | H5: =ホテル部門→!N40 -> 16024147
A6: 本川 | B6: =ホテル部門→!N63 -> 1071 | C6: =ホテル部門→!N64 -> 1222 | D6: =ホテル部門→!N65 -> 7810.7311 | E6: =ホテル部門→!N66 -> 6845.5753 | F6: =ホテル部門→!N62 -> 0.3260274 | G6: =ホテル部門→!N59 -> 8365293 | H6: =ホテル部門→!N59 -> 8365293
A7: 天神ハウス | B7: =ホテル部門→!N77 -> 30 | C7: =ホテル部門→!N78 -> 141 | D7: =ホテル部門→!N79 -> 76707.633 | E7: =ホテル部門→!N80 -> 16320.773 | F7: =ホテル部門→!N76 -> 0.082191781 | G7: =ホテル部門→!N73 -> 2301229 | H7: =ホテル部門→!N73 -> 2301229
A8: 玖波 | B8: =ホテル部門→!N91 -> 61 | C8: =ホテル部門→!N92 -> 367 | D8: =ホテル部門→!N93 -> 80844.262 | E8: =ホテル部門→!N94 -> 13437.33 | F8: =ホテル部門→!N90 -> 0.33888889 | G8: =ホテル部門→!N87 -> 4931500 | H8: =ホテル部門→!N87 -> 4931500 | I8: 年間180日の稼働設定のため、月あたり15日の稼働となり、他施設と比較して稼働率が高めに算出される。
A9: 弥山 | B9: =弥山!N10 -> 2267 | C9: =弥山!N11 -> 4461 | D9: =弥山!N12 -> 11845.071 | E9: =弥山!N13 -> 6019.4521 | F9: =弥山!N9 -> 2.0141068 | G9: =弥山!N5 -> 26852776 | H9: =弥山!N4 -> 31554666
A10: 温井 | B10: =温井!P4 -> 1847 | C10: =温井!P5 -> 3538 | D10: =温井!P13 -> 56789.617 | E10: =温井!P14 -> 32680.631 | F10: =温井!P10 -> 1.3390429 | G10: =温井!P29 -> 15012501 | H10: =温井!P3 -> 30755817
A11: いこいの村 | B11: =いこいの村!P4 -> 0 | C11: =いこいの村!P5 -> 0 | D11: =いこいの村!P13 -> 0 | E11: =いこいの村!P14 -> 0 | F11: =いこいの村!P10 -> 0 | G11: =いこいの村!P29 -> 0 | H11: =いこいの村!P3 -> 0
A12: 高屋 | B12: =マンスリー部門!N8 -> 786 | C12: =マンスリー部門!N9 -> 786 | D12: =マンスリー部門!N10 -> #DIV/0! | E12: =マンスリー部門!N11 -> #DIV/0! | F12: =マンスリー部門!N7 -> 0.19576588 | G12: =マンスリー部門!N4 -> 2330000 | H12: =マンスリー部門!N4 -> 2330000
A13: 壱番館 | B13: =マンスリー部門!N23 -> 176 | C13: =マンスリー部門!N24 -> 179 | D13: =マンスリー部門!N25 -> #DIV/0! | E13: =マンスリー部門!N26 -> #DIV/0! | F13: =マンスリー部門!N22 -> 0.080365297 | G13: =マンスリー部門!N19 -> 501900 | H13: =マンスリー部門!N19 -> 501900
A14: 弐番館 | B14: =マンスリー部門!N38 -> 139 | C14: =マンスリー部門!N39 -> 139 | D14: =マンスリー部門!N40 -> #DIV/0! | E14: =マンスリー部門!N41 -> #DIV/0! | F14: =マンスリー部門!N37 -> 0.19041096 | G14: =マンスリー部門!N34 -> 403500 | H14: =マンスリー部門!N34 -> 403500
A15: 大竹 | B15: =マンスリー部門!N53 -> 195 | C15: =マンスリー部門!N54 -> 195 | D15: =マンスリー部門!N55 -> 2512.8205 | E15: =マンスリー部門!N56 -> 2512.8205 | F15: =マンスリー部門!N52 -> 0.26712329 | G15: =マンスリー部門!N49 -> 490000 | H15: =マンスリー部門!N49 -> 490000
A16: 竹原 | B16: =マンスリー部門!N68 -> 89 | C16: =マンスリー部門!N69 -> 93 | D16: =マンスリー部門!N70 -> 4573.0337 | E16: =マンスリー部門!N71 -> 4376.3441 | F16: =マンスリー部門!N67 -> 0.12191781 | G16: =マンスリー部門!N64 -> 407000 | H16: =マンスリー部門!N64 -> 407000
A17: サウナ
A18: フォレスト | B18: =フォレストヒルズガーデン!N9 -> 113 | C18: =フォレストヒルズガーデン!N10 -> 397 | D18: =フォレストヒルズガーデン!N11 -> 40666.265 | E18: =フォレストヒルズガーデン!N12 -> 11575.033 | F18: =フォレストヒルズガーデン!N8 -> 0.03869863 | G18: =フォレストヒルズガーデン!N4 -> 4595288 | H18: =フォレストヒルズガーデン!N4 -> 4595288
A19: 総合計 | B19: =SUM(B4:B18) -> 13455 | C19: =SUM(C4:C18) -> 21191 | G19: =SUM(G4:G18) -> 129743391 | H19: =SUM(H4:H18) -> 154371862
A21: 販売客室数 | C21: 利用人数 | E21: 客室売上 | G21: 総売上
A22: =B19 -> 13455 | B22: 室 | C22: =C19 -> 21191 | D22: 名 | E22: =G19 -> 129743391 | F22: 円 | G22: =H19 -> 154371862 | H22: 円

Sheet ホテル部門→
A1: 2026年 グローバルリゾート売上目標及び売上実績 | M1: 46037
A2: 全体 | B2: １月 | C2: ２月 | D2: ３月 | E2: ４月 | F2: ５月 | G2: ６月 | H2: ７月 | I2: ８月 | J2: ９月 | K2: １０月 | L2: １１月 | M2: １２月 | N2: 合計
A3: 目標売上 | B3: =B16+B39+B58+B72+B86 -> 10796694 | C3: =C16+C39+C58+C72+C86 -> 9067219 | D3: =D16+D39+D58+D72+D86 -> 15831767 | E3: =E16+E39+E58+E72+E86 -> 13205981 | F3: =F16+F39+F58+F72+F86 -> 15256604 | G3: =G16+G39+G58+G72+G86 -> 9008685 | H3: =H16+H39+H58+H72+H86 -> 15974001 | I3: =I16+I39+I58+I72+I86 -> 20766504 | ... M3: =M16+M39+M58+M72+M86 -> 10481301 | N3: =SUM(B3:M3) -> 174190007
A4: 売上進捗 | B4: =B17+B40+B59+B73+B87 -> 8908958 | C4: =C17+C40+C59+C73+C87 -> 9792729 | D4: =D17+D40+D59+D73+D87 -> 15185436 | E4: =E17+E40+E59+E73+E87 -> 13558124 | F4: =F17+F40+F59+F73+F87 -> 15383235 | G4: =G17+G40+G59+G73+G87 -> 7732367 | H4: =H17+H40+H59+H73+H87 -> 2409348 | I4: =I17+I40+I59+I73+I87 -> 3256530 | ... M4: =M17+M40+M59+M73+M87 -> 147350 | N4: =SUM(B4:M4) -> 79270462
A5: 達成率 | B5: =B4/B3 -> 0.82515611 | C5: =C4/C3 -> 1.0800146 | D5: =D4/D3 -> 0.95917506 | E5: =E4/E3 -> 1.0266654 | F5: =F4/F3 -> 1.0083001 | G5: =G4/G3 -> 0.85832361 | H5: =H4/H3 -> 0.15082934 | I5: =I4/I3 -> 0.15681648 | ... N5: =N4/N3 -> 0.45508042
A6: 売上目標差異 | B6: =B4-B3 -> -1887736 | C6: =C4-C3 -> 725510 | D6: =D4-D3 -> -646331 | E6: =E4-E3 -> 352143 | F6: =F4-F3 -> 126631 | G6: =G4-G3 -> -1276318 | H6: =H4-H3 -> -13564653 | I6: =I4-I3 -> -17509974 | ... M6: =M4-M3 -> -10333951 | N6: =SUM(B6:M6) -> -94919545
A7: 昨年売上 | B7: =B36+B53+B67+B81+B95 -> 11682489 | C7: =C36+C53+C67+C81+C95 -> 12430189 | D7: =D36+D53+D67+D81+D95 -> 16314013 | E7: =E36+E53+E67+E81+E95 -> 13357025 | F7: =F36+F53+F67+F81+F95 -> 15040357 | G7: =G36+G53+G67+G81+G95 -> 8892648 | H7: =H36+H53+H67+H81+H95 -> 12500189 | I7: =I36+I53+I67+I81+I95 -> 21549998 | ... M7: =M36+M53+M67+M81+M95 -> 11469908 | N7: =SUM(B7:M7) -> 173376507
A8: 昨年対比 | B8: =B4/B7 -> 0.76259075 | C8: =C4/C7 -> 0.78781819 | D8: =D4/D7 -> 0.93082162 | E8: =E4/E7 -> 1.0150557 | F8: =F4/F7 -> 1.0227972 | G8: =G4/G7 -> 0.86952357 | H8: =H4/H7 -> 0.19274493 | I8: =I4/I7 -> 0.1511151 | ... N8: =N4/N7 -> 0.45721571
A9: 経費予測 | B9: 14000000 | C9: 13500000 | D9: 16000000 | E9: 20000000 | F9: 19000000 | G9: 17000000 | H9: 16000000 | I9: 15000000 | J9: 17500000 | K9: 18500000 | L9: 17500000 | M9: 17000000 | N9: =SUM(B9:M9) -> 201000000
A10: 昨年経費 | B10: 10060899 | C10: 12353825 | D10: 14986723 | E10: 11582455 | F10: 13674200 | G10: 9447256 | H10: 11605483 | I10: 20129350 | J10: 13346312 | K10: 14940477 | L10: 10392780 | M10: 3389135 | N10: =SUM(B10:M10) -> 145908895
A11: 経費実績 | N11: =SUM(B11:M11) -> 0
A12: 経費差異 | B12: =B9-B11 -> 14000000 | C12: =C9-C10 -> 1146175 | D12: =D9-D10 -> 1013277 | E12: =E9-E10 -> 8417545 | F12: =F9-F10 -> 5325800 | G12: =G9-G11 -> 17000000 | H12: =H9-H11 -> 16000000 | I12: =I9-I11 -> 15000000 | J12: =J9-J11 -> 17500000 | K12: =K9-K11 -> 18500000 | L12: =L9-L11 -> 17500000 | M12: 18000000 | N12: =SUM(B12:M12) -> 149402797
A13: 差引収支 | B13: =B4-B11 -> 8908958 | C13: =C4-C11 -> 9792729 | D13: =D4-D11 -> 15185436 | E13: =E4-E11 -> 13558124 | F13: =F4-F11 -> 15383235 | G13: =G4-G11 -> 7732367 | H13: =H4-H11 -> 2409348 | I13: =I4-I11 -> 3256530 | ... M13: =M4-M11 -> 147350 | N13: =SUM(B13:M13) -> 79270462
A15: デルーネ | B15: １月 | C15: ２月 | D15: ３月 | E15: ４月 | F15: ５月 | G15: ６月 | H15: ７月 | I15: ８月 | J15: ９月 | K15: １０月 | L15: １１月 | M15: １２月 | N15: 合計
A16: 目標売上 | B16: 7261662 | C16: 5866776 | D16: 10663661 | E16: 8372542 | F16: 10091773 | G16: 6020957 | H16: 10861148 | I16: 13339294 | J16: 8976175 | K16: 12967689 | L16: 13075844 | M16: 6830956 | N16: 114328477 | O16: 2025年売上実績
A17: 売上進捗 | B17: =B18+B27+B19 -> 6712201 | C17: =C18+C27+C19 -> 6486426 | D17: =D18+D27+D19 -> 9961885 | E17: =E18+E27+E19 -> 8310821 | F17: =F18+F27+F19 -> 9884840 | G17: =G18+G27+G19 -> 4996865 | H17: =H18+H27+H19 -> 1386977 | I17: =I18+I27+I19 -> 2069324 | ... M17: =M18+M27+M19 -> 147350 | N17: =SUM(B17:M17) -> 51711522
A18: 客室売上 | B18: 5993256 | C18: 6022901 | D18: 8920925 | E18: 7531181 | F18: 9185215 | G18: 4897710 | H18: 1299802 | I18: 1946074 | J18: 768782 | K18: 709806 | L18: 141000 | M18: 145700 | N18: =SUM(B18:M18) -> 47562352
A19: レジ売上 | B19: 107885 | C19: 17565 | D19: 99520
A20: 達成率 | B20: =B17/B16 -> 0.92433399 | C20: =C17/C16 -> 1.1056202 | D20: =D17/D16 -> 0.93418996 | E20: =E17/E16 -> 0.99262816 | F20: =F17/F16 -> 0.97949488 | G20: =G17/G16 -> 0.82991209 | H20: =H17/H16 -> 0.12770077 | I20: =I17/I16 -> 0.15512995 | ... M20: =M17/M16 -> 0.021570919 | N20: =N18/N16 -> 0.41601492
A21: 差異 | B21: =B17-B16 -> -549461 | C21: =C17-C16 -> 619650 | D21: =D17-D16 -> -701776 | E21: =E17-E16 -> -61721 | F21: =F17-F16 -> -206933 | G21: =G17-G16 -> -1024092 | H21: =H17-H16 -> -9474171 | I21: =I17-I16 -> -11269970 | ... M21: =M17-M16 -> -6683606 | N21: =SUM(B21:M21) -> -62616955
A22: 稼働率 | B22: =B23/(51*31) -> 0.4345351 | C22: =C23/(51*29) -> 0.46923597 | D22: =D23/(51*31) -> 0.59962049 | E22: =E23/(51*30) -> 0.50915033 | F22: =F23/(51*31) -> 0.56862745 | G22: =G23/(51*30) -> 0.35359477 | H22: =H23/(51*31) -> 0.079696395 | I22: =I23/(51*31) -> 0.080328906 | J22: =J23/(51*30) -> 0.046405229 | K22: =K23/(51*31) -> 0.049968374 | L22: =L23/(51*30) -> 0.020261438 | M22: =M23/(51*31) -> 0.019607843 | N22: =N23/(51*365) -> 0.26929895
A23: 販売客室数 | B23: 687 | C23: 694 | D23: 948 | E23: 779 | F23: 899 | G23: 541 | H23: 126 | I23: 127 | J23: 71 | K23: 79 | L23: 31 | M23: 31 | N23: =SUM(B23:M23) -> 5013
A24: 利用人数 | B24: 928 | C24: 911 | D24: 1441 | E24: 1059 | F24: 1355 | G24: 756 | H24: 242 | I24: 341 | J24: 134 | K24: 130 | L24: 31 | M24: 31 | N24: =SUM(B24:M24) -> 7359
A25: 客室単価 | B25: =B18/B23 -> 8723.8079 | C25: =C18/C23 -> 8678.5317 | D25: =D18/D23 -> 9410.2584 | E25: =E18/E23 -> 9667.7548 | F25: =F18/F23 -> 10217.147 | G25: =G18/G23 -> 9053.0684 | H25: =H18/H23 -> 10315.889 | I25: =I18/I23 -> 15323.417 | ... N25: =N18/N23 -> 9487.8021
A26: 客単価 | B26: =B18/B24 -> 6458.25 | C26: =C18/C24 -> 6611.3074 | D26: =D18/D24 -> 6190.7876 | E26: =E18/E24 -> 7111.5968 | F26: =F18/F24 -> 6778.7565 | G26: =G18/G24 -> 6478.4524 | H26: =H18/H24 -> 5371.0826 | I26: =I18/I24 -> 5706.9619 | ... N26: =N18/N24 -> 6463.1542
A27: 飲食売上 | B27: =B28+B31 -> 611060 | C27: =C28+C31 -> 445960 | D27: =D28+D31 -> 941440 | E27: =E28+E31 -> 779640 | F27: =F28+F31 -> 699625 | G27: =G28+G31 -> 99155 | H27: =H28+H31 -> 87175 | I27: =I28+I31 -> 123250 | ... M27: =M28+M31 -> 1650 | N27: =SUM(B27:M27) -> 3924200
A28: 朝食売上 | B28: 395670 | C28: 333630 | D28: 599280 | E28: 450615 | F28: 428670 | G28: 80355 | H28: 58740 | I28: 82830 | J28: 63525 | K28: 51975 | L28: 1650 | M28: 1650 | N28: =SUM(B28:M28) -> 2548590
A29: 朝食数 | B29: 243 | C29: 207 | D29: 380 | E29: 280 | F29: 267 | G29: 49 | H29: 38 | I29: 55 | J29: 40 | K29: 33 | L29: 1 | M29: 1 | N29: =SUM(B29:M29) -> 1594
A30: 利用率 | B30: =B29/B24 -> 0.26185345 | C30: =C29/C24 -> 0.22722283 | D30: =D29/D24 -> 0.26370576 | E30: =E29/E24 -> 0.26440038 | F30: =F29/F24 -> 0.19704797 | G30: =G29/G24 -> 0.064814815 | H30: =H29/H24 -> 0.15702479 | I30: =I29/I24 -> 0.16129032 | ... N30: =N29/N24 -> 0.21660552
A31: 夕食売上 | B31: 215390 | C31: 112330 | D31: 342160 | E31: 329025 | F31: 270955 | G31: 18800 | H31: 28435 | I31: 40420 | J31: 13395 | K31: 4700 | L31: 0 | M31: 0 | N31: =SUM(B31:M31) -> 1375610
A32: 夕食数 | B32: 90 | C32: 49 | D32: 151 | E32: 137 | F32: 118 | G32: 8 | H32: 13 | I32: 19 | J32: 6 | K32: 2 | L32: 0 | M32: 0 | N32: =SUM(B32:M32) -> 593
A33: 利用率 | B33: =B32/B24 -> 0.096982759 | C33: =C32/C24 -> 0.053787047 | D33: =D32/D24 -> 0.10478834 | E33: =E32/E24 -> 0.12936733 | F33: =F32/F24 -> 0.087084871 | G33: =G32/G24 -> 0.010582011 | H33: =H32/H24 -> 0.053719008 | I33: =I32/I24 -> 0.055718475 | ... N33: =N32/N24 -> 0.080581601
A34: 昨年売上 | B34: 7261662 | C34: 5866776 | D34: 10663661 | E34: 8372542 | F34: 10091773 | G34: 6020957 | H34: 10861148 | I34: 13339294 | J34: 8976175 | K34: 12967689 | L34: 13075844 | M34: 6830956 | N34: 114328477
A35: 昨年対比 | B35: =B17/B34 -> 0.92433399 | C35: =C17/C34 -> 1.1056202 | D35: =D17/D34 -> 0.93418996 | E35: =E17/E34 -> 0.99262816 | F35: =F17/F34 -> 0.97949488 | G35: =G17/G34 -> 0.82991209 | H35: =H17/H34 -> 0.12770077 | I35: =I17/I34 -> 0.15512995 | ... M35: =M17/M34 -> 0.021570919 | N35: =N18/N36 -> 0.41587389
A36: 2024年売上 | B36: 8277657 | C36: 9355406 | D36: 11198747 | E36: 8577026 | F36: 9703126 | G36: 6231420 | H36: 7654906 | I36: 13871118 | J36: 8723067 | K36: 11086919 | L36: 11777413 | M36: 7910443 | N36: =SUM(B36:M36) -> 114367248
A38: ビュー | B38: １月 | C38: ２月 | D38: ３月 | E38: ４月 | F38: ５月 | G38: ６月 | H38: ７月 | I38: ８月 | J38: ９月 | K38: １０月 | L38: １１月 | M38: １２月 | N38: 合計
A39: 目標売上 | B39: 2143056 | C39: 1559909 | D39: 2743253 | E39: 2602903 | F39: 2606733 | G39: 1341712 | H39: 3302659 | I39: 4469894 | J39: 2740428 | K39: 3669167 | L39: 3942044 | M39: 1966245 | N39: 33088003 | O39: 2025年売上実績
A40: 売上進捗 | B40: =B41+B50+B42 -> 1319475 | C40: =C41+C50+C42 -> 1757661 | D40: =D41+D50+D42 -> 2882218 | E40: =E41+E50+E42 -> 2904045 | F40: =F41+F50+F42 -> 3017659 | G40: =G41+G50+G42 -> 2196076 | H40: =H41+H50+H42 -> 492989 | I40: =I41+I50+I42 -> 716260 | ... M40: =M41+M50+M42 -> 0 | N40: =SUM(B40:M40) -> 16024147
A41: 客室売上 | B41: 1313280 | C41: 1749061 | D41: 2862918 | E41: 2904045 | F41: 3017659 | G41: 2196076 | H41: 492989 | I41: 716260 | J41: 540084 | K41: 197680 | L41: 0 | M41: 0 | N41: =SUM(B41:M41) -> 15990052
A42: レジ売上 | B42: 6195 | C42: 8600 | D42: 19300
...

Sheet 弥山
A1: 2026年 弥山 売上目標及び売上実績
A2: 弥山全体 | B2: １月 | C2: ２月 | D2: ３月 | E2: ４月 | F2: ５月 | G2: ６月 | H2: ７月 | I2: ８月 | J2: ９月 | K2: １０月 | L2: １１月 | M2: １２月 | N2: 合計
A3: 目標売上 | B3: 3701096 | C3: 2980174 | D3: 5584201 | E3: 5487259 | F3: 6761527 | G3: 3942572 | H3: 5866719 | I3: 9564791 | J3: 5465630 | K3: 8958395 | L3: 8362200 | M3: 5672113 | N3: 72346677 | O3: 2025年売上実績
A4: 売上進捗 | B4: =B5+B14+B6 -> 2906901 | C4: =C5+C14+C6 -> 4965898 | D4: =D5+D14+D6 -> 6807485 | E4: =E5+E14+E6 -> 4004248 | F4: =F5+F14+F6 -> 6175495 | G4: =G5+G14+G6 -> 2105073 | H4: =H5+H14+H6 -> 1056902 | I4: =I5+I14+I6 -> 1697508 | ... M4: =M5+M14+M6 -> 20000 | N4: =SUM(B4:M4) -> 31554666
A5: 客室売上 | B5: 2493516 | C5: 4182983 | D5: 5251225 | E5: 3713533 | F5: 5433020 | G5: 1772568 | H5: 998427 | I5: 1575613 | J5: 686771 | K5: 562660 | L5: 170460 | M5: 12000 | N5: =SUM(B5:M5) -> 26852776
A6: レジ売上 | B6: 138235 | C6: 187870 | D6: 685450
A7: 達成率 | B7: =B4/B3 -> 0.78541627 | C7: =C4/C3 -> 1.6663114 | D7: =D4/D3 -> 1.2190616 | E7: =E4/E3 -> 0.72973556 | F7: =F4/F3 -> 0.91332845 | G7: =G4/G3 -> 0.53393394 | H7: =H4/H3 -> 0.18015214 | I7: =I4/I3 -> 0.17747466 | ... N7: =N4/N3 -> 0.43615916
A8: 売上目標差異 | B8: =B4-B3 -> -794195 | C8: =C4-C3 -> 1985724 | D8: =D4-D3 -> 1223284 | E8: =E4-E3 -> -1483011 | F8: =F4-F3 -> -586032 | G8: =G4-G3 -> -1837499 | H8: =H4-H3 -> -4809817 | I8: =I4-I3 -> -7867283 | ... M8: =M4-M3 -> -5652113 | N8: =SUM(B8:M8) -> -40792011
A9: 稼働率 | B9: =B10/(37*31) -> 0.2048823 | C9: =C10/(37*29) -> 0.3028891 | D9: =D10/(37*31) -> 0.37053182 | E9: =E10/(37*30) -> 0.30540541 | F9: =F10/(37*31) -> 0.3722755 | G9: =G10/(37*30) -> 0.18018018 | H9: =H10/(37*31) -> 0.060156931 | I9: =I10/(37*31) -> 0.080209241 | J9: =J10/(37*30) -> 0.05045045 | K9: =K10/(37*31) -> 0.060156931 | L9: =L10/(37*30) -> 0.025225225 | M9: =M10/(37*31) -> 0.0017436792 | N9: =SUM(B9:M9) -> 2.0141068
A10: 販売客室数 | B10: 235 | C10: 325 | D10: 425 | E10: 339 | F10: 427 | G10: 200 | H10: 69 | I10: 92 | J10: 56 | K10: 69 | L10: 28 | M10: 2 | N10: =SUM(B10:M10) -> 2267
A11: 利用人数 | B11: 403 | C11: 762 | D11: 911 | E11: 532 | F11: 753 | G11: 356 | H11: 188 | I11: 302 | J11: 122 | K11: 93 | L11: 37 | M11: 2 | N11: =SUM(B11:M11) -> 4461
A12: 客室単価 | B12: =B5/B10 -> 10610.706 | C12: =C5/C10 -> 12870.717 | D12: =D5/D10 -> 12355.824 | E12: =E5/E10 -> 10954.375 | F12: =F5/F10 -> 12723.7 | G12: =G5/G10 -> 8862.84 | H12: =H5/H10 -> 14469.957 | I12: =I5/I10 -> 17126.228 | ... N12: =N5/N10 -> 11845.071
A13: 客単価 | B13: =B5/B11 -> 6187.3846 | C13: =C5/C11 -> 5489.479 | D13: =D5/D11 -> 5764.2426 | E13: =E5/E11 -> 6980.3252 | F13: =F5/F11 -> 7215.166 | G13: =G5/G11 -> 4979.1236 | H13: =H5/H11 -> 5310.7819 | I13: =I5/I11 -> 5217.2616 | ... N13: =N5/N11 -> 6019.4521
A14: 飲食売上 | B14: =B15+B18 -> 275150 | C14: =C15+C18 -> 595045 | D14: =D15+D18 -> 870810 | E14: =E15+E18 -> 290715 | F14: =F15+F18 -> 742475 | G14: =G15+G18 -> 332505 | H14: =H15+H18 -> 58475 | I14: =I15+I18 -> 121895 | ... N14: =N15+N18 -> 3690335
A15: 朝食売上 | B15: 129030 | C15: 272740 | D15: 465795 | E15: 200475 | F15: 408540 | G15: 156255 | H15: 41085 | I15: 54450 | J15: 51810 | K15: 90255 | L15: 34650 | M15: 3300 | N15: =SUM(B15:M15) -> 1908385
A16: 朝食数 | B16: 80 | C16: 192 | D16: 295 | E16: 123 | F16: 253 | G16: 95 | H16: 27 | I16: 36 | J16: 32 | K16: 55 | L16: 21 | M16: 2 | N16: =SUM(B16:M16) -> 1211
A17: 利用率 | B17: =B16/B11 -> 0.19851117 | C17: =C16/C11 -> 0.2519685 | D17: =D16/D11 -> 0.32381998 | E17: =E16/E11 -> 0.23120301 | F17: =F16/F11 -> 0.33598938 | G17: =G16/G11 -> 0.26685393 | H17: =H16/H11 -> 0.14361702 | I17: =I16/I11 -> 0.1192053 | ... M17: =M16/M11 -> 1
A18: 夕食売上 | B18: 146120 | C18: 322305 | D18: 405015 | E18: 90240 | F18: 333935 | G18: 176250 | H18: 17390 | I18: 67445 | J18: 58750 | K18: 117500 | L18: 42300 | M18: 4700 | N18: =SUM(B18:M18) -> 1781950
A19: 夕食数 | B19: 50 | C19: 134 | D19: 178 | E19: 39 | F19: 146 | G19: 75 | H19: 8 | I19: 32 | J19: 25 | K19: 50 | L19: 18 | M19: 2 | N19: =SUM(B19:M19) -> 757
A20: 利用率 | B20: =B19/B11 -> 0.12406948 | C20: =C19/C11 -> 0.17585302 | D20: =D19/D11 -> 0.19538968 | E20: =E19/E11 -> 0.073308271 | F20: =F19/F11 -> 0.1938911 | G20: =G19/G11 -> 0.21067416 | H20: =H19/H11 -> 0.042553191 | I20: =I19/I11 -> 0.10596026 | ... M20: =M19/M11 -> 1
A21: 経費予測 | B21: 14000000 | C21: 13500000 | D21: 16000000 | E21: 20000000 | F21: 19000000 | G21: 17000000 | H21: 16000000 | I21: 15000000 | J21: 17500000 | K21: 18500000 | L21: 17500000 | M21: 17000000 | N21: =SUM(B21:M21) -> 201000000
A22: 昨年経費 | O22: ←未入力
A23: 経費実績 | N23: =SUM(B23:M23) -> 0
A24: 経費差異 | B24: =B21-B23 -> 14000000 | C24: =C21-C22 -> 13500000 | D24: =D21-D22 -> 16000000 | E24: =E21-E22 -> 20000000 | F24: =F21-F22 -> 19000000 | G24: =G21-G23 -> 17000000 | H24: =H21-H23 -> 16000000 | I24: =I21-I23 -> 15000000 | J24: =J21-J23 -> 17500000 | K24: =K21-K23 -> 18500000 | L24: =L21-L23 -> 17500000 | M24: 18000000 | N24: =SUM(B24:M24) -> 202000000
A25: 差引収支 | B25: =B5-B23 -> 2493516 | C25: =C5-C22 -> 4182983 | D25: =D5-D22 -> 5251225 | E25: =E5-E22 -> 3713533 | F25: =F5-F22 -> 5433020 | G25: =G5-G21 -> -15227432 | H25: =H5-H21 -> -15001573 | I25: =I5-I21 -> -13424387 | J25: =J5-J21 -> -16813229 | K25: =K5-K21 -> -17937340 | L25: =L5-L21 -> -17329540 | M25: =M5-M21 -> -16988000 | N25: =SUM(B25:M25) -> -91647224
A26: 昨年売上 | B26: 3701096 | C26: 2980174 | D26: 5584201 | E26: 5487259 | F26: 6761527 | G26: 3942572 | H26: 5866719 | I26: 9564791 | J26: 5465630 | K26: 8958395 | L26: 8362200 | M26: 5672113 | N26: 72346677
A27: 昨年対比 | B27: =B4/B26 -> 0.78541627 | C27: =C4/C26 -> 1.6663114 | D27: =D4/D26 -> 1.2190616 | E27: =E4/E26 -> 0.72973556 | F27: =F4/F26 -> 0.91332845 | G27: =G4/G26 -> 0.53393394 | H27: =H4/H26 -> 0.18015214 | I27: =I4/I26 -> 0.17747466 | ... M27: =M4/M26 -> 0.0035260228 | N27: =N5/N26 -> 0.37116806
A28: 2024年売上 | B28: 5019767 | C28: 5564351 | D28: 8310430 | E28: 4790923 | F28: 6533622 | G28: 4389116 | H28: 4605120 | I28: 9240258 | J28: 6569181 | K28: 7721028 | L28: 8280505 | M28: 5169972 | N28: =SUM(B28:M28) -> 76194273 | O28: OK
A29: 未販売
A30: 別館1004 | B30: １月 | C30: ２月 | D30: ３月 | E30: ４月 | F30: ５月 | G30: ６月 | H30: ７月 | I30: ８月 | J30: ９月 | K30: １０月 | L30: １１月 | M30: １２月 | N30: 合計
A31: 目標売上 | B31: 50000 | C31: 150000 | D31: 200000 | E31: 210000 | F31: 190000 | G31: 90000 | H31: 90000 | I31: 250000 | J31: 90000 | K31: 130000 | L31: 200000 | M31: 50000 | N31: =SUM(B31:M31) -> 1700000
A32: 売上進捗 | B32: 60000 | C32: 0 | D32: 0 | N32: =SUM(B32:M32) -> 60000
A33: 達成率 | B33: =B32/B31 -> 1.2 | C33: =C32/C31 -> 0 | D33: =D32/D31 -> 0 | E33: =E32/E31 -> 0 | F33: =F32/F31 -> 0 | G33: =G32/G31 -> 0 | H33: =H32/H31 -> 0 | I33: =I32/I31 -> 0 | ... N33: =N32/N31 -> 0.035294118
A34: 差異 | B34: =B32-B31 -> 10000 | C34: =C32-C31 -> -150000 | D34: =D32-D31 -> -200000 | E34: =E32-E31 -> -210000 | F34: =F32-F31 -> -190000 | G34: =G32-G31 -> -90000 | H34: =H32-H31 -> -90000 | I34: =I32-I31 -> -250000 | ... M34: =M32-M31 -> -50000 | N34: =SUM(B34:M34) -> -1640000
A35: 稼働率 | B35: =B36/(1*31) -> 0.032258065 | C35: =C36/(1*29) -> 0 | D35: =D36/(1*31) -> 0 | E35: =E36/(1*30) -> 0 | F35: =F36/(1*31) -> 0 | G35: =G36/(1*30) -> 0 | H35: =H36/(1*31) -> 0 | I35: =I36/(1*31) -> 0 | J35: =J36/(1*30) -> 0 | K35: =K36/(1*31) -> 0 | L35: =L36/(1*30) -> 0 | M35: =M36/(1*31) -> 0
A36: 販売客室数 | B36: 1 | C36: 0 | D36: 0 | N36: =SUM(B36:M36) -> 1
A37: 利用人数 | B37: 3 | C37: 0 | D37: 0 | N37: =SUM(B37:M37) -> 3
A38: 客室単価 | B38: =B32/B36 -> 60000 | C38: =C32/C36 -> #DIV/0! | D38: =D32/D36 -> #DIV/0! | E38: =E32/E36 -> #DIV/0! | F38: =F32/F36 -> #DIV/0! | G38: =G32/G36 -> #DIV/0! | H38: =H32/H36 -> #DIV/0! | I38: =I32/I36 -> #DIV/0! | ... N38: =N32/N36 -> 60000
A39: 客単価 | B39: =B32/B37 -> 20000 | C39: =C32/C37 -> #DIV/0! | D39: =D32/D37 -> #DIV/0! | E39: =E32/E37 -> #DIV/0! | F39: =F32/F37 -> #DIV/0! | G39: =G32/G37 -> #DIV/0! | H39: =H32/H37 -> #DIV/0! | I39: =I32/I37 -> #DIV/0! | ... N39: =N32/N37 -> 20000
A40: 昨年売上 | B40: 49071 | C40: 137999 | D40: 200400 | E40: 205579 | F40: 187337 | G40: 81410 | H40: 89625 | I40: 237984 | J40: 89828 | K40: 129196 | L40: 189315 | M40: 135230 | N40: =SUM(B40:M40) -> 1732974
...

Sheet 温井
A1: GR NUKUI 売上推移表
D2: 1月 | E2: 2月 | F2: 3月 | G2: 4月 | H2: 5月 | I2: 6月 | J2: 7月 | K2: 8月 | L2: 9月 | M2: 10月 | N2: 11月 | O2: 12月 | P2: 合計
A3: 総売上高(GOR) | D3: 7428554 | E3: 7562227 | F3: 3799283 | G3: 2330934 | H3: 4784742 | I3: 2087208 | J3: 1038480 | K3: 1446637 | L3: 100152 | M3: 177600 | P3: =SUM(D3:O3) -> 30755817
A4: 販売室数 | D4: 306 | E4: 360 | F4: 192 | G4: 163 | H4: 226 | I4: 156 | J4: 120 | K4: 284 | L4: 5 | M4: 35 | P4: =SUM(D4:O4) -> 1847
A5: 販売人数 | D5: 632 | E5: 625 | F5: 339 | G5: 215 | H5: 370 | I5: 210 | J5: 241 | K5: 792 | L5: 8 | M5: 106 | P5: =SUM(D5:O5) -> 3538
A6: 大人 | D6: 538 | E6: 584 | F6: 316 | G6: 205 | P6: =SUM(D6:O6) -> 1643
A7: 子供 | D7: 94 | E7: 41 | F7: 23 | G7: 10 | P7: =SUM(D7:O7) -> 168
A8: 販売可能室数 | D8: 837 | E8: 702 | F8: 810 | G8: 729 | P8: =SUM(D8:O8) -> 3078
A9: 販売可能人員 | D9: 3420 | E9: 3420 | F9: 3420 | G9: 3420 | P9: =SUM(D9:O9) -> 13680
A10: 客室稼働率(Occ) | D10: 0.3655914 | E10: 0.51282051 | F10: 0.23703704 | G10: 0.22359396 | P10: =SUM(D10:O10) -> 1.3390429
A11: 人員稼働率 | D11: 0.18479532 | E11: 0.18274854 | F11: 0.099122807 | G11: 0.062865497 | P11: =SUM(D11:O11) -> 0.52953216
A12: 1室平均稼働人員 | D12: 2.0653595 | E12: 1.7361111 | F12: 1.765625 | G12: 1.3190184 | P12: =SUM(D12:O12) -> 6.886114
A13: ADR | D13: 18241.562 | E13: 13774.772 | F13: 14952.411 | G13: 9820.8712 | P13: =SUM(D13:O13) -> 56789.617
A14: APR | D14: 8832.1487 | E14: 7934.2688 | F14: 8468.6224 | G14: 7445.5907 | P14: =SUM(D14:O14) -> 32680.631
A15: Rev.PAR | D15: 6668.9582 | E15: 7063.9858 | F15: 3544.2753 | G15: 2195.8875 | P15: =SUM(D15:O15) -> 19473.107
P16: =SUM(D16:O16) -> 0
A17: レストラン利用者数 | D17: 265 | E17: 278 | F17: 190 | G17: 136 | P17: =SUM(D17:O17) -> 869
A18: 朝食 | C18: =IF(D5=0,"",D18/D5) -> 0.25158228 | D18: 159 | E18: 165 | F18: 117 | G18: 82
A19: 昼食 | D19: 0 | E19: 0 | F19: 0 | G19: 1
A20: 夕食 | C20: =IF(D5=0,"",D20/D5) -> 0.16772152 | D20: 106 | E20: 113 | F20: 73 | G20: 53
A22: 宴会利用者数 | D22: 81 | E22: 148 | F22: 0 | G22: 0 | P22: =SUM(D22:O22) -> 229
A23: 会議/展示会 | D23: 0 | E23: 9 | F23: 0 | G23: 0
A24: 宴会 | D24: 81 | E24: 139 | F24: 0 | G24: 0
A26: 立寄入浴利用者数 | D26: 478 | E26: 499 | F26: 513 | G26: 425 | P26: =SUM(D26:O26) -> 1915
A27: 立寄入浴 | D27: 478 | E27: 499 | F27: 513 | G27: 425
A29: 売上高内訳 | B29: 宿 泊 売 上 | D29: 5581918 | E29: 4958918 | F29: 2870863 | G29: 1600802 | P29: =SUM(D29:O29) -> 15012501
B30: 宿泊売上(大人） | D30: 5565653 | E30: 4958918 | F30: 2870863 | G30: 1593602
B31: 宿泊売上(子人) | D31: 0 | E31: 0 | F31: 0 | G31: 0
B32: 寝具代 | D32: 0 | E32: 0 | F32: 0 | G32: 0
B33: 休憩料 | D33: 4000 | E33: 0 | F33: 0 | G33: 0
D34: 0 | E34: 0 | F34: 0 | G34: 0
B35: キャンセル料 | D35: 12265 | E35: 0 | F35: 0 | G35: 7200
B36: 宿 泊 その他 | D36: 0 | E36: 0 | F36: 0 | G36: 0 | P36: =SUM(D36:O36) -> 0
B37: 電話・FAX・コピー等 | D37: 0 | E37: 0 | F37: 0 | G37: 0 | P37: =SUM(D37:O37) -> 0
D38: 0 | E38: 0 | F38: 0 | G38: 0 | P38: =SUM(D38:O38) -> 0
D39: 0 | E39: 0 | F39: 0 | G39: 0 | P39: =SUM(D39:O39) -> 0
D40: 0 | E40: 0 | F40: 0 | G40: 0 | P40: =SUM(D40:O40) -> 0
B41: レストラン 売 上 | D41: 771900 | E41: 850700 | F41: 606500 | G41: 480700 | P41: =SUM(D41:O41) -> 2709800
B42: 料 理 売 上 | D42: 742400 | E42: 796100 | F42: 591000 | G42: 459200 | P42: =SUM(D42:O42) -> 2588700
B43: (朝 食) | D43: 285800 | E43: 300800 | F43: 211000 | G43: 155000 | P43: =SUM(D43:O43) -> 952600
...

Sheet いこいの村
A1: GR いこいの村ひろしま 売上推移表
D2: 1月 | E2: 2月 | F2: 3月 | G2: 4月 | H2: 5月 | I2: 6月 | J2: 7月 | K2: 8月 | L2: 9月 | M2: 10月 | N2: 11月 | O2: 12月 | P2: 合計
A3: 総売上高(GOR) | D3: 8292624 | E3: 8535484 | F3: 4929332 | G3: 6092392 | H3: 3646914 | I3: 1303991 | J3: 1869506 | K3: 948336 | L3: 1793043 | M3: 415440
A4: 販売室数 | D4: 303 | E4: 279 | F4: 162 | G4: 182 | H4: 155 | I4: 103 | J4: 183 | K4: 459 | L4: 105 | M4: 83
A5: 販売人数 | D5: 738 | E5: 741 | F5: 426 | G5: 554 | H5: 440 | I5: 273 | J5: 636 | K5: 1969 | L5: 469 | M5: 314
A6: 大人 | D6: 0 | E6: 636 | F6: 116 | G6: 0
A7: 子供 | D7: 0 | E7: 37 | F7: 8 | G7: 0
A8: 販売可能室数 | D8: 837 | E8: 702 | F8: 837 | G8: 648
A9: 販売可能人員 | D9: 3751 | E9: 3146 | F9: 3388 | G9: 3630
A10: 客室稼働率(Occ) | D10: 0.36200717 | E10: 0.3974359 | F10: 0.19354839 | G10: 0.2808642
A11: 人員稼働率 | D11: 0.19674753 | E11: 0.23553719 | F11: 0.1257379 | G11: 0.15261708
A12: 1室平均稼働人員 | D12: 2.4356436 | E12: 2.655914 | F12: 2.6296296 | G12: 3.043956
A13: ADR | D13: 26170.244 | E13: 16863.097 | F13: 16012.79 | G13: 13805.654
A14: APR | D14: 10744.694 | E14: 6349.2632 | F14: 6089.3709 | G14: 4535.4314
A15: Rev.PAR | D15: 9473.816 | E15: 6702 | F15: 3099.2497 | G15: 3877.5139
A17: レストラン利用者数 | D17: 0 | E17: 1015 | F17: 709 | G17: 1469
A18: 朝食 | C18: =IF(J5=0,"",J18/J5) -> 0 | D18: 0 | E18: 512 | F18: 296 | G18: 518
A19: 昼食 | D19: 0 | E19: 0 | F19: 128 | G19: 438
A20: 夕食 | C20: =IF(J5=0,"",J20/J5) -> 0 | D20: 0 | E20: 503 | F20: 285 | G20: 513
A22: 宴会利用者数 | D22: 0 | E22: 0 | F22: 0 | G22: 0
A23: 会議/展示会 | D23: 0 | E23: 0 | F23: 0 | G23: 0
A24: 宴会 | D24: 0 | E24: 0 | F24: 0 | G24: 0
A26: 日帰り入浴利用者数 | D26: 0 | E26: 426 | F26: 226 | G26: 150
A27: 日帰り入浴 | D27: 0 | E27: 426 | F27: 226 | G27: 150
A28: 日帰り入浴（松原自治会）
A29: 売上高内訳 | B29: 宿 泊 売 上 | D29: 7929584 | E29: 4704804 | F29: 2594072 | G29: 2512629
B30: 宿泊売上(大人） | D30: 7929584 | E30: 4694114 | F30: 2588872 | G30: 2512629
B31: 宿泊売上(子人) | D31: 0 | E31: 0 | F31: 0 | G31: 0
B32: 寝具代 | D32: 0 | E32: 0 | F32: 0 | G32: 0
B33: 休憩料 | D33: 0 | E33: 0 | F33: 0 | G33: 0
D34: 0 | E34: 0 | F34: 0 | G34: 0
B35: キャンセル料 | D35: 0 | E35: 10690 | F35: 5200 | G35: 0
B36: 宿 泊 その他 | D36: 0 | E36: 0 | F36: 0 | G36: 0
B37: 電話・FAX・コピー等 | D37: 0 | E37: 0 | F37: 0 | G37: 0
D38: 0 | E38: 0 | F38: 0 | G38: 0
D39: 0 | E39: 0 | F39: 0 | G39: 0
D40: 0 | E40: 0 | F40: 0 | G40: 0
B41: レストラン 売 上 | D41: 7390 | E41: 3163530 | F41: 1686760 | G41: 2802181
B42: 料 理 売 上 | D42: 0 | E42: 3081860 | F42: 1625640 | G42: 2794541
B43: (朝 食) | D43: 0 | E43: 915250 | F43: 531000 | G43: 791840
...

Sheet 深入山GS
D1: 休業 | O1: 休業
D2: 1月 | E2: 2月 | F2: 3月 | G2: 4月 | H2: 5月 | I2: 6月 | J2: 7月 | K2: 8月 | L2: 9月 | M2: 10月 | N2: 11月 | O2: 12月 | P2: 合計
A3: 総売上高(GOR) | G3: 378080 | P3: =SUM(D3:O3) -> 378080
A4: 利用件数 | G4: 29 | P4: =SUM(D4:O4) -> 29
A5: グランドゴルフ場（大人） | G5: 19 | P5: =SUM(D5:O5) -> 19
A6: グランドゴルフ場（子供） | G6: 0 | P6: =SUM(D6:O6) -> 0
A7: グランドゴルフ場（いこい） | G7: 0 | P7: =SUM(D7:O7) -> 0
A8: オートキャンプ | G8: 5 | P8: =SUM(D8:O8) -> 5
A9: デイキャンプ | G9: 5 | P9: =SUM(D9:O9) -> 5
A10: 体験棟 | G10: 0 | P10: =SUM(D10:O10) -> 0
A11: 多目的広場 | G11: 0 | P11: =SUM(D11:O11) -> 0
A13: 利用人数 | G13: 111 | P13: =SUM(D13:O13) -> 111
A14: グランドゴルフ場（大人）町内 | G14: 56 | P14: =SUM(D14:O14) -> 56
A15: グランドゴルフ場（大人）町外 | G15: 5 | P15: =SUM(D15:O15) -> 5
... A22: 多目的広場 | G22: 0 | P22: =SUM(D22:O22) -> 0
A24: 売上高内訳 | B24: 施設利用料 | G24: 73800 | P24: =SUM(D24:O24) -> 73800
B25: グランドゴルフ場 | G25: 30600 | P25: =SUM(D25:O25) -> 30600
B26: オートキャンプ | G26: 24000 | P26: =SUM(D26:O26) -> 24000
B27: デイキャンプ | G27: 17000 | P27: =SUM(D27:O27) -> 17000
B28: 道具類貸出 | G28: 700 | P28: =SUM(D28:O28) -> 700
B29: 多目的広場 | G29: 1500 | P29: =SUM(D29:O29) -> 1500
B30: 体験棟 | G30: 0 | P30: =SUM(D30:O30) -> 0
G31: 0 | P31: =SUM(D31:O31) -> 0
G32: 0 | P32: =SUM(D32:O32) -> 0
B33: 売店売上 | G33: 304280 | P33: =SUM(D33:O33) -> 304280
B34: おみやげ | G34: 222100 | P34: =SUM(D34:O34) -> 222100
B35: 地域特産品（地元産） | G35: 9100 | P35: =SUM(D35:O35) -> 9100
B36: アイス・氷 | G36: 48880 | P36: =SUM(D36:O36) -> 48880
B37: コーヒー | G37: 24200 | P37: =SUM(D37:O37) -> 24200
B38: 地図 | G38: 0 | P38: =SUM(D38:O38) -> 0
B39: 自動販売機 | G39: 0 | P39: =SUM(D39:O39) -> 0
B40: 弁当 | G40: 0 | P40: =SUM(D40:O40) -> 0
B41: その他 | G41: 0 | P41: =SUM(D41:O41) -> 0
G42: 0
B43: 入金合計 | G43: 378080 | P43: =SUM(D43:O43) -> 378080
B44: 現 金 | G44: 378080 | P44: =SUM(D44:O44) -> 378080
B45: システム | G45: 0 | P45: =SUM(D45:O45) -> 0
B46: 売 掛 | G46: 0 | P46: =SUM(D46:O46) -> 0
B47: 過不足 | P47: =SUM(D47:O47) -> 0
A49: 経費 | B49: GS | C49: １月 | D49: ２月 | E49: ３月 | F49: ４月 | G49: ５月 | H49: ６月 | I49: ７月 | J49: ８月 | K49: ９月 | L49: １０月 | M49: １１月 | N49: １２月 | O49: 合計
...

Sheet フォレストヒルズガーデン
A1: フォレストヒルズガーデン | B1: １月 | C1: ２月 | D1: ３月 | E1: ４月 | F1: ５月 | G1: ６月 | H1: ７月 | I1: ８月 | J1: ９月 | K1: １０月 | L1: １１月 | M1: １２月 | N1: 合計
A2: 目標売上 | N2: =SUM(B2:M2) -> 0
A3: 総売上 | B3: =B4+B5 -> 5670857 | C3: =C4+C5 -> 5411304 | D3: =D4+D5 -> 6110445 | E3: =E4+E5 -> 5535949 | F3: =F4+F5 -> 7265723 | G3: =G4+G5 -> 5640457 | H3: =H4+H5 -> 4902843 | I3: =I4+I5 -> 5877492 | ... N3: =N4+N5 -> 60057288
A4: 売上進捗 | B4: 1049020 | C4: 789471 | D4: 1488612 | E4: 914116 | F4: 2643890 | G4: 1018624 | H4: 281010 | I4: 1255659 | J4: 208200 | K4: 0 | L4: 75000 | M4: 0 | N4: 4595288
A5: 指定管理料 | B5: 4621837 | C5: 4621833 | D5: 4621833 | E5: 4621833 | F5: 4621833 | G5: 4621833 | H5: 4621833 | I5: 4621833 | J5: 4621833 | K5: 4621833 | L5: 4621833 | M5: 4621833 | N5: =SUM(B5:M5) -> 55462000
A6: 達成率 | B6: =B4/B2 -> #DIV/0! | C6: =C4/C2 -> #DIV/0! | D6: =D4/D2 -> #DIV/0! | E6: =E4/E2 -> #DIV/0! | F6: =F4/F2 -> #DIV/0! | G6: =G4/G2 -> #DIV/0! | H6: =H4/H2 -> #DIV/0! | I6: =I4/I2 -> #DIV/0! | ... N6: =N4/N2 -> #DIV/0!
A7: 差異 | B7: =B4-B2 -> 1049020 | C7: =C4-C2 -> 789471 | D7: =D4-D2 -> 1488612 | E7: =E4-E2 -> 914116 | F7: =F4-F2 -> 2643890 | G7: =G4-G2 -> 1018624 | H7: =H4-H2 -> 281010 | I7: =I4-I2 -> 1255659 | ... M7: =M4-M2 -> 0 | N7: =SUM(B7:M7) -> 9723602
A8: 稼働率 | B8: =B9/(8*29) -> 0.099137931 | C8: =C9/(8*29) -> 0.13362069 | D8: =D9/(8*31) -> 0.16129032 | E8: =E9/(8*30) -> 0.10833333 | F8: =F9/(8*31) -> 0.26209677 | G8: =G9/(8*30) -> 0.12083333 | H8: =H9/(8*31) -> 0.092741935 | I8: =I9/(8*31) -> 0.092741935 | J8: =J9/(8*30) -> 0.020833333 | K8: =K9/(8*31) -> 0.0040322581 | L8: =L9/(8*30) -> 0.033333333 | M8: =M9/(8*31) -> 0.0080645161 | N8: =N9/(8*365) -> 0.03869863
A9: 販売客室数 | B9: 23 | C9: 31 | D9: 40 | E9: 26 | F9: 65 | G9: 29 | H9: 23 | I9: 23 | J9: 5 | K9: 1 | L9: 8 | M9: 2 | N9: 113
A10: 利用人数 | B10: 98 | C10: 97 | D10: 122 | E10: 83 | F10: 214 | G10: 106 | H10: 88 | I10: 88 | J10: 15 | K10: 6 | L10: 23 | M10: 13 | N10: 397
A11: 客室単価 | B11: =B4/B9 -> 45609.565 | C11: =C4/C9 -> 25466.806 | D11: =D4/D9 -> 37215.3 | E11: =E4/E9 -> 35158.308 | F11: =F4/F9 -> 40675.231 | G11: =G4/G9 -> 35124.966 | H11: =H4/H9 -> 12217.826 | I11: =I4/I9 -> 54593.87 | ... N11: =N4/N9 -> 40666.265
A12: 客単価 | B12: =B4/B10 -> 10704.286 | C12: =C4/C10 -> 8138.8763 | D12: =D4/D10 -> 12201.738 | E12: =E4/E10 -> 11013.446 | F12: =F4/F10 -> 12354.626 | G12: =G4/G10 -> 9609.6604 | H12: =H4/H10 -> 3193.2955 | I12: =I4/I10 -> 14268.852 | ... N12: =N4/N10 -> 11575.033
A13: 昨年売上
A14: 昨年対比 | B14: =B4/B13 -> #DIV/0! | C14: =C4/C13 -> #DIV/0! | D14: =D4/D13 -> #DIV/0! | E14: =E4/E13 -> #DIV/0! | F14: =F4/F13 -> #DIV/0! | G14: =G4/G13 -> #DIV/0! | H14: =H4/H13 -> #DIV/0! | I14: =I4/I13 -> #DIV/0! | ... N14: =N4/N13 -> #DIV/0!
A16: 年間指定管理料：55,462,000円

Sheet マンスリー部門
A1: 2026年 マンスリー 売上目標及び売上実績
A2: TAKAYA | B2: １月 | C2: ２月 | D2: ３月 | E2: ４月 | F2: ５月 | G2: ６月 | H2: ７月 | I2: ８月 | J2: ９月 | K2: １０月 | L2: １１月 | M2: １２月 | N2: 合計
A3: 目標売上 | B3: 142000 | C3: 506000 | D3: 517000 | E3: 636000 | F3: 441000 | G3: 421980 | H3: 310000 | I3: 246000 | J3: 96000 | K3: 228000 | L3: 450000 | M3: 323000 | N3: 4316980
A4: 売上進捗 | B4: 251000 | C4: 308000 | D4: 651000 | E4: 455000 | F4: 272000 | G4: 195000 | H4: 78000 | I4: 120000 | J4: 0 | K4: 0 | L4: 0 | M4: 0 | N4: =SUM(B4:M4) -> 2330000
A5: 達成率 | B5: =B4/B3 -> 1.7676056 | C5: =C4/C3 -> 0.60869565 | D5: =D4/D3 -> 1.2591876 | E5: =E4/E3 -> 0.71540881 | F5: =F4/F3 -> 0.61678005 | G5: =G4/G3 -> 0.46210721 | H5: =H4/H3 -> 0.2516129 | I5: =I4/I3 -> 0.48780488 | ... N5: =N4/N3 -> 0.53972916
A6: 差異 | B6: =B4-B3 -> 109000 | C6: =C4-C3 -> -198000 | D6: =D4-D3 -> 134000 | E6: =E4-E3 -> -181000 | F6: =F4-F3 -> -169000 | G6: =G4-G3 -> -226980 | H6: =H4-H3 -> -232000 | I6: =I4-I3 -> -126000 | ... M6: =M4-M3 -> -323000 | N6: =SUM(B6:M6) -> -1986980
A7: 稼働率 | B7: =B8/(12*31) -> 0.23924731 | C7: =C8/(12*29) -> 0.31896552 | D7: =D8/(12*31) -> 0.56989247 | E7: =E8/(12*30) -> 0.41944444 | F7: =F8/(12*31) -> 0.22580645 | G7: =G8/(12*30) -> 0.18055556 | H7: =H8/(11*31) -> 0.076246334 | I7: =I8/(11*31) -> 0.14076246 | J7: =J8/(11*30) -> 0 | K7: =K8/(11*31) -> 0 | L7: =L8/(11*30) -> 0 | M7: =M8/(11*31) -> 0 | N7: =N8/(11*365) -> 0.19576588
A8: 販売客室数 | B8: 89 | C8: 111 | D8: 212 | E8: 151 | F8: 84 | G8: 65 | H8: 26 | I8: 48 | J8: 0 | K8: 0 | L8: 0 | M8: 0 | N8: =SUM(B8:M8) -> 786
A9: 利用人数 | B9: 89 | C9: 111 | D9: 212 | E9: 151 | F9: 84 | G9: 65 | H9: 26 | I9: 48 | J9: 0 | K9: 0 | L9: 0 | M9: 0 | N9: =SUM(B9:M9) -> 786
A10: 客室単価 | B10: =B4/B8 -> 2820.2247 | C10: =C4/C8 -> 2774.7748 | D10: =D4/D8 -> 3070.7547 | E10: =E4/E8 -> 3013.245 | F10: =F4/F8 -> 3238.0952 | G10: =G4/G8 -> 3000 | H10: =H4/H8 -> 3000 | I10: =I4/I8 -> 2500 | ... M10: =M4/M8 -> #DIV/0! | N10: =AVERAGE(B10:M10) -> #DIV/0!
A11: 客単価 | B11: =B4/B9 -> 2820.2247 | C11: =C4/C9 -> 2774.7748 | D11: =D4/D9 -> 3070.7547 | E11: =E4/E9 -> 3013.245 | F11: =F4/F9 -> 3238.0952 | G11: =G4/G9 -> 3000 | H11: =H4/H9 -> 3000 | I11: =I4/I9 -> 2500 | ... M11: =M4/M9 -> #DIV/0! | N11: =AVERAGE(B11:M11) -> #DIV/0!
A12: 昨年売上 | B12: 142000 | C12: 506000 | D12: 517000 | E12: 636000 | F12: 441000 | G12: 421980 | H12: 310000 | I12: 246000 | J12: 96000 | K12: 228000 | L12: 450000 | M12: 323000 | N12: 4316980
A13: 昨年対比 | B13: =B4/B12 -> 1.7676056 | C13: =C4/C12 -> 0.60869565 | D13: =D4/D12 -> 1.2591876 | E13: =E4/E12 -> 0.71540881 | F13: =F4/F12 -> 0.61678005 | G13: =G4/G12 -> 0.46210721 | H13: =H4/H12 -> 0.2516129 | I13: =I4/I12 -> 0.48780488 | ... N13: =N4/N12 -> 0.53972916
A14: 経費実績 | N14: =SUM(B14:M14) -> 0
A15: 売上-経費 | B15: =B4-B14 -> 251000 | C15: =C4-C14 -> 308000 | D15: =D4-D14 -> 651000 | E15: =E4-E14 -> 455000 | F15: =F4-F14 -> 272000 | G15: =G4-G14 -> 195000 | H15: =H4-H14 -> 78000 | I15: =I4-I14 -> 120000 | ... M15: =M4-M14 -> 0 | N15: =SUM(B15:M15) -> 2330000
A17: 壱番館 | B17: １月 | C17: ２月 | D17: ３月 | E17: ４月 | F17: ５月 | G17: ６月 | H17: ７月 | I17: ８月 | J17: ９月 | K17: １０月 | L17: １１月 | M17: １２月 | N17: 合計
A18: 目標売上 | B18: 276000 | C18: 162000 | D18: 189000 | E18: 103500 | F18: 164000 | G18: 165000 | H18: 127500 | I18: 217000 | J18: 142500 | K18: 0 | L18: 183000 | M18: 78000 | N18: 1807500
A19: 売上進捗 | B19: 155000 | C19: 110500 | D19: 66000 | E19: 101400 | F19: 24000 | G19: 45000 | H19: 0 | I19: 0 | J19: 0 | K19: 0 | L19: 0 | M19: 0 | N19: =SUM(B19:M19) -> 501900
A20: 達成率 | B20: =B19/B18 -> 0.5615942 | C20: =C19/C18 -> 0.68209877 | D20: =D19/D18 -> 0.34920635 | E20: =E19/E18 -> 0.97971014 | F20: =F19/F18 -> 0.14634146 | G20: =G19/G18 -> 0.27272727 | H20: =H19/H18 -> 0 | I20: =I19/I18 -> 0 | ... N20: =N19/N18 -> 0.27767635
A21: 差異 | B21: =B19-B18 -> -121000 | C21: =C19-C18 -> -51500 | D21: =D19-D18 -> -123000 | E21: =E19-E18 -> -2100 | F21: =F19-F18 -> -140000 | G21: =G19-G18 -> -120000 | H21: =H19-H18 -> -127500 | I21: =I19-I18 -> -217000 | ... M21: =M19-M18 -> -78000 | N21: =SUM(B21:M21) -> -1305600
A22: 稼働率 | B22: =B23/(6*31) -> 0.27956989 | C22: =C23/(6*29) -> 0.22988506 | D22: 0.47 | E22: =E23/(6*30) -> 0.2 | F22: =F23/(6*31) -> 0.043010753 | G22: =G23/(6*30) -> 0.1 | H22: =H23/(6*31) -> 0 | I22: =I23/(6*31) -> 0 | J22: =J23/(6*30) -> 0 | K22: =K23/(6*31) -> 0 | L22: =L23/(6*30) -> 0 | M22: =M23/(6*31) -> 0 | N22: =N23/(6*365) -> 0.080365297
A23: 販売客室数 | B23: 52 | C23: 40 | D23: 22 | E23: 36 | F23: 8 | G23: 18 | H23: 0 | I23: 0 | J23: 0 | K23: 0 | L23: 0 | M23: 0 | N23: =SUM(B23:M23) -> 176
A24: 利用人数 | B24: 52 | C24: 43 | D24: 22 | E24: 36 | F24: 8 | G24: 18 | H24: 0 | I24: 0 | J24: 0 | K24: 0 | L24: 0 | M24: 0 | N24: =SUM(B24:M24) -> 179
A25: 客室単価 | B25: =B19/B23 -> 2980.7692 | C25: 52 | D25: =D19/D23 -> 3000 | E25: =E19/E23 -> 2816.6667 | F25: =F19/F23 -> 3000 | G25: =G19/G23 -> 2500 | H25: =H19/H23 -> #DIV/0! | I25: =I19/I23 -> #DIV/0! | J25: =J19/J23 -> #DIV/0! | K25: =K19/K23 -> #DIV/0! | ... M25: =M19/M23 -> #DIV/0! | N25: =AVERAGE(B25:M25) -> #DIV/0!
A26: 客単価 | B26: =B19/B24 -> 2980.7692 | C26: =C19/C24 -> 2569.7674 | D26: =D19/D24 -> 3000 | E26: =E19/E24 -> 2816.6667 | F26: =F19/F24 -> 3000 | G26: =G19/G24 -> 2500 | H26: =H19/H24 -> #DIV/0! | I26: =I19/I24 -> #DIV/0! | ... M26: =M19/M24 -> #DIV/0! | N26: =AVERAGE(B26:M26) -> #DIV/0!
A27: 昨年売上 | B27: 276000 | C27: 162000 | D27: 189000 | E27: 103500 | F27: 164000 | G27: 165000 | H27: 127500 | I27: 217000 | J27: 142500 | K27: 0 | L27: 183000 | M27: 78000 | N27: 1807500
A28: 昨年対比 | B28: =B19/B27 -> 0.5615942 | C28: =C19/C27 -> 0.68209877 | D28: =D19/D27 -> 0.34920635 | E28: =E19/E27 -> 0.97971014 | F28: =F19/F27 -> 0.14634146 | G28: =G19/G27 -> 0.27272727 | H28: =H19/H27 -> 0 | I28: =I19/I27 -> 0 | ... N28: =N19/N27 -> 0.27767635
A29: 経費実績 | B29: =C99 -> -50293 | C29: =D99 -> -41060 | D29: =E99 -> -71751 | E29: =F99 -> 0 | F29: =G99 -> 0 | G29: =H99 -> 0 | H29: =I99 -> 0 | I29: =J99 -> 0 | ... M29: =N99 -> 0 | N29: =SUM(B29:M29) -> -163104
A30: 売上-経費 | B30: =B19-B29 -> 205293 | C30: =C19-C29 -> 151560 | D30: =D19-D29 -> 137751 | E30: =E19-E29 -> 101400 | F30: =F19-F29 -> 24000 | G30: =G19-G29 -> 45000 | H30: =H19-H29 -> 0 | I30: =I19-I29 -> 0 | ... M30: =M19-M29 -> 0 | N30: =SUM(B30:M30) -> 665004
A32: 弐番館 | B32: １月 | C32: ２月 | D32: ３月 | E32: ４月 | F32: ５月 | G32: ６月 | H32: ７月 | I32: ８月 | J32: ９月 | K32: １０月 | L32: １１月 | M32: １２月 | N32: 合計
A33: 目標売上 | B33: 60000 | C33: 121500 | D33: 69000 | E33: 58000 | F33: 9000 | G33: 108000 | H33: 63000 | I33: 56500 | J33: 44000 | K33: 57000 | L33: 48000 | M33: 54500 | N33: 748500
A34: 売上進捗 | B34: 0 | C34: 42500 | D34: 0 | E34: 90000 | F34: 93000 | G34: 46000 | H34: 57000 | I34: 75000 | J34: 0 | K34: 0 | L34: 0 | M34: 0 | N34: =SUM(B34:M34) -> 403500
A35: 達成率 | B35: =B34/B33 -> 0 | C35: =C34/C33 -> 0.34979424 | D35: =D34/D33 -> 0 | E35: =E34/E33 -> 1.5517241 | F35: =F34/F33 -> 10.333333 | G35: =G34/G33 -> 0.42592593 | H35: =H34/H33 -> 0.9047619 | I35: =I34/I33 -> 1.3274336 | ... N35: =N34/N33 -> 0.53907816
A36: 売上目標差異 | B36: =B34-B33 -> -60000 | C36: =C34-C33 -> -79000 | D36: =D34-D33 -> -69000 | E36: =E34-E33 -> 32000 | F36: =F34-F33 -> 84000 | G36: =G34-G33 -> -62000 | H36: =H34-H33 -> -6000 | I36: =I34-I33 -> 18500 | ... M36: =M34-M33 -> -54500 | N36: =SUM(B36:M36) -> -345000
A37: 稼働率 | B37: =B38/(2*31) -> 0 | C37: =C38/(2*29) -> 0.29310345 | D37: =D38/(2*31) -> 0 | E37: =E38/(2*30) -> 0.5 | F37: =F38/(2*31) -> 0.5 | G37: =G38/(2*30) -> 0.2 | H37: =H38/(2*31) -> 0.30645161 | I37: =I38/(2*31) -> 0.48387097 | J37: =J38/(2*30) -> 0 | K37: =K38/(2*31) -> 0 | L37: =L38/(2*30) -> 0 | M37: =M38/(2*31) -> 0 | N37: =N38/(2*365) -> 0.19041096
A38: 販売客室数 | B38: 0 | C38: 17 | D38: 0 | E38: 30 | F38: 31 | G38: 12 | H38: 19 | I38: 30 | J38: 0 | K38: 0 | L38: 0 | M38: 0 | N38: =SUM(B38:M38) -> 139
A39: 利用人数 | B39: 0 | C39: 17 | D39: 0 | E39: 30 | F39: 31 | G39: 12 | H39: 19 | I39: 30 | J39: 0 | K39: 0 | L39: 0 | M39: 0 | N39: =SUM(B39:M39) -> 139
A40: 客室単価 | B40: =B34/B38 -> #DIV/0! | C40: =C34/C38 -> 2500 | D40: =D34/D38 -> #DIV/0! | E40: =E34/E38 -> 3000 | F40: =F34/F38 -> 3000 | G40: =G34/G38 -> 3833.3333 | H40: =H34/H38 -> 3000 | I40: =I34/I38 -> 2500 | ... M40: =M34/M38 -> #DIV/0! | N40: =AVERAGE(B40:M40) -> #DIV/0!
A41: 客単価 | B41: =B34/B39 -> #DIV/0! | C41: =C34/C39 -> 2500 | D41: =D34/D39 -> #DIV/0! | E41: =E34/E39 -> 3000 | F41: =F34/F39 -> 3000 | G41: =G34/G39 -> 3833.3333 | H41: =H34/H39 -> 3000 | I41: =I34/I39 -> 2500 | ... M41: =M34/M39 -> #DIV/0! | N41: =AVERAGE(B41:M41) -> #DIV/0!
A42: 昨年売上 | B42: 60000 | C42: 121500 | D42: 69000 | E42: 58000 | F42: 9000 | G42: 108000 | H42: 63000 | I42: 56500 | J42: 44000 | K42: 57000 | L42: 48000 | M42: 54500 | N42: 748500
...

Sheet 竹原
A1: GR竹原マンスリー 及び 海の駅 売上推移表
D2: 1月 | E2: 2月 | F2: 3月 | G2: 4月 | H2: 5月 | I2: 6月 | J2: 7月 | K2: 8月 | L2: 9月 | M2: 10月 | N2: 11月 | O2: 12月 | P2: 合計
A3: 総売上高(GOR) | D3: =D4+D18+D28+D30+D34+D38 -> 1247037 | E3: =E4+E18+E28+E30+E34+E38 -> 1238472 | F3: =F4+F18+F28+F30+F34+F38 -> 1370148 | G3: =G4+G18+G28+G30+G34+G38 -> 1202444 | H3: =H4+H18+H28+H30+H34+H38 -> 789000 | I3: =I4+I18+I28+I30+I34+I38 -> 683000 | J3: =J4+J18+J28+J30+J34+J38 -> 683000 | K3: =K4+K18+K28+K30+K34+K38 -> 683000 | ... P3: =P4+P18+P28+P30+P34+P38 -> 407000
A4: マンスリー売上 | D4: =マンスリー部門!B64 -> 46000 | E4: 16500 | F4: =マンスリー部門!D64 -> 63000 | G4: =マンスリー部門!E64 -> 157500 | H4: =マンスリー部門!F64 -> 106000 | I4: =マンスリー部門!G64 -> 0 | J4: =マンスリー部門!H64 -> 0 | K4: =マンスリー部門!I64 -> 0 | L4: =マンスリー部門!J64 -> 0 | M4: =マンスリー部門!K64 -> 0 | ... P4: =マンスリー部門!N64 -> 407000
A5: 販売室数 | D5: =マンスリー部門!B68 -> 9 | E5: 4 | F5: =マンスリー部門!D68 -> 14 | G5: =マンスリー部門!E68 -> 35 | H5: =マンスリー部門!F68 -> 23 | I5: =マンスリー部門!G68 -> 0 | J5: =マンスリー部門!H68 -> 0 | K5: =マンスリー部門!I68 -> 0 | L5: =マンスリー部門!J68 -> 0 | M5: =マンスリー部門!K68 -> 0 | ... P5: =マンスリー部門!N68 -> 89
A6: 販売人数 | D6: =マンスリー部門!B69 -> 12 | E6: 4 | F6: =マンスリー部門!D69 -> 14 | G6: =マンスリー部門!E69 -> 35 | H6: =マンスリー部門!F69 -> 24 | I6: =マンスリー部門!G69 -> 0 | J6: =マンスリー部門!H69 -> 0 | K6: =マンスリー部門!I69 -> 0 | L6: =マンスリー部門!J69 -> 0 | M6: =マンスリー部門!K69 -> 0 | ... P6: =マンスリー部門!N69 -> 93
A7: 大人
A8: 子供
A9: 販売可能室数
A10: 販売可能人員
A11: 客室稼働率(Occ)
A12: 人員稼働率
A13: 1室平均稼働人員
A14: ADR
A15: APR
A16: Rev.PAR
A18: レストラン 売 上 | D18: 281140 | E18: 294620 | F18: 388608 | G18: 350644
A19: 会計数 | D19: 128 | E19: 121 | F19: 180 | G19: 158
A20: 会計単価 | D20: 2196 | E20: 2435 | F20: 2159 | G20: 2219
A21: 客数 | D21: 188 | E21: 196 | F21: 329 | G21: 230
A22: 客単価 | D22: 1495 | E22: 1503 | F22: 1181 | G22: 1525
A23: 商品数 | D23: 311 | E23: 337 | F23: 453 | G23: 435
A24: 現金 | D24: 187940 | E24: 206410 | F24: 271730 | G24: 288744
A25: 現金その他 | D25: 93200 | E25: 88210 | F25: 116878 | G25: 61900
A26: 割引額 | D26: 0
A28: 駐車場代
A30: 委託料 | D30: =SUM(D31:D32) -> 683000 | E30: =SUM(E31:E32) -> 683000 | F30: =SUM(F31:F32) -> 683000 | G30: =SUM(G31:G32) -> 683000 | H30: =SUM(H31:H32) -> 683000 | I30: =SUM(I31:I32) -> 683000 | J30: =SUM(J31:J32) -> 683000 | K30: =SUM(K31:K32) -> 683000 | ... P30: =SUM(P31:P32) -> 0
A31: 内訳 | B31: 海の駅指定管理（竹原市） | D31: 650000 | E31: 650000 | F31: 650000 | G31: 650000 | H31: 650000 | I31: 650000 | J31: 650000 | K31: 650000 | L31: 650000 | M31: 650000 | N31: 650000 | O31: 650000
B32: 駐車場管理（アマノ） | D32: 33000 | E32: 33000 | F32: 33000 | G32: 33000 | H32: 33000 | I32: 33000 | J32: 33000 | K32: 33000 | L32: 33000 | M32: 33000 | N32: 33000 | O32: 33000
A34: 利用料 | D34: =D35+D36 -> 20700 | E34: =E35+E36 -> 16850 | F34: =F35+F36 -> 27700 | G34: =G35+G36 -> 11300 | H34: =H35+H36 -> 0 | I34: =I35+I36 -> 0 | J34: =J35+J36 -> 0 | K34: =K35+K36 -> 0 | ... P34: =P35+P36 -> 0
A35: 内訳 | B35: 交流ｽﾍﾟｰｽ | D35: 20300 | E35: 16850 | F35: 27300 | G35: 10700
B36: ﾜｰｸｽﾍﾟｰｽ | D36: 400 | E36: 0 | F36: 400 | G36: 600
A38: 家賃請求 | D38: =SUM(D39:D44) -> 216197 | E38: =SUM(E39:E44) -> 227502 | F38: =SUM(F39:F44) -> 207840 | G38: =SUM(G39:G44) -> 0 | H38: =SUM(H39:H44) -> 0 | I38: =SUM(I39:I44) -> 0 | J38: =SUM(J39:J44) -> 0 | K38: =SUM(K39:K44) -> 0 | ... P38: =SUM(P39:P44) -> 0
A39: 内訳 | B39: ﾌｪﾘｰ同盟 | D39: 18542 | E39: 19484 | F39: 17846
B40: 大崎汽船 | D40: 35555 | E40: 37363 | F40: 34219
B41: 竹原海運 | D41: 72821 | E41: 75961 | F41: 70499
B42: 契島運輸 | D42: 10594 | E42: 10909 | F42: 10360
B43: 前川酒店 | D43: 78685 | E43: 83785 | F43: 74916
B44: ﾚｽﾄﾗﾝ | D44: 0
D46: 1月 | E46: 2月 | F46: 3月 | G46: 4月 | H46: 5月 | I46: 6月 | J46: 7月 | K46: 8月 | L46: 9月 | M46: 10月 | N46: 11月 | O46: 12月 | P46: 合計
...

Sheet サウナ
A1: サウナ | B1: １月 | C1: ２月 | D1: ３月 | E1: ４月 | F1: ５月 | G1: ６月 | H1: ７月 | I1: ８月 | J1: ９月 | K1: １０月 | L1: １１月 | M1: １２月 | N1: 合計
A2: 目標売上 | B2: 0 | C2: 134014 | D2: 118994 | E2: 83911 | F2: 90367 | G2: 116684 | H2: 101322 | I2: 186370 | J2: 56609 | K2: 156028 | L2: 71628 | M2: 153076 | N2: 1269003
A3: 売上進捗 | B3: 0 | C3: 113218 | D3: 134706 | E3: 121831 | F3: 36276 | G3: 0 | H3: 0 | I3: 0 | J3: 0 | K3: 0 | L3: 0 | M3: 0 | N3: =SUM(B3:M3) -> 406031
A4: 達成率 | B4: =B3/B2 -> #DIV/0! | C4: =C3/C2 -> 0.84482218 | D4: =D3/D2 -> 1.1320403 | E4: =E3/E2 -> 1.4519074 | F4: =F3/F2 -> 0.40142973 | G4: =G3/G2 -> 0 | H4: =H3/H2 -> 0 | I4: =I3/I2 -> 0 | ... N4: =N3/N2 -> 0.31996063
A5: 予約件数 | B5: 0 | C5: 4 | D5: 5 | E5: 4 | F5: 1 | G5: 0 | H5: 0 | I5: 0 | J5: 0 | K5: 0 | L5: 0 | M5: 0 | N5: =SUM(B5:M5) -> 14
A6: 利用人数 | B6: 0 | C6: 8 | D6: 10 | E6: 9 | F6: 2 | G6: 0 | H6: 0 | I6: 0 | J6: 0 | K6: 0 | L6: 0 | M6: 0 | N6: =SUM(B6:M6) -> 29
A7: 客単価 | B7: =B3/B6 -> #DIV/0! | C7: =C3/C6 -> 14152.25 | D7: =D3/D6 -> 13470.6 | E7: =E3/E6 -> 13536.778 | F7: =F3/F6 -> 18138 | G7: =G3/G6 -> #DIV/0! | H7: =H3/H6 -> #DIV/0! | I7: =I3/I6 -> #DIV/0! | ... M7: =M3/M6 -> #DIV/0! | N7: =AVERAGE(B7:M7) -> #DIV/0!
A8: 稼働率 | B8: =B5/(1*31) -> 0 | C8: =C5/(1*28) -> 0.14285714 | D8: =D5/(1*31) -> 0.16129032 | E8: =E5/(1*30) -> 0.13333333 | F8: =F5/(1*31) -> 0.032258065 | G8: =G5/(1*30) -> 0 | H8: =H5/(1*30) -> 0 | I8: =I5/(1*31) -> 0 | J8: =J5/(1*30) -> 0 | K8: =K5/(1*31) -> 0 | L8: =L5/(1*30) -> 0 | M8: =M5/(1*31) -> 0 | N8: =N5/(1*365) -> 0.038356164
A9: 売上目標差異 | B9: =B3-B2 -> 0 | C9: =C3-C2 -> -20796 | D9: =D3-D2 -> 15712 | E9: =E3-E2 -> 37920 | F9: =F3-F2 -> -54091 | G9: =G3-G2 -> -116684 | H9: =H3-H2 -> -101322 | I9: =I3-I2 -> -186370 | ... M9: =M3-M2 -> -153076 | N9: =SUM(B9:M9) -> -862972
A10: 昨年売上 | B10: 0 | C10: 134014 | D10: 118994 | E10: 83911 | F10: 90367 | G10: 116684 | H10: 101322 | I10: 186370 | J10: 56609 | K10: 156028 | L10: 71628 | M10: 153076 | N10: 1269003
A11: 昨年対比 | B11: =B3/B10 -> #DIV/0! | C11: =C3/C10 -> 0.84482218 | D11: =D3/D10 -> 1.1320403 | E11: =E3/E10 -> 1.4519074 | F11: =F3/F10 -> 0.40142973 | G11: =G3/G10 -> 0 | H11: =H3/H10 -> 0 | I11: =I3/I10 -> 0 | ... N11: =N3/N10 -> 0.31996063
A12: 経費予測 | N12: =SUM(B12:M12) -> 0
A13: 昨年経費 | N13: =SUM(B13:M13) -> 0
A14: 経費実績 | N14: =SUM(B14:M14) -> 0
A15: 経費差異 | B15: =B12-B14 -> 0 | C15: =C12-C13 -> 0 | D15: =D12-D13 -> 0 | E15: =E12-E13 -> 0 | F15: =F12-F13 -> 0 | G15: =G12-G14 -> 0 | H15: =H12-H14 -> 0 | I15: =I12-I14 -> 0 | J15: =J12-J14 -> 0 | K15: =K12-K14 -> 0 | L15: =L12-L14 -> 0 | M15: 18000000 | N15: =SUM(B15:M15) -> 18000000
A16: 差引収支 | B16: =B3-B14 -> 0 | C16: =C3-C13 -> 113218 | D16: =D3-D13 -> 134706 | E16: =E3-E13 -> 121831 | F16: =F3-F13 -> 36276 | G16: =G3-G12 -> 0 | H16: =H3-H12 -> 0 | I16: =I3-I12 -> 0 | J16: =J3-J12 -> 0 | K16: =K3-K12 -> 0 | L16: =L3-L12 -> 0 | M16: =M3-M12 -> 0 | N16: =SUM(B16:M16) -> 406031
