Workbook

Sheet トップ
A1: 全社統合 資金管理ファイル v10（シート集約版＋OTA予測機能）
A3: ■ シート構成（19シート）
A5: 分類 | B5: シート名 | C5: 内容
A6: 概観 | B6: 全社合算サマリー | C6: 6社合計の月別ダッシュボード
A7: 概観 | B7: 全社月次サマリー | C7: 6社×4ヶ月の明細
A8: マスター | B8: マスター_物件 | C8: 物件→会社マッピング
A9: マスター | B9: マスター_勘定科目 | C9: 勘定科目→資金繰り項目マッピング
A10: マスター | B10: マスター_OTA | C10: OTA別の入金サイクル設定
A11: 入力 | B11: 入金入力 | C11: 全社統合の入金入力（会社列でフィルター）
A12: 入力 | B12: 未払予定一覧 | C12: 全社統合の支出予定／カード枠回復統合（会社列でフィルター）
A13: 入力 | B13: 売上入力 | C13: OTA別売上入力（月別／施設別／OTA別）
A14: 計算 | B14: 入金予測 | C14: 売上入力 × OTAサイクル → 予測入金（自動計算）
A15: 日次 | B15: 日次_<会社名> | C15: 会社別の日次キャッシュフロー（5-8月 縦積み・6シート）
A16: 資金繰り | B16: 資金繰り_* | C16: 資金繰り表 4シート（5月起点12ヶ月）
A18: ■ v10での主な変更
A20: ・入金入力／未払予定一覧を会社列で1シートに統合（旧18シート → 2シート）
A21: ・カード枠回復を未払予定一覧の「種別」列で統合（旧6シート → 0シート、未払一覧側へ集約）
A22: ・日次キャッシュフローを社別1枚に4ヶ月縦積み（旧24シート → 6シート）
A23: ・マスター_OTA／売上入力／入金予測を新規追加（OTA別入金サイクル予測）
A24: ・レガシーシート（5月入出金一覧／取引先別集計／注記）を削除
A25: ・シート総数：51 → 19（-32枚 / -63%）

Sheet 全社合算サマリー
A1: 全社合算サマリー（6社合計）
A2: 6社の月別キャッシュフロー集計
A4: ■ 月別合算（6社合計）
A5: 月 | B5: 入金（円） | C5: 支出（円） | D5: 当月差引（円） | E5: 月末累計差引（円） | F5: カード枠回復額（円） | G5: 月末使用可能額（円）
A6: 5月 | B6: =日次_レジデンス!B37+日次_リゾート!B37+日次_モーテル!B37+日次_ザック!B37+日次_ワールド・レイ!B37+日次_ココ・ユニバース!B37 -> 45366181 | C6: =日次_レジデンス!C37+日次_リゾート!C37+日次_モーテル!C37+日次_ザック!C37+日次_ワールド・レイ!C37+日次_ココ・ユニバース!C37 -> 48481617 | D6: =日次_レジデンス!D37+日次_リゾート!D37+日次_モーテル!D37+日次_ザック!D37+日次_ワールド・レイ!D37+日次_ココ・ユニバース!D37 -> -8385436.4 | E6: =日次_レジデンス!E37+日次_リゾート!E37+日次_モーテル!E37+日次_ザック!E37+日次_ワールド・レイ!E37+日次_ココ・ユニバース!E37 -> -8385436.4 | F6: =日次_レジデンス!F37+日次_リゾート!F37+日次_モーテル!F37+日次_ザック!F37+日次_ワールド・レイ!F37+日次_ココ・ユニバース!F37 -> 5270000 | G6: =日次_レジデンス!G37+日次_リゾート!G37+日次_モーテル!G37+日次_ザック!G37+日次_ワールド・レイ!G37+日次_ココ・ユニバース!G37 -> -3115436.4
A7: 6月 | B7: =日次_レジデンス!B70+日次_リゾート!B70+日次_モーテル!B70+日次_ザック!B70+日次_ワールド・レイ!B70+日次_ココ・ユニバース!B70 -> 34253666 | C7: =日次_レジデンス!C70+日次_リゾート!C70+日次_モーテル!C70+日次_ザック!C70+日次_ワールド・レイ!C70+日次_ココ・ユニバース!C70 -> 39932206 | D7: =日次_レジデンス!D70+日次_リゾート!D70+日次_モーテル!D70+日次_ザック!D70+日次_ワールド・レイ!D70+日次_ココ・ユニバース!D70 -> -5678540.3 | E7: =日次_レジデンス!E70+日次_リゾート!E70+日次_モーテル!E70+日次_ザック!E70+日次_ワールド・レイ!E70+日次_ココ・ユニバース!E70 -> -14063977 | F7: =日次_レジデンス!F70+日次_リゾート!F70+日次_モーテル!F70+日次_ザック!F70+日次_ワールド・レイ!F70+日次_ココ・ユニバース!F70 -> 0 | G7: =日次_レジデンス!G70+日次_リゾート!G70+日次_モーテル!G70+日次_ザック!G70+日次_ワールド・レイ!G70+日次_ココ・ユニバース!G70 -> -8793976.7
A8: 7月 | B8: =日次_レジデンス!B104+日次_リゾート!B104+日次_モーテル!B104+日次_ザック!B104+日次_ワールド・レイ!B104+日次_ココ・ユニバース!B104 -> 30777994 | C8: =日次_レジデンス!C104+日次_リゾート!C104+日次_モーテル!C104+日次_ザック!C104+日次_ワールド・レイ!C104+日次_ココ・ユニバース!C104 -> 37223663 | D8: =日次_レジデンス!D104+日次_リゾート!D104+日次_モーテル!D104+日次_ザック!D104+日次_ワールド・レイ!D104+日次_ココ・ユニバース!D104 -> -6445668.6 | E8: =日次_レジデンス!E104+日次_リゾート!E104+日次_モーテル!E104+日次_ザック!E104+日次_ワールド・レイ!E104+日次_ココ・ユニバース!E104 -> -20509645 | F8: =日次_レジデンス!F104+日次_リゾート!F104+日次_モーテル!F104+日次_ザック!F104+日次_ワールド・レイ!F104+日次_ココ・ユニバース!F104 -> 0 | G8: =日次_レジデンス!G104+日次_リゾート!G104+日次_モーテル!G104+日次_ザック!G104+日次_ワールド・レイ!G104+日次_ココ・ユニバース!G104 -> -15239645
A9: 8月 | B9: =日次_レジデンス!B138+日次_リゾート!B138+日次_モーテル!B138+日次_ザック!B138+日次_ワールド・レイ!B138+日次_ココ・ユニバース!B138 -> 39570607 | C9: =日次_レジデンス!C138+日次_リゾート!C138+日次_モーテル!C138+日次_ザック!C138+日次_ワールド・レイ!C138+日次_ココ・ユニバース!C138 -> 38086901 | D9: =日次_レジデンス!D138+日次_リゾート!D138+日次_モーテル!D138+日次_ザック!D138+日次_ワールド・レイ!D138+日次_ココ・ユニバース!D138 -> 1483706.2 | E9: =日次_レジデンス!E138+日次_リゾート!E138+日次_モーテル!E138+日次_ザック!E138+日次_ワールド・レイ!E138+日次_ココ・ユニバース!E138 -> -19025939 | F9: =日次_レジデンス!F138+日次_リゾート!F138+日次_モーテル!F138+日次_ザック!F138+日次_ワールド・レイ!F138+日次_ココ・ユニバース!F138 -> 0 | G9: =日次_レジデンス!G138+日次_リゾート!G138+日次_モーテル!G138+日次_ザック!G138+日次_ワールド・レイ!G138+日次_ココ・ユニバース!G138 -> -13755939
A10: 4ヶ月合計 | B10: =SUM(B6:B9) -> 1.4996845e+08 | C10: =SUM(C6:C9) -> 163724387 | D10: =SUM(D6:D9) -> -19025939 | E10: =E9 -> -19025939 | F10: =SUM(F6:F9) -> 5270000 | G10: =G9 -> -13755939

Sheet 全社月次サマリー
A1: 全社月次サマリー（6社×4ヶ月）
A3: 会社 | B3: 月 | C3: 入金（円） | D3: 支出（円） | E3: 当月差引（円） | F3: 月末累計差引（円） | G3: カード枠回復額（円） | H3: 月末使用可能額（円）
A4: レジデンス | B4: 5月 | C4: =日次_レジデンス!B37 -> 9692753 | D4: =日次_レジデンス!C37 -> 6684291 | E4: =日次_レジデンス!D37 -> 3008462 | F4: =日次_レジデンス!E37 -> 3008462 | G4: =日次_レジデンス!F37 -> 0 | H4: =日次_レジデンス!G37 -> 3008462
A5: レジデンス | B5: 6月 | C5: =日次_レジデンス!B70 -> 0 | D5: =日次_レジデンス!C70 -> 6177138 | E5: =日次_レジデンス!D70 -> -6177138 | F5: =日次_レジデンス!E70 -> -3168676 | G5: =日次_レジデンス!F70 -> 0 | H5: =日次_レジデンス!G70 -> -3168676
A6: レジデンス | B6: 7月 | C6: =日次_レジデンス!B104 -> 0 | D6: =日次_レジデンス!C104 -> 6177138 | E6: =日次_レジデンス!D104 -> -6177138 | F6: =日次_レジデンス!E104 -> -9345814 | G6: =日次_レジデンス!F104 -> 0 | H6: =日次_レジデンス!G104 -> -9345814
A7: レジデンス | B7: 8月 | C7: =日次_レジデンス!B138 -> 0 | D7: =日次_レジデンス!C138 -> 6177138 | E7: =日次_レジデンス!D138 -> -6177138 | F7: =日次_レジデンス!E138 -> -15522952 | G7: =日次_レジデンス!F138 -> 0 | H7: =日次_レジデンス!G138 -> -15522952
A8: レジデンス | B8: 4ヶ月合計 | C8: =SUM(C4:C7) -> 9692753 | D8: =SUM(D4:D7) -> 25215705 | E8: =SUM(E4:E7) -> -15522952 | F8: =F7 -> -15522952 | G8: =SUM(G4:G7) -> 0 | H8: =H7 -> -15522952
A10: リゾート | B10: 5月 | C10: =日次_リゾート!B37 -> 24503948 | D10: =日次_リゾート!C37 -> 34253022 | E10: =日次_リゾート!D37 -> -15019074 | F10: =日次_リゾート!E37 -> -15019074 | G10: =日次_リゾート!F37 -> 5270000 | H10: =日次_リゾート!G37 -> -9749074.1
A11: リゾート | B11: 6月 | C11: =日次_リゾート!B70 -> 25595864 | D11: =日次_リゾート!C70 -> 30740710 | E11: =日次_リゾート!D70 -> -5144846.5 | F11: =日次_リゾート!E70 -> -20163921 | G11: =日次_リゾート!F70 -> 0 | H11: =日次_リゾート!G70 -> -14893921
A12: リゾート | B12: 7月 | C12: =日次_リゾート!B104 -> 23257259 | D12: =日次_リゾート!C104 -> 28032167 | E12: =日次_リゾート!D104 -> -4774908.2 | F12: =日次_リゾート!E104 -> -24938829 | G12: =日次_リゾート!F104 -> 0 | H12: =日次_リゾート!G104 -> -19668829
A13: リゾート | B13: 8月 | C13: =日次_リゾート!B138 -> 30710595 | D13: =日次_リゾート!C138 -> 29167405 | E13: =日次_リゾート!D138 -> 1543190.2 | F13: =日次_リゾート!E138 -> -23395639 | G13: =日次_リゾート!F138 -> 0 | H13: =日次_リゾート!G138 -> -18125639
A14: リゾート | B14: 4ヶ月合計 | C14: =SUM(C10:C13) -> 1.0406767e+08 | D14: =SUM(D10:D13) -> 122193304 | E14: =SUM(E10:E13) -> -23395639 | F14: =F13 -> -23395639 | G14: =SUM(G10:G13) -> 5270000 | H14: =H13 -> -18125639
A16: モーテル | B16: 5月 | C16: =日次_モーテル!B37 -> 8046038.3 | D16: =日次_モーテル!C37 -> 1998914 | E16: =日次_モーテル!D37 -> 6047124.3 | F16: =日次_モーテル!E37 -> 6047124.3 | G16: =日次_モーテル!F37 -> 0 | H16: =日次_モーテル!G37 -> 6047124.3
A17: モーテル | B17: 6月 | C17: =日次_モーテル!B70 -> 4753795.2 | D17: =日次_モーテル!C70 -> 185173 | E17: =日次_モーテル!D70 -> 4568622.2 | F17: =日次_モーテル!E70 -> 10615746 | G17: =日次_モーテル!F70 -> 0 | H17: =日次_モーテル!G70 -> 10615746
A18: モーテル | B18: 7月 | C18: =日次_モーテル!B104 -> 3640308 | D18: =日次_モーテル!C104 -> 185173 | E18: =日次_モーテル!D104 -> 3455135 | F18: =日次_モーテル!E104 -> 14070881 | G18: =日次_モーテル!F104 -> 0 | H18: =日次_モーテル!G104 -> 14070881
A19: モーテル | B19: 8月 | C19: =日次_モーテル!B138 -> 4983212 | D19: =日次_モーテル!C138 -> 185173 | E19: =日次_モーテル!D138 -> 4798039 | F19: =日次_モーテル!E138 -> 18868920 | G19: =日次_モーテル!F138 -> 0 | H19: =日次_モーテル!G138 -> 18868920
A20: モーテル | B20: 4ヶ月合計 | C20: =SUM(C16:C19) -> 21423353 | D20: =SUM(D16:D19) -> 2554433 | E20: =SUM(E16:E19) -> 18868920 | F20: =F19 -> 18868920 | G20: =SUM(G16:G19) -> 0 | H20: =H19 -> 18868920
A22: ザック | B22: 5月 | C22: =日次_ザック!B37 -> 5441.4 | D22: =日次_ザック!C37 -> 278050 | E22: =日次_ザック!D37 -> -272608.6 | F22: =日次_ザック!E37 -> -272608.6 | G22: =日次_ザック!F37 -> 0 | H22: =日次_ザック!G37 -> -272608.6
A23: ザック | B23: 6月 | C23: =日次_ザック!B70 -> 27207 | D23: =日次_ザック!C70 -> 272000 | E23: =日次_ザック!D70 -> -244793 | F23: =日次_ザック!E70 -> -517401.6 | G23: =日次_ザック!F70 -> 0 | H23: =日次_ザック!G70 -> -517401.6
A24: ザック | B24: 7月 | C24: =日次_ザック!B104 -> 3627.6 | D24: =日次_ザック!C104 -> 272000 | E24: =日次_ザック!D104 -> -268372.4 | F24: =日次_ザック!E104 -> -785774 | G24: =日次_ザック!F104 -> 0 | H24: =日次_ザック!G104 -> -785774
A25: ザック | B25: 8月 | C25: =日次_ザック!B138 -> 0 | D25: =日次_ザック!C138 -> 0 | E25: =日次_ザック!D138 -> 0 | F25: =日次_ザック!E138 -> -785774 | G25: =日次_ザック!F138 -> 0 | H25: =日次_ザック!G138 -> -785774
A26: ザック | B26: 4ヶ月合計 | C26: =SUM(C22:C25) -> 36276 | D26: =SUM(D22:D25) -> 822050 | E26: =SUM(E22:E25) -> -785774 | F26: =F25 -> -785774 | G26: =SUM(G22:G25) -> 0 | H26: =H25 -> -785774
A28: ワールド・レイ | B28: 5月 | C28: =日次_ワールド・レイ!B37 -> 863000 | D28: =日次_ワールド・レイ!C37 -> 2163774 | E28: =日次_ワールド・レイ!D37 -> -1300774 | F28: =日次_ワールド・レイ!E37 -> -1300774 | G28: =日次_ワールド・レイ!F37 -> 0 | H28: =日次_ワールド・レイ!G37 -> -1300774
A29: ワールド・レイ | B29: 6月 | C29: =日次_ワールド・レイ!B70 -> 300000 | D29: =日次_ワールド・レイ!C70 -> 1441937 | E29: =日次_ワールド・レイ!D70 -> -1141937 | F29: =日次_ワールド・レイ!E70 -> -2442711 | G29: =日次_ワールド・レイ!F70 -> 0 | H29: =日次_ワールド・レイ!G70 -> -2442711
A30: ワールド・レイ | B30: 7月 | C30: =日次_ワールド・レイ!B104 -> 300000 | D30: =日次_ワールド・レイ!C104 -> 1441937 | E30: =日次_ワールド・レイ!D104 -> -1141937 | F30: =日次_ワールド・レイ!E104 -> -3584648 | G30: =日次_ワールド・レイ!F104 -> 0 | H30: =日次_ワールド・レイ!G104 -> -3584648
A31: ワールド・レイ | B31: 8月 | C31: =日次_ワールド・レイ!B138 -> 300000 | D31: =日次_ワールド・レイ!C138 -> 1441937 | E31: =日次_ワールド・レイ!D138 -> -1141937 | F31: =日次_ワールド・レイ!E138 -> -4726585 | G31: =日次_ワールド・レイ!F138 -> 0 | H31: =日次_ワールド・レイ!G138 -> -4726585
A32: ワールド・レイ | B32: 4ヶ月合計 | C32: =SUM(C28:C31) -> 1763000 | D32: =SUM(D28:D31) -> 6489585 | E32: =SUM(E28:E31) -> -4726585 | F32: =F31 -> -4726585 | G32: =SUM(G28:G31) -> 0 | H32: =H31 -> -4726585
A34: ココ・ユニバース | B34: 5月 | C34: =日次_ココ・ユニバース!B37 -> 2255000 | D34: =日次_ココ・ユニバース!C37 -> 3103566 | E34: =日次_ココ・ユニバース!D37 -> -848566 | F34: =日次_ココ・ユニバース!E37 -> -848566 | G34: =日次_ココ・ユニバース!F37 -> 0 | H34: =日次_ココ・ユニバース!G37 -> -848566
A35: ココ・ユニバース | B35: 6月 | C35: =日次_ココ・ユニバース!B70 -> 3576800 | D35: =日次_ココ・ユニバース!C70 -> 1115248 | E35: =日次_ココ・ユニバース!D70 -> 2461552 | F35: =日次_ココ・ユニバース!E70 -> 1612986 | G35: =日次_ココ・ユニバース!F70 -> 0 | H35: =日次_ココ・ユニバース!G70 -> 1612986
A36: ココ・ユニバース | B36: 7月 | C36: =日次_ココ・ユニバース!B104 -> 3576800 | D36: =日次_ココ・ユニバース!C104 -> 1115248 | E36: =日次_ココ・ユニバース!D104 -> 2461552 | F36: =日次_ココ・ユニバース!E104 -> 4074538 | G36: =日次_ココ・ユニバース!F104 -> 0 | H36: =日次_ココ・ユニバース!G104 -> 4074538
A37: ココ・ユニバース | B37: 8月 | C37: =日次_ココ・ユニバース!B138 -> 3576800 | D37: =日次_ココ・ユニバース!C138 -> 1115248 | E37: =日次_ココ・ユニバース!D138 -> 2461552 | F37: =日次_ココ・ユニバース!E138 -> 6536090 | G37: =日次_ココ・ユニバース!F138 -> 0 | H37: =日次_ココ・ユニバース!G138 -> 6536090
A38: ココ・ユニバース | B38: 4ヶ月合計 | C38: =SUM(C34:C37) -> 12985400 | D38: =SUM(D34:D37) -> 6449310 | E38: =SUM(E34:E37) -> 6536090 | F38: =F37 -> 6536090 | G38: =SUM(G34:G37) -> 0 | H38: =H37 -> 6536090
A40: 全社合計 | C40: =SUM(C4:C7)+SUM(C10:C13)+SUM(C16:C19)+SUM(C22:C25)+SUM(C28:C31)+SUM(C34:C37) -> 1.4996845e+08 | D40: =SUM(D4:D7)+SUM(D10:D13)+SUM(D16:D19)+SUM(D22:D25)+SUM(D28:D31)+SUM(D34:D37) -> 163724387 | E40: =SUM(E4:E7)+SUM(E10:E13)+SUM(E16:E19)+SUM(E22:E25)+SUM(E28:E31)+SUM(E34:E37) -> -19025939 | G40: =SUM(G4:G7)+SUM(G10:G13)+SUM(G16:G19)+SUM(G22:G25)+SUM(G28:G31)+SUM(G34:G37) -> 5270000

Sheet 支払可能性分析
A1: 支払可能性分析（月次収支予測 + 未払繰越の優先度別支払可能性）
A2: 入金予測（売上予測+OTAサイクル+手動入力）と支出予測（月次予定+反復予測）から、各月の余剰を計算。残高内で支払可能な未払繰越を優先度順に判定。
A4: ■ Section 1：月次収支予測（全社合算）
A5: 月 | B5: 入金予測（円） | C5: 支出予測（円） | D5: 月次差引（円） | E5: 累計余剰（円） | F5: カード枠回復（円） | G5: 実質使用可能額（円） | H5: 判定
A6: 5月 | B6: =全社合算サマリー!B6 -> 45366181 | C6: =全社合算サマリー!C6 -> 48481617 | D6: =B6-C6 -> -3115436.4 | E6: =全社合算サマリー!E6 -> -8385436.4 | F6: =全社合算サマリー!F6 -> 5270000 | G6: =全社合算サマリー!G6 -> -3115436.4 | H6: =IF(G6>=10000000,"◎ 余裕",IF(G6>=0,"○ 適正",IF(G6>=-5000000,"△ 注意","✕ 資金不足"))) -> △ 注意
A7: 6月 | B7: =全社合算サマリー!B7 -> 34253666 | C7: =全社合算サマリー!C7 -> 39932206 | D7: =B7-C7 -> -5678540.3 | E7: =全社合算サマリー!E7 -> -14063977 | F7: =全社合算サマリー!F7 -> 0 | G7: =全社合算サマリー!G7 -> -8793976.7 | H7: =IF(G7>=10000000,"◎ 余裕",IF(G7>=0,"○ 適正",IF(G7>=-5000000,"△ 注意","✕ 資金不足"))) -> ✕ 資金不足
A8: 7月 | B8: =全社合算サマリー!B8 -> 30777994 | C8: =全社合算サマリー!C8 -> 37223663 | D8: =B8-C8 -> -6445668.6 | E8: =全社合算サマリー!E8 -> -20509645 | F8: =全社合算サマリー!F8 -> 0 | G8: =全社合算サマリー!G8 -> -15239645 | H8: =IF(G8>=10000000,"◎ 余裕",IF(G8>=0,"○ 適正",IF(G8>=-5000000,"△ 注意","✕ 資金不足"))) -> ✕ 資金不足
A9: 8月 | B9: =全社合算サマリー!B9 -> 39570607 | C9: =全社合算サマリー!C9 -> 38086901 | D9: =B9-C9 -> 1483706.2 | E9: =全社合算サマリー!E9 -> -19025939 | F9: =全社合算サマリー!F9 -> 0 | G9: =全社合算サマリー!G9 -> -13755939 | H9: =IF(G9>=10000000,"◎ 余裕",IF(G9>=0,"○ 適正",IF(G9>=-5000000,"△ 注意","✕ 資金不足"))) -> ✕ 資金不足
A11: ■ Section 2：未払繰越の優先度別リスト（全件）
A12: # | B12: 会社 | C12: 物件 | D12: 概要 | E12: 累積未払額 | F12: 優先度 | G12: 累計支払額 | H12: 判定（支払可否）
A13: 1 | B13: リゾート | C13: リゾート | D13: アイパス [予定日設定済] | E13: 801900 | F13: 高 | G13: =E13 -> 801900 | H13: =IF(G13<=$G9,"○ 支払可能","✕ 不足") -> ✕ 不足
A14: 2 | B14: リゾート | C14: リゾート | D14: クリンプロ（4か月分） [予定日設定済] | E14: 488840 | F14: 高 | G14: =G13+E14 -> 1290740 | H14: =IF(G14<=$G9,"○ 支払可能","✕ 不足") -> ✕ 不足
A15: 3 | B15: リゾート | C15: リゾート | D15: 百姓屋（4か月分） [予定日設定済] | E15: 187000 | F15: 高 | G15: =G14+E15 -> 1477740 | H15: =IF(G15<=$G9,"○ 支払可能","✕ 不足") -> ✕ 不足
A16: 4 | B16: リゾート | C16: リゾート | D16: 第一興商（5か月分） [予定日設定済] | E16: 187000 | F16: 高 | G16: =G15+E16 -> 1664740 | H16: =IF(G16<=$G9,"○ 支払可能","✕ 不足") -> ✕ 不足
A17: 5 | B17: レジデンス | C17: レジデンス | D17: あしたば [予定日設定済] | E17: 132000 | F17: 高 | G17: =G16+E17 -> 1796740 | H17: =IF(G17<=$G9,"○ 支払可能","✕ 不足") -> ✕ 不足
A18: 6 | B18: リゾート | C18: フォレスト | D18: みどりのまち（3ヶ月分） [予定日設定済] | E18: 124300 | F18: 高 | G18: =G17+E18 -> 1921040 | H18: =IF(G18<=$G9,"○ 支払可能","✕ 不足") -> ✕ 不足
A19: 7 | B19: リゾート | C19: リゾート | D19: 安芸クリーナー（5か月分） [予定日設定済] | E19: 110000 | F19: 高 | G19: =G18+E19 -> 2031040 | H19: =IF(G19<=$G9,"○ 支払可能","✕ 不足") -> ✕ 不足
A20: 8 | B20: リゾート | C20: リゾート | D20: 西部環境（4か月分） | E20: 92400 | F20: 高 | G20: =G19+E20 -> 2123440 | H20: =IF(G20<=$G9,"○ 支払可能","✕ 不足") -> ✕ 不足
A21: 9 | B21: リゾート | C21: リゾート | D21: 竹原クリーナー（5か月分） [予定日設定済] | E21: 88000 | F21: 高 | G21: =G20+E21 -> 2211440 | H21: =IF(G21<=$G9,"○ 支払可能","✕ 不足") -> ✕ 不足
A22: 10 | B22: リゾート | C22: リゾート | D22: アシード（5か月分） [予定日設定済] | E22: 70400 | F22: 高 | G22: =G21+E22 -> 2281840 | H22: =IF(G22<=$G9,"○ 支払可能","✕ 不足") -> ✕ 不足
A23: 11 | B23: リゾート | C23: リゾート | D23: 第一興商 [予定日設定済] | E23: 66000 | F23: 高 | G23: =G22+E23 -> 2347840 | H23: =IF(G23<=$G9,"○ 支払可能","✕ 不足") -> ✕ 不足
A24: 12 | B24: リゾート | C24: リゾート | D24: 青原木材（3ヶ月分） | E24: 486420 | F24: 中 | G24: =G23+E24 -> 2834260 | H24: =IF(G24<=$G9,"○ 支払可能","✕ 不足") -> ✕ 不足
A25: 13 | B25: リゾート | C25: リゾート | D25: あしたば [予定日設定済] | E25: 264000 | F25: 中 | G25: =G24+E25 -> 3098260 | H25: =IF(G25<=$G9,"○ 支払可能","✕ 不足") -> ✕ 不足
A26: 14 | B26: リゾート | C26: リゾート | D26: アペックス（3ヶ月分） [予定日設定済] | E26: 92495 | F26: 中 | G26: =G25+E26 -> 3190755 | H26: =IF(G26<=$G9,"○ 支払可能","✕ 不足") -> ✕ 不足
A27: 15 | B27: リゾート | C27: リゾート | D27: アペックス（3ヶ月分） [予定日設定済] | E27: 48540 | F27: 中 | G27: =G26+E27 -> 3239295 | H27: =IF(G27<=$G9,"○ 支払可能","✕ 不足") -> ✕ 不足
A28: 16 | B28: モーテル | C28: モーテル | D28: ふくや（3ヶ月分） [予定日設定済] | E28: 25651 | F28: 中 | G28: =G27+E28 -> 3264946 | H28: =IF(G28<=$G9,"○ 支払可能","✕ 不足") -> ✕ 不足
A29: 17 | B29: リゾート | C29: リゾート | D29: イマイチ（3ヶ月分） [予定日設定済] | E29: 24486 | F29: 中 | G29: =G28+E29 -> 3289432 | H29: =IF(G29<=$G9,"○ 支払可能","✕ 不足") -> ✕ 不足
A30: 18 | B30: リゾート | C30: リゾート | D30: キャノン [予定日設定済] | E30: 23702 | F30: 中 | G30: =G29+E30 -> 3313134 | H30: =IF(G30<=$G9,"○ 支払可能","✕ 不足") -> ✕ 不足
A31: 19 | B31: モーテル | C31: モーテル | D31: あしたば（4月分） [予定日設定済] | E31: 22000 | F31: 中 | G31: =G30+E31 -> 3335134 | H31: =IF(G31<=$G9,"○ 支払可能","✕ 不足") -> ✕ 不足
A32: 20 | B32: リゾート | C32: フォレスト | D32: フォワード [予定日設定済] | E32: 18648 | F32: 中 | G32: =G31+E32 -> 3353782 | H32: =IF(G32<=$G9,"○ 支払可能","✕ 不足") -> ✕ 不足
A33: 21 | B33: モーテル | C33: モーテル | D33: ASKUL（2か月分） [予定日設定済] | E33: 15932 | F33: 低 | G33: =G32+E33 -> 3369714 | H33: =IF(G33<=$G9,"○ 支払可能","✕ 不足") -> ✕ 不足
A35: 未払繰越合計 | E35: =SUM(E13:E33) -> 3369714 | G35: =G33 -> 3369714
A37: ■ Section 3：総括（8月末時点の使用可能額との比較）
A39: 8月末使用可能額 | B39: =G9 -> -13755939
A40: 優先度「高」未払合計 | B40: =SUMPRODUCT((未払予定一覧!$B$4:$B$803="未払繰越")*(未払予定一覧!$M$4:$M$803="高")*(未払予定一覧!$P$4:$P$803<>"済")*(未払予定一覧!$P$4:$P$803<>"取消")*未払予定一覧!$L$4:$L$803) -> 2499640
A41: 優先度「中」未払合計 | B41: =SUMPRODUCT((未払予定一覧!$B$4:$B$803="未払繰越")*(未払予定一覧!$M$4:$M$803="中")*(未払予定一覧!$P$4:$P$803<>"済")*(未払予定一覧!$P$4:$P$803<>"取消")*未払予定一覧!$L$4:$L$803) -> 1242347
A42: 優先度「低」未払合計 | B42: =SUMPRODUCT((未払予定一覧!$B$4:$B$803="未払繰越")*(未払予定一覧!$M$4:$M$803="低")*(未払予定一覧!$P$4:$P$803<>"済")*(未払予定一覧!$P$4:$P$803<>"取消")*未払予定一覧!$L$4:$L$803) -> 15932
A44: 「高」完済後の余剰 | C44: =G9-B40 -> -16255579 | D44: =IF(C44>=0,"◎ 「高」全件支払可能","✕ 「高」一部支払不可") -> ✕ 「高」一部支払不可
A45: 「高」+「中」完済後の余剰 | C45: =G9-B40-B41 -> -17497926 | D45: =IF(C45>=0,"○ 「中」まで全件可","✕ 「中」一部支払不可") -> ✕ 「中」一部支払不可
A46: 全優先度完済後の余剰 | C46: =G9-B40-B41-B42 -> -17513858 | D46: =IF(C46>=0,"◎ 全件支払可","✕ 一部支払不可") -> ✕ 一部支払不可

Sheet 2025-2026比較
A1: 2025年実績 vs 2026年予測 比較分析（施設×月）
A2: 充足率 = 2026予測 / 2025実績。緑=80%以上、黄=30-80%、赤=30%未満（要補正）
A4: 施設 | B4: 年区分 | C4: 1月 | D4: 2月 | E4: 3月 | F4: 4月 | G4: 5月 | H4: 6月 | I4: 7月 | J4: 8月 | K4: 9月 | L4: 10月 | M4: 11月 | N4: 12月 | O4: 年計
A5: de Lune | B5: 2025実績 | C5: 7261662 | D5: 5866776 | E5: 10663661 | F5: 8372542 | G5: 10091773 | H5: 6020957 | I5: 10861148 | J5: 13339294 | K5: 8976175 | L5: 12967689 | M5: 13075844 | N5: 6830956 | O5: 114328477
B6: 2026予測（5/13） | C6: 0 | D6: 0 | E6: 0 | F6: 8310821 | G6: 9120696 | H6: 2157347 | I6: 869144 | J6: 1477233 | K6: 468498 | L6: 601121 | M6: 142650 | N6: 145700 | O6: 23293210
B7: 充足率 | C7: 0 | D7: 0 | E7: 0 | F7: 0.99262816 | G7: 0.90377538 | H7: 0.35830633 | I7: 0.080023217 | J7: 0.11074297 | K7: 0.052193501 | L7: 0.046355291 | M7: 0.01090943 | N7: 0.021329372 | O7: 0.20373935
A9: VIEW | B9: 2025実績 | C9: 2143056 | D9: 1559909 | E9: 2743253 | F9: 2602903 | G9: 2606733 | H9: 1341712 | I9: 3302659 | J9: 4469894 | K9: 2740428 | L9: 3669167 | M9: 3942044 | N9: 1966245 | O9: 33088003
B10: 2026予測（5/13） | C10: 0 | D10: 0 | E10: 0 | F10: 2904045 | G10: 2785752 | H10: 613130 | I10: 320289 | J10: 312594 | K10: 492830 | L10: 112580 | M10: 0 | N10: 0 | O10: 7541220
B11: 充足率 | C11: 0 | D11: 0 | E11: 0 | F11: 1.1156947 | G11: 1.0686756 | H11: 0.45697586 | I11: 0.096979131 | J11: 0.069933202 | K11: 0.17983687 | L11: 0.030682714 | M11: 0 | N11: 0 | O11: 0.22791403
A13: 本川 | B13: 2025実績 | C13: 901976 | D13: 970534 | E13: 1394853 | F13: 1600536 | G13: 2028098 | H13: 1051016 | I13: 1110194 | J13: 2097316 | K13: 1566778 | L13: 2477290 | M13: 2350836 | N13: 1139100 | O13: 18688527
B14: 2026予測（5/13） | C14: 0 | D14: 0 | E14: 0 | F14: 1955058 | G14: 1560292 | H14: 249824 | I14: 396582 | J14: 411126 | K14: 109252 | L14: 159276 | M14: 0 | N14: 0 | O14: 4841410
B15: 充足率 | C15: 0 | D15: 0 | E15: 0 | F15: 1.221502 | G15: 0.76933758 | H15: 0.23769762 | I15: 0.35721865 | J15: 0.19602482 | K15: 0.069730364 | L15: 0.064294451 | M15: 0 | N15: 0 | O15: 0.25905787
A17: 天神 | B17: 2025実績 | C17: 32400 | D17: 174440 | E17: 247060 | F17: 115860 | G17: 270500 | H17: 85200 | I17: 214180 | J17: 318420 | K17: 53469 | L17: 261170 | M17: 349410 | N17: 179120 | O17: 2301229
B18: 2026予測（5/13） | C18: 0 | D18: 0 | E18: 0 | F18: 56700 | G18: 176080 | H18: 32400 | I18: 0 | J18: 0 | K18: 0 | L18: 0 | M18: 0 | N18: 0 | O18: 265180
B19: 充足率 | C19: 0 | D19: 0 | E19: 0 | F19: 0.48938374 | G19: 0.6509427 | H19: 0.38028169 | I19: 0 | J19: 0 | K19: 0 | L19: 0 | M19: 0 | N19: 0 | O19: 0.11523408
A21: 玖波 | B21: 2025実績 | C21: 327400 | D21: 369900 | E21: 730100 | F21: 460700 | G21: 431900 | H21: 183300 | I21: 218250 | J21: 793250 | K21: 246500 | L21: 418500 | M21: 476700 | N21: 275000 | O21: 4931500
B22: 2026予測（5/13） | C22: 0 | D22: 0 | E22: 0 | F22: 331500 | G22: 280500 | H22: 190750 | I22: 96000 | J22: 0 | K22: 0 | L22: 0 | M22: 0 | N22: 0 | O22: 898750
B23: 充足率 | C23: 0 | D23: 0 | E23: 0 | F23: 0.7195572 | G23: 0.64945589 | H23: 1.0406438 | I23: 0.43986254 | J23: 0 | K23: 0 | L23: 0 | M23: 0 | N23: 0 | O23: 0.18224678
A25: 弥山 | B25: 2025実績 | C25: 3701096 | D25: 2980174 | E25: 5584201 | F25: 5487259 | G25: 6761527 | H25: 3942572 | I25: 5866719 | J25: 9564791 | K25: 5465630 | L25: 8958395 | M25: 8362200 | N25: 5672113 | O25: 72346677
B26: 2026予測（5/13） | C26: 0 | D26: 0 | E26: 0 | F26: 4004248 | G26: 5707582 | H26: 1940810 | I26: 593347 | J26: 1509171 | K26: 362863 | L26: 533648 | M26: 237410 | N26: 20000 | O26: 14909079
B27: 充足率 | C27: 0 | D27: 0 | E27: 0 | F27: 0.72973556 | G27: 0.84412619 | H27: 0.49227002 | I27: 0.10113779 | J27: 0.157784 | K27: 0.066389968 | L27: 0.059569599 | M27: 0.028390854 | N27: 0.0035260228 | O27: 0.20607828
A29: 温井 | B29: 2025実績 | C29: 3022505 | D29: 4261675 | E29: 3738314 | F29: 2113091 | G29: 3281694 | H29: 2228827 | I29: 5237483 | J29: 6962206 | K29: 4111027 | L29: 5703514 | M29: 5651540 | N29: 4532837 | O29: 50844713
B30: 2026予測（5/13） | C30: 0 | D30: 0 | E30: 0 | F30: 2330934 | G30: 4564062 | H30: 1719708 | I30: 1045292 | J30: 1433757 | K30: 83838 | L30: 66600 | M30: 0 | N30: 0 | O30: 11244191
B31: 充足率 | C31: 0 | D31: 0 | E31: 0 | F31: 1.1030921 | G31: 1.390764 | H31: 0.77157536 | I31: 0.19957907 | J31: 0.2059343 | K31: 0.020393444 | L31: 0.011677012 | M31: 0 | N31: 0 | O31: 0.22114769
A33: いこいの村 | B33: 2025実績 | C33: 0 | D33: 0 | E33: 0 | F33: 5067080 | G33: 5172360 | H33: 5590656 | I33: 8590205 | J33: 14720394 | K33: 5111672 | L33: 5445149 | M33: 5263750 | N33: 4624660 | O33: 59585926
B34: 2026予測（5/13） | C34: 0 | D34: 0 | E34: 0 | F34: 6092392 | G34: 2928671 | H34: 1212724 | I34: 1777188 | J34: 963416 | K34: 1722323 | L34: 405410 | M34: 0 | N34: 0 | O34: 15102124
B35: 充足率 | F35: 1.2023477 | G35: 0.56621562 | H35: 0.2169198 | I35: 0.2068854 | J35: 0.065447705 | K35: 0.33693926 | L35: 0.074453426 | M35: 0 | N35: 0 | O35: 0.25345119
A37: TAKAYA | B37: 2025実績 | C37: 142000 | D37: 506000 | E37: 517000 | F37: 636000 | G37: 441000 | H37: 421980 | I37: 310000 | J37: 246000 | K37: 96000 | L37: 228000 | M37: 450000 | N37: 323000 | O37: 4316980
B38: 2026予測（5/13） | C38: 0 | D38: 0 | E38: 0 | F38: 455000 | G38: 272000 | H38: 195000 | I38: 78000 | J38: 120000 | K38: 0 | L38: 0 | M38: 0 | N38: 0 | O38: 1120000
B39: 充足率 | C39: 0 | D39: 0 | E39: 0 | F39: 0.71540881 | G39: 0.61678005 | H39: 0.46210721 | I39: 0.2516129 | J39: 0.48780488 | K39: 0 | L39: 0 | M39: 0 | N39: 0 | O39: 0.25944063
A41: 壱番館 | B41: 2025実績 | C41: 276000 | D41: 162000 | E41: 189000 | F41: 103500 | G41: 164000 | H41: 165000 | I41: 127500 | J41: 217000 | K41: 142500 | L41: 0 | M41: 183000 | N41: 78000 | O41: 1807500
B42: 2026予測（5/13） | C42: 0 | D42: 0 | E42: 0 | F42: 101400 | G42: 24000 | H42: 45000 | I42: 0 | J42: 0 | K42: 0 | L42: 0 | M42: 0 | N42: 0 | O42: 170400
B43: 充足率 | C43: 0 | D43: 0 | E43: 0 | F43: 0.97971014 | G43: 0.14634146 | H43: 0.27272727 | I43: 0 | J43: 0 | K43: 0 | M43: 0 | N43: 0 | O43: 0.094273859
A45: 弐番館 | B45: 2025実績 | C45: 60000 | D45: 121500 | E45: 69000 | F45: 58000 | G45: 9000 | H45: 108000 | I45: 63000 | J45: 56500 | K45: 44000 | L45: 57000 | M45: 48000 | N45: 54500 | O45: 748500
B46: 2026予測（5/13） | C46: 0 | D46: 0 | E46: 0 | F46: 90000 | G46: 0 | H46: 0 | I46: 0 | J46: 75000 | K46: 0 | L46: 0 | M46: 0 | N46: 0 | O46: 165000
B47: 充足率 | C47: 0 | D47: 0 | E47: 0 | F47: 1.5517241 | G47: 0 | H47: 0 | I47: 0 | J47: 1.3274336 | K47: 0 | L47: 0 | M47: 0 | N47: 0 | O47: 0.22044088
A49: Otake | B49: 2025実績 | C49: 0 | D49: 0 | E49: 0 | F49: 0 | G49: 15000 | H49: 0 | I49: 0 | J49: 77500 | K49: 132500 | L49: 75000 | M49: 35000 | N49: 77500 | O49: 412500
B50: 2026予測（5/13） | C50: 0 | D50: 0 | E50: 0 | F50: 105000 | G50: 77500 | H50: 72500 | I50: 0 | J50: 0 | K50: 0 | L50: 0 | M50: 0 | N50: 0 | O50: 255000
B51: 充足率 | G51: 5.1666667 | J51: 0 | K51: 0 | L51: 0 | M51: 0 | N51: 0 | O51: 0.61818182
A53: 竹原（ﾚｽﾄﾗﾝ含む） | B53: 2025実績 | C53: 1568869 | D53: 1184756 | E53: 1834990 | F53: 3032420 | G53: 1954383 | H53: 1736192 | I53: 1423207 | J53: 1213337 | K53: 1539082 | L53: 1127424 | M53: 593424 | N53: 593424 | O53: 17801508
...

Sheet マスター_物件
A1: 物件→会社 マッピング表
A3: 物件名 | B3: 所属会社 | C3: 備考
A4: リゾート | B4: リゾート
A5: ほうらい | B5: リゾート
A6: フォレスト | B6: リゾート
A7: ｸﾞﾘｰﾝｼｬﾜｰ | B7: リゾート
A8: 周防大島 | B8: リゾート
A9: モーテル | B9: モーテル
A10: レジデンス | B10: レジデンス
A11: ココユニバース | B11: ザック

Sheet マスター_勘定科目
A1: 勘定科目→資金繰り項目 マッピング表
A3: 勘定科目 | B3: 資金繰り項目 | C3: 備考
A4: 水道光熱費 | B4: 買掛金支払
A5: 設備費 | B5: 買掛金支払
A6: 通信費 | B6: 買掛金支払
A7: 衛生管理費 | B7: 買掛金支払
A8: 食材費 | B8: 買掛金支払
A9: システム利用料 | B9: 買掛金支払
A10: 業務委託料 | B10: 買掛金支払
A11: 備品消耗品費 | B11: 買掛金支払
A12: ゴミ収集費 | B12: 買掛金支払
A13: 租税公課 | B13: 税金・社会保険料
A14: 保険 | B14: その他経費
A15: 手数料 | B15: その他経費
... A22: 社員給与 | B22: 従業員給与

Sheet マスター_OTA
A1: OTA／決済サイクル マスター（売上計上月に対する入金タイミング）
A2: ※ 当月・翌月・翌々月への分配比率（合計が100%になるように設定）／入金日も指定
A3: OTA／決済名 | B3: 当月比率(%) | C3: 翌月比率(%) | D3: 翌々月比率(%) | E3: 入金日（当月） | F3: 入金日（翌月） | G3: 入金日（翌々月）
A4: Booking | B4: 0 | C4: 100 | D4: 0 | F4: 5
A5: 楽天 | B5: 0 | C5: 100 | D5: 0 | F5: 10
A6: 楽天-25日 | B6: 0 | C6: 100 | D6: 0 | F6: 25
A7: じゃらん | B7: 0 | C7: 100 | D7: 0 | F7: 25
A8: 一休 | B8: 0 | C8: 100 | D8: 0 | F8: 28
A9: Expedia | B9: 0 | C9: 100 | D9: 0 | F9: 25
A10: Agoda | B10: 0 | C10: 100 | D10: 0 | F10: 25
A11: スマレジ | B11: 0 | C11: 100 | D11: 0 | F11: 23
A12: JCB | B12: 0 | C12: 100 | D12: 0 | F12: 23
A13: GMO | B13: 0 | C13: 100 | D13: 0 | F13: 23
A14: JMS | B14: 0 | C14: 100 | D14: 0 | F14: 23
A15: PayPay | B15: 0 | C15: 100 | D15: 0 | F15: 5
A16: カード | B16: 0 | C16: 100 | D16: 0 | F16: 25
A17: 現金売上 | B17: 100 | C17: 0 | D17: 0 | E17: 20
A18: ホテル売上 | B18: 15 | C18: 75 | D18: 10 | E18: 20 | F18: 10 | G18: 25
A19: 竹原市 | B19: 0 | C19: 100 | D19: 0 | F19: 15
A20: 売上 | B20: 15 | C20: 75 | D20: 10 | E20: 20 | F20: 10 | G20: 25
A21: リクルートペイメント | B21: 0 | C21: 100 | D21: 0 | F21: 15
A22: リクルートポイント | B22: 0 | C22: 100 | D22: 0 | F22: 25
A23: イッキュウ | B23: 0 | C23: 100 | D23: 0 | F23: 28
A24: コカ・コーラ | B24: 0 | C24: 100 | D24: 0 | F24: 20
A25: JTB | B25: 0 | C25: 100 | D25: 0 | F25: 25
A26: メルペイ | B26: 0 | C26: 100 | D26: 0 | F26: 10
A27: 振込代行リクルート | B27: 0 | C27: 100 | D27: 0 | F27: 25
A28: 白菱 | B28: 0 | C28: 100 | D28: 0 | F28: 2
A29: ラインプロフェクト | B29: 100 | C29: 0 | D29: 0 | E29: 5

Sheet 入金入力
A1: 入金入力（全社統合・会社列で識別）
A2: ※ 区分は資金繰り表項目／フィルターで会社別／OTA売上連動は「売上入力」へ
A3: 会社 | B3: 日付 | C3: 項目 | D3: 区分 | E3: 金額（円） | F3: 備考 | G3: 入金確認
A4: ココ・ユニバース | B4: 46120 | C4: ユ)パルコ | D4: 現金売上 | E4: 1900000 | F4: 広島銀行0208510 | G4: 確認済
A5: ココ・ユニバース | B5: 46125 | C5: カ)ワールドレイ | D5: 現金売上 | E5: 150000 | F5: 広島銀行0208510 | G5: 確認済
A6: ココ・ユニバース | B6: 46125 | C6: カ)ココユニバース | D6: 現金売上 | E6: 700000 | F6: 広島銀行0208510-社内振替 | G6: 確認済
A7: ココ・ユニバース | B7: 46127 | C7: カ)ケアイコミュニティ | D7: 現金売上 | E7: 730900 | F7: 広島銀行0208510 | G7: 確認済
A8: ココ・ユニバース | B8: 46133 | C8: 振込入金 | D8: 現金売上 | E8: 401500 | F8: 広島銀行0208510 | G8: 確認済
A9: ココ・ユニバース | B9: 46133 | C9: ユ)パルコ | D9: 現金売上 | E9: 921800 | F9: 広島銀行0208510 | G9: 確認済
A10: ココ・ユニバース | B10: 46137 | C10: カ)ココユニバース | D10: 現金売上 | E10: 560000 | F10: 広島銀行0208510-社内振替 | G10: 確認済
A11: ココ・ユニバース | B11: 46144 | C11: カ)ココユニバース | D11: 現金売上 | E11: 300000 | F11: 広島銀行0208510-社内振替 | G11: 確認済
A12: ココ・ユニバース | B12: 46153 | C12: ユ)パルコ | D12: 現金売上 | E12: 1900000 | F12: 広島銀行0208510 | G12: 確認済
A13: ココ・ユニバース | B13: 46181 | C13: ユ)パルコ（月次予測） | D13: 現金売上 | E13: 1900000 | F13: パルコ系月次予測 | G13: 予測
A14: ココ・ユニバース | B14: 46194 | C14: ユ)パルコ（月次予測） | D14: 現金売上 | E14: 921800 | F14: パルコ系月次予測 | G14: 予測
A15: ココ・ユニバース | B15: 46188 | C15: カ)ケアイコミュニティ（月次予測） | D15: 現金売上 | E15: 700000 | F15: ケアイコミュニティ月次予測 | G15: 予測
... A380: モーテル | B380: 46173 | C380: 現金売上 | D380: 現金売上 | E380: 377864 | F380: 4月実績ベース予測（4/30相当） | G380: 予測
A505: 合計 | E505: =SUM(E4:E503) -> 209454107

Sheet 売上入力
A1: 売上入力（OTA別／施設別／月別の売上）
A2: ※ 売上計上月にOTA・施設・売上額を入力 → マスター_OTAの分配比率で入金予測へ自動展開
A3: 計上月 | B3: 会社 | C3: 施設 | D3: OTA／決済 | E3: 売上額（円） | F3: 備考
A4: 46113 | B4: ザック | C4: MAKI de SAUNA | D4: 売上 | E4: 0 | F4: [サウナ] 5/13予約ベース [元売上額: 121,831円 - 入金確認表で実績計上済みのためゼロ化]
A5: 46113 | B5: リゾート | C5: Otake | D5: 売上 | E5: 0 | F5: [マンスリー] 5/13予約ベース [元売上額: 105,000円 - 入金確認表で実績計上済みのためゼロ化]
A6: 46113 | B6: リゾート | C6: TAKAYA | D6: 売上 | E6: 0 | F6: [マンスリー] 5/13予約ベース [元売上額: 455,000円 - 入金確認表で実績計上済みのためゼロ化]
A7: 46113 | B7: リゾート | C7: VIEW | D7: ホテル売上 | E7: 0 | F7: [ホテル] 5/13予約ベース [元売上額: 2,904,045円 - 入金確認表で実績計上済みのためゼロ化]
A8: 46113 | B8: リゾート | C8: de Lune | D8: ホテル売上 | E8: 0 | F8: [ホテル] 5/13予約ベース [元売上額: 8,310,821円 - 入金確認表で実績計上済みのためゼロ化]
A9: 46113 | B9: リゾート | C9: いこいの村 | D9: ホテル売上 | E9: 0 | F9: [ホテル] 5/13予約ベース [元売上額: 6,092,392円 - 入金確認表で実績計上済みのためゼロ化]
A10: 46113 | B10: リゾート | C10: グリーンシャワー | D10: 売上 | E10: 0 | F10: [指定管理] 5/13予約ベース [元売上額: 626,997円 - 入金確認表で実績計上済みのためゼロ化]
A11: 46113 | B11: リゾート | C11: フォレストヒルズガーデン | D11: 売上 | E11: 0 | F11: [指定管理] 5/13予約ベース [元売上額: 5,535,949円 - 入金確認表で実績計上済みのためゼロ化]
A12: 46113 | B12: リゾート | C12: 壱番館 | D12: 売上 | E12: 0 | F12: [マンスリー] 5/13予約ベース [元売上額: 101,400円 - 入金確認表で実績計上済みのためゼロ化]
A13: 46113 | B13: リゾート | C13: 天神 | D13: ホテル売上 | E13: 0 | F13: [ホテル] 5/13予約ベース [元売上額: 56,700円 - 入金確認表で実績計上済みのためゼロ化]
A14: 46113 | B14: リゾート | C14: 弐番館 | D14: 売上 | E14: 0 | F14: [マンスリー] 5/13予約ベース [元売上額: 90,000円 - 入金確認表で実績計上済みのためゼロ化]
A15: 46113 | B15: モーテル | C15: 弥山 | D15: ホテル売上 | E15: 0 | F15: [ホテル] 5/13予約ベース [元売上額: 4,004,248円 - 入金確認表で実績計上済みのためゼロ化]
... A98: 46357 | B98: リゾート | C98: 竹原（ﾚｽﾄﾗﾝ含む） | D98: 竹原市 | E98: 683000 | F98: [指定管理] 5/13予約ベース
A205: 合計 | E205: =SUM(E4:E203) -> 247638350

Sheet 入金予測
A1: 入金予測（売上入力 × マスター_OTA の比率で自動計算）
A2: ※ 売上入力1行につき最大3行（当月/翌月/翌々月）の予測を自動展開／月次サマリーの入金へ自動加算
A3: 予測入金日 | B3: 会社 | C3: 施設 | D3: OTA／決済 | E3: 予測入金額（円） | F3: 売上計上月 | G3: 備考
A4: =IFERROR(IF(売上入力!A4="","",IF(INDEX(マスター_OTA!$B$4:$B$29,MATCH(売上入力!D4,マスター_OTA!$A$4:$A$29,0))=0,"",DATE(YEAR(売上入力!A4),MONTH(売上入力!A4),IFERROR(INDEX(マスター_OTA!$E$4:$E$29,MATCH(売上入力!D4,マスター_OTA!$A$4:$A$29,0)),28)))),"") -> 46132 | B4: =IF(売上入力!B4="","",売上入力!B4) -> ザック | C4: =IF(売上入力!C4="","",売上入力!C4) -> MAKI de SAUNA | D4: =IF(売上入力!D4="","",売上入力!D4) -> 売上 | E4: =IFERROR(IF(売上入力!E4="",0,売上入力!E4*INDEX(マスター_OTA!$B$4:$B$29,MATCH(売上入力!D4,マスター_OTA!$A$4:$A$29,0))/100),0) -> 0 | F4: =IF(売上入力!A4="","",売上入力!A4) -> 46113 | G4: 当月分
A5: =IFERROR(IF(売上入力!A4="","",IF(INDEX(マスター_OTA!$C$4:$C$29,MATCH(売上入力!D4,マスター_OTA!$A$4:$A$29,0))=0,"",DATE(YEAR(売上入力!A4),MONTH(売上入力!A4)+1,IFERROR(INDEX(マスター_OTA!$F$4:$F$29,MATCH(売上入力!D4,マスター_OTA!$A$4:$A$29,0)),25)))),"") -> 46152 | B5: =IF(売上入力!B4="","",売上入力!B4) -> ザック | C5: =IF(売上入力!C4="","",売上入力!C4) -> MAKI de SAUNA | D5: =IF(売上入力!D4="","",売上入力!D4) -> 売上 | E5: =IFERROR(IF(売上入力!E4="",0,売上入力!E4*INDEX(マスター_OTA!$C$4:$C$29,MATCH(売上入力!D4,マスター_OTA!$A$4:$A$29,0))/100),0) -> 0 | F5: =IF(売上入力!A4="","",売上入力!A4) -> 46113 | G5: 翌月分
A6: =IFERROR(IF(売上入力!A4="","",IF(INDEX(マスター_OTA!$D$4:$D$29,MATCH(売上入力!D4,マスター_OTA!$A$4:$A$29,0))=0,"",DATE(YEAR(売上入力!A4),MONTH(売上入力!A4)+2,IFERROR(INDEX(マスター_OTA!$G$4:$G$29,MATCH(売上入力!D4,マスター_OTA!$A$4:$A$29,0)),25)))),"") -> 46198 | B6: =IF(売上入力!B4="","",売上入力!B4) -> ザック | C6: =IF(売上入力!C4="","",売上入力!C4) -> MAKI de SAUNA | D6: =IF(売上入力!D4="","",売上入力!D4) -> 売上 | E6: =IFERROR(IF(売上入力!E4="",0,売上入力!E4*INDEX(マスター_OTA!$D$4:$D$29,MATCH(売上入力!D4,マスター_OTA!$A$4:$A$29,0))/100),0) -> 0 | F6: =IF(売上入力!A4="","",売上入力!A4) -> 46113 | G6: 翌々月分
A7: =IFERROR(IF(売上入力!A5="","",IF(INDEX(マスター_OTA!$B$4:$B$29,MATCH(売上入力!D5,マスター_OTA!$A$4:$A$29,0))=0,"",DATE(YEAR(売上入力!A5),MONTH(売上入力!A5),IFERROR(INDEX(マスター_OTA!$E$4:$E$29,MATCH(売上入力!D5,マスター_OTA!$A$4:$A$29,0)),28)))),"") -> 46132 | B7: =IF(売上入力!B5="","",売上入力!B5) -> リゾート | C7: =IF(売上入力!C5="","",売上入力!C5) -> Otake | D7: =IF(売上入力!D5="","",売上入力!D5) -> 売上 | E7: =IFERROR(IF(売上入力!E5="",0,売上入力!E5*INDEX(マスター_OTA!$B$4:$B$29,MATCH(売上入力!D5,マスター_OTA!$A$4:$A$29,0))/100),0) -> 0 | F7: =IF(売上入力!A5="","",売上入力!A5) -> 46113 | G7: 当月分
A8: =IFERROR(IF(売上入力!A5="","",IF(INDEX(マスター_OTA!$C$4:$C$29,MATCH(売上入力!D5,マスター_OTA!$A$4:$A$29,0))=0,"",DATE(YEAR(売上入力!A5),MONTH(売上入力!A5)+1,IFERROR(INDEX(マスター_OTA!$F$4:$F$29,MATCH(売上入力!D5,マスター_OTA!$A$4:$A$29,0)),25)))),"") -> 46152 | B8: =IF(売上入力!B5="","",売上入力!B5) -> リゾート | C8: =IF(売上入力!C5="","",売上入力!C5) -> Otake | D8: =IF(売上入力!D5="","",売上入力!D5) -> 売上 | E8: =IFERROR(IF(売上入力!E5="",0,売上入力!E5*INDEX(マスター_OTA!$C$4:$C$29,MATCH(売上入力!D5,マスター_OTA!$A$4:$A$29,0))/100),0) -> 0 | F8: =IF(売上入力!A5="","",売上入力!A5) -> 46113 | G8: 翌月分
A9: =IFERROR(IF(売上入力!A5="","",IF(INDEX(マスター_OTA!$D$4:$D$29,MATCH(売上入力!D5,マスター_OTA!$A$4:$A$29,0))=0,"",DATE(YEAR(売上入力!A5),MONTH(売上入力!A5)+2,IFERROR(INDEX(マスター_OTA!$G$4:$G$29,MATCH(売上入力!D5,マスター_OTA!$A$4:$A$29,0)),25)))),"") -> 46198 | B9: =IF(売上入力!B5="","",売上入力!B5) -> リゾート | C9: =IF(売上入力!C5="","",売上入力!C5) -> Otake | D9: =IF(売上入力!D5="","",売上入力!D5) -> 売上 | E9: =IFERROR(IF(売上入力!E5="",0,売上入力!E5*INDEX(マスター_OTA!$D$4:$D$29,MATCH(売上入力!D5,マスター_OTA!$A$4:$A$29,0))/100),0) -> 0 | F9: =IF(売上入力!A5="","",売上入力!A5) -> 46113 | G9: 翌々月分
A10: =IFERROR(IF(売上入力!A6="","",IF(INDEX(マスター_OTA!$B$4:$B$29,MATCH(売上入力!D6,マスター_OTA!$A$4:$A$29,0))=0,"",DATE(YEAR(売上入力!A6),MONTH(売上入力!A6),IFERROR(INDEX(マスター_OTA!$E$4:$E$29,MATCH(売上入力!D6,マスター_OTA!$A$4:$A$29,0)),28)))),"") -> 46132 | B10: =IF(売上入力!B6="","",売上入力!B6) -> リゾート | C10: =IF(売上入力!C6="","",売上入力!C6) -> TAKAYA | D10: =IF(売上入力!D6="","",売上入力!D6) -> 売上 | E10: =IFERROR(IF(売上入力!E6="",0,売上入力!E6*INDEX(マスター_OTA!$B$4:$B$29,MATCH(売上入力!D6,マスター_OTA!$A$4:$A$29,0))/100),0) -> 0 | F10: =IF(売上入力!A6="","",売上入力!A6) -> 46113 | G10: 当月分
A11: =IFERROR(IF(売上入力!A6="","",IF(INDEX(マスター_OTA!$C$4:$C$29,MATCH(売上入力!D6,マスター_OTA!$A$4:$A$29,0))=0,"",DATE(YEAR(売上入力!A6),MONTH(売上入力!A6)+1,IFERROR(INDEX(マスター_OTA!$F$4:$F$29,MATCH(売上入力!D6,マスター_OTA!$A$4:$A$29,0)),25)))),"") -> 46152 | B11: =IF(売上入力!B6="","",売上入力!B6) -> リゾート | C11: =IF(売上入力!C6="","",売上入力!C6) -> TAKAYA | D11: =IF(売上入力!D6="","",売上入力!D6) -> 売上 | E11: =IFERROR(IF(売上入力!E6="",0,売上入力!E6*INDEX(マスター_OTA!$C$4:$C$29,MATCH(売上入力!D6,マスター_OTA!$A$4:$A$29,0))/100),0) -> 0 | F11: =IF(売上入力!A6="","",売上入力!A6) -> 46113 | G11: 翌月分
A12: =IFERROR(IF(売上入力!A6="","",IF(INDEX(マスター_OTA!$D$4:$D$29,MATCH(売上入力!D6,マスター_OTA!$A$4:$A$29,0))=0,"",DATE(YEAR(売上入力!A6),MONTH(売上入力!A6)+2,IFERROR(INDEX(マスター_OTA!$G$4:$G$29,MATCH(売上入力!D6,マスター_OTA!$A$4:$A$29,0)),25)))),"") -> 46198 | B12: =IF(売上入力!B6="","",売上入力!B6) -> リゾート | C12: =IF(売上入力!C6="","",売上入力!C6) -> TAKAYA | D12: =IF(売上入力!D6="","",売上入力!D6) -> 売上 | E12: =IFERROR(IF(売上入力!E6="",0,売上入力!E6*INDEX(マスター_OTA!$D$4:$D$29,MATCH(売上入力!D6,マスター_OTA!$A$4:$A$29,0))/100),0) -> 0 | F12: =IF(売上入力!A6="","",売上入力!A6) -> 46113 | G12: 翌々月分
A13: =IFERROR(IF(売上入力!A7="","",IF(INDEX(マスター_OTA!$B$4:$B$29,MATCH(売上入力!D7,マスター_OTA!$A$4:$A$29,0))=0,"",DATE(YEAR(売上入力!A7),MONTH(売上入力!A7),IFERROR(INDEX(マスター_OTA!$E$4:$E$29,MATCH(売上入力!D7,マスター_OTA!$A$4:$A$29,0)),28)))),"") -> 46132 | B13: =IF(売上入力!B7="","",売上入力!B7) -> リゾート | C13: =IF(売上入力!C7="","",売上入力!C7) -> VIEW | D13: =IF(売上入力!D7="","",売上入力!D7) -> ホテル売上 | E13: =IFERROR(IF(売上入力!E7="",0,売上入力!E7*INDEX(マスター_OTA!$B$4:$B$29,MATCH(売上入力!D7,マスター_OTA!$A$4:$A$29,0))/100),0) -> 0 | F13: =IF(売上入力!A7="","",売上入力!A7) -> 46113 | G13: 当月分
A14: =IFERROR(IF(売上入力!A7="","",IF(INDEX(マスター_OTA!$C$4:$C$29,MATCH(売上入力!D7,マスター_OTA!$A$4:$A$29,0))=0,"",DATE(YEAR(売上入力!A7),MONTH(売上入力!A7)+1,IFERROR(INDEX(マスター_OTA!$F$4:$F$29,MATCH(売上入力!D7,マスター_OTA!$A$4:$A$29,0)),25)))),"") -> 46152 | B14: =IF(売上入力!B7="","",売上入力!B7) -> リゾート | C14: =IF(売上入力!C7="","",売上入力!C7) -> VIEW | D14: =IF(売上入力!D7="","",売上入力!D7) -> ホテル売上 | E14: =IFERROR(IF(売上入力!E7="",0,売上入力!E7*INDEX(マスター_OTA!$C$4:$C$29,MATCH(売上入力!D7,マスター_OTA!$A$4:$A$29,0))/100),0) -> 0 | F14: =IF(売上入力!A7="","",売上入力!A7) -> 46113 | G14: 翌月分
A15: =IFERROR(IF(売上入力!A7="","",IF(INDEX(マスター_OTA!$D$4:$D$29,MATCH(売上入力!D7,マスター_OTA!$A$4:$A$29,0))=0,"",DATE(YEAR(売上入力!A7),MONTH(売上入力!A7)+2,IFERROR(INDEX(マスター_OTA!$G$4:$G$29,MATCH(売上入力!D7,マスター_OTA!$A$4:$A$29,0)),25)))),"") -> 46198 | B15: =IF(売上入力!B7="","",売上入力!B7) -> リゾート | C15: =IF(売上入力!C7="","",売上入力!C7) -> VIEW | D15: =IF(売上入力!D7="","",売上入力!D7) -> ホテル売上 | E15: =IFERROR(IF(売上入力!E7="",0,売上入力!E7*INDEX(マスター_OTA!$D$4:$D$29,MATCH(売上入力!D7,マスター_OTA!$A$4:$A$29,0))/100),0) -> 0 | F15: =IF(売上入力!A7="","",売上入力!A7) -> 46113 | G15: 翌々月分
A16: =IFERROR(IF(売上入力!A8="","",IF(INDEX(マスター_OTA!$B$4:$B$29,MATCH(売上入力!D8,マスター_OTA!$A$4:$A$29,0))=0,"",DATE(YEAR(売上入力!A8),MONTH(売上入力!A8),IFERROR(INDEX(マスター_OTA!$E$4:$E$29,MATCH(売上入力!D8,マスター_OTA!$A$4:$A$29,0)),28)))),"") -> 46132 | B16: =IF(売上入力!B8="","",売上入力!B8) -> リゾート | C16: =IF(売上入力!C8="","",売上入力!C8) -> de Lune | D16: =IF(売上入力!D8="","",売上入力!D8) -> ホテル売上 | E16: =IFERROR(IF(売上入力!E8="",0,売上入力!E8*INDEX(マスター_OTA!$B$4:$B$29,MATCH(売上入力!D8,マスター_OTA!$A$4:$A$29,0))/100),0) -> 0 | F16: =IF(売上入力!A8="","",売上入力!A8) -> 46113 | G16: 当月分
A17: =IFERROR(IF(売上入力!A8="","",IF(INDEX(マスター_OTA!$C$4:$C$29,MATCH(売上入力!D8,マスター_OTA!$A$4:$A$29,0))=0,"",DATE(YEAR(売上入力!A8),MONTH(売上入力!A8)+1,IFERROR(INDEX(マスター_OTA!$F$4:$F$29,MATCH(売上入力!D8,マスター_OTA!$A$4:$A$29,0)),25)))),"") -> 46152 | B17: =IF(売上入力!B8="","",売上入力!B8) -> リゾート | C17: =IF(売上入力!C8="","",売上入力!C8) -> de Lune | D17: =IF(売上入力!D8="","",売上入力!D8) -> ホテル売上 | E17: =IFERROR(IF(売上入力!E8="",0,売上入力!E8*INDEX(マスター_OTA!$C$4:$C$29,MATCH(売上入力!D8,マスター_OTA!$A$4:$A$29,0))/100),0) -> 0 | F17: =IF(売上入力!A8="","",売上入力!A8) -> 46113 | G17: 翌月分
A18: =IFERROR(IF(売上入力!A8="","",IF(INDEX(マスター_OTA!$D$4:$D$29,MATCH(売上入力!D8,マスター_OTA!$A$4:$A$29,0))=0,"",DATE(YEAR(売上入力!A8),MONTH(売上入力!A8)+2,IFERROR(INDEX(マスター_OTA!$G$4:$G$29,MATCH(売上入力!D8,マスター_OTA!$A$4:$A$29,0)),25)))),"") -> 46198 | B18: =IF(売上入力!B8="","",売上入力!B8) -> リゾート | C18: =IF(売上入力!C8="","",売上入力!C8) -> de Lune | D18: =IF(売上入力!D8="","",売上入力!D8) -> ホテル売上 | E18: =IFERROR(IF(売上入力!E8="",0,売上入力!E8*INDEX(マスター_OTA!$D$4:$D$29,MATCH(売上入力!D8,マスター_OTA!$A$4:$A$29,0))/100),0) -> 0 | F18: =IF(売上入力!A8="","",売上入力!A8) -> 46113 | G18: 翌々月分
A19: =IFERROR(IF(売上入力!A9="","",IF(INDEX(マスター_OTA!$B$4:$B$29,MATCH(売上入力!D9,マスター_OTA!$A$4:$A$29,0))=0,"",DATE(YEAR(売上入力!A9),MONTH(売上入力!A9),IFERROR(INDEX(マスター_OTA!$E$4:$E$29,MATCH(売上入力!D9,マスター_OTA!$A$4:$A$29,0)),28)))),"") -> 46132 | B19: =IF(売上入力!B9="","",売上入力!B9) -> リゾート | C19: =IF(売上入力!C9="","",売上入力!C9) -> いこいの村 | D19: =IF(売上入力!D9="","",売上入力!D9) -> ホテル売上 | E19: =IFERROR(IF(売上入力!E9="",0,売上入力!E9*INDEX(マスター_OTA!$B$4:$B$29,MATCH(売上入力!D9,マスター_OTA!$A$4:$A$29,0))/100),0) -> 0 | F19: =IF(売上入力!A9="","",売上入力!A9) -> 46113 | G19: 当月分
A20: =IFERROR(IF(売上入力!A9="","",IF(INDEX(マスター_OTA!$C$4:$C$29,MATCH(売上入力!D9,マスター_OTA!$A$4:$A$29,0))=0,"",DATE(YEAR(売上入力!A9),MONTH(売上入力!A9)+1,IFERROR(INDEX(マスター_OTA!$F$4:$F$29,MATCH(売上入力!D9,マスター_OTA!$A$4:$A$29,0)),25)))),"") -> 46152 | B20: =IF(売上入力!B9="","",売上入力!B9) -> リゾート | C20: =IF(売上入力!C9="","",売上入力!C9) -> いこいの村 | D20: =IF(売上入力!D9="","",売上入力!D9) -> ホテル売上 | E20: =IFERROR(IF(売上入力!E9="",0,売上入力!E9*INDEX(マスター_OTA!$C$4:$C$29,MATCH(売上入力!D9,マスター_OTA!$A$4:$A$29,0))/100),0) -> 0 | F20: =IF(売上入力!A9="","",売上入力!A9) -> 46113 | G20: 翌月分
A21: =IFERROR(IF(売上入力!A9="","",IF(INDEX(マスター_OTA!$D$4:$D$29,MATCH(売上入力!D9,マスター_OTA!$A$4:$A$29,0))=0,"",DATE(YEAR(売上入力!A9),MONTH(売上入力!A9)+2,IFERROR(INDEX(マスター_OTA!$G$4:$G$29,MATCH(売上入力!D9,マスター_OTA!$A$4:$A$29,0)),25)))),"") -> 46198 | B21: =IF(売上入力!B9="","",売上入力!B9) -> リゾート | C21: =IF(売上入力!C9="","",売上入力!C9) -> いこいの村 | D21: =IF(売上入力!D9="","",売上入力!D9) -> ホテル売上 | E21: =IFERROR(IF(売上入力!E9="",0,売上入力!E9*INDEX(マスター_OTA!$D$4:$D$29,MATCH(売上入力!D9,マスター_OTA!$A$4:$A$29,0))/100),0) -> 0 | F21: =IF(売上入力!A9="","",売上入力!A9) -> 46113 | G21: 翌々月分
A22: =IFERROR(IF(売上入力!A10="","",IF(INDEX(マスター_OTA!$B$4:$B$29,MATCH(売上入力!D10,マスター_OTA!$A$4:$A$29,0))=0,"",DATE(YEAR(売上入力!A10),MONTH(売上入力!A10),IFERROR(INDEX(マスター_OTA!$E$4:$E$29,MATCH(売上入力!D10,マスター_OTA!$A$4:$A$29,0)),28)))),"") -> 46132 | B22: =IF(売上入力!B10="","",売上入力!B10) -> リゾート | C22: =IF(売上入力!C10="","",売上入力!C10) -> グリーンシャワー | D22: =IF(売上入力!D10="","",売上入力!D10) -> 売上 | E22: =IFERROR(IF(売上入力!E10="",0,売上入力!E10*INDEX(マスター_OTA!$B$4:$B$29,MATCH(売上入力!D10,マスター_OTA!$A$4:$A$29,0))/100),0) -> 0 | F22: =IF(売上入力!A10="","",売上入力!A10) -> 46113 | G22: 当月分
A23: =IFERROR(IF(売上入力!A10="","",IF(INDEX(マスター_OTA!$C$4:$C$29,MATCH(売上入力!D10,マスター_OTA!$A$4:$A$29,0))=0,"",DATE(YEAR(売上入力!A10),MONTH(売上入力!A10)+1,IFERROR(INDEX(マスター_OTA!$F$4:$F$29,MATCH(売上入力!D10,マスター_OTA!$A$4:$A$29,0)),25)))),"") -> 46152 | B23: =IF(売上入力!B10="","",売上入力!B10) -> リゾート | C23: =IF(売上入力!C10="","",売上入力!C10) -> グリーンシャワー | D23: =IF(売上入力!D10="","",売上入力!D10) -> 売上 | E23: =IFERROR(IF(売上入力!E10="",0,売上入力!E10*INDEX(マスター_OTA!$C$4:$C$29,MATCH(売上入力!D10,マスター_OTA!$A$4:$A$29,0))/100),0) -> 0 | F23: =IF(売上入力!A10="","",売上入力!A10) -> 46113 | G23: 翌月分
A24: =IFERROR(IF(売上入力!A10="","",IF(INDEX(マスター_OTA!$D$4:$D$29,MATCH(売上入力!D10,マスター_OTA!$A$4:$A$29,0))=0,"",DATE(YEAR(売上入力!A10),MONTH(売上入力!A10)+2,IFERROR(INDEX(マスター_OTA!$G$4:$G$29,MATCH(売上入力!D10,マスター_OTA!$A$4:$A$29,0)),25)))),"") -> 46198 | B24: =IF(売上入力!B10="","",売上入力!B10) -> リゾート | C24: =IF(売上入力!C10="","",売上入力!C10) -> グリーンシャワー | D24: =IF(売上入力!D10="","",売上入力!D10) -> 売上 | E24: =IFERROR(IF(売上入力!E10="",0,売上入力!E10*INDEX(マスター_OTA!$D$4:$D$29,MATCH(売上入力!D10,マスター_OTA!$A$4:$A$29,0))/100),0) -> 0 | F24: =IF(売上入力!A10="","",売上入力!A10) -> 46113 | G24: 翌々月分
A25: =IFERROR(IF(売上入力!A11="","",IF(INDEX(マスター_OTA!$B$4:$B$29,MATCH(売上入力!D11,マスター_OTA!$A$4:$A$29,0))=0,"",DATE(YEAR(売上入力!A11),MONTH(売上入力!A11),IFERROR(INDEX(マスター_OTA!$E$4:$E$29,MATCH(売上入力!D11,マスター_OTA!$A$4:$A$29,0)),28)))),"") -> 46132 | B25: =IF(売上入力!B11="","",売上入力!B11) -> リゾート | C25: =IF(売上入力!C11="","",売上入力!C11) -> フォレストヒルズガーデン | D25: =IF(売上入力!D11="","",売上入力!D11) -> 売上 | E25: =IFERROR(IF(売上入力!E11="",0,売上入力!E11*INDEX(マスター_OTA!$B$4:$B$29,MATCH(売上入力!D11,マスター_OTA!$A$4:$A$29,0))/100),0) -> 0 | F25: =IF(売上入力!A11="","",売上入力!A11) -> 46113 | G25: 当月分
A26: =IFERROR(IF(売上入力!A11="","",IF(INDEX(マスター_OTA!$C$4:$C$29,MATCH(売上入力!D11,マスター_OTA!$A$4:$A$29,0))=0,"",DATE(YEAR(売上入力!A11),MONTH(売上入力!A11)+1,IFERROR(INDEX(マスター_OTA!$F$4:$F$29,MATCH(売上入力!D11,マスター_OTA!$A$4:$A$29,0)),25)))),"") -> 46152 | B26: =IF(売上入力!B11="","",売上入力!B11) -> リゾート | C26: =IF(売上入力!C11="","",売上入力!C11) -> フォレストヒルズガーデン | D26: =IF(売上入力!D11="","",売上入力!D11) -> 売上 | E26: =IFERROR(IF(売上入力!E11="",0,売上入力!E11*INDEX(マスター_OTA!$C$4:$C$29,MATCH(売上入力!D11,マスター_OTA!$A$4:$A$29,0))/100),0) -> 0 | F26: =IF(売上入力!A11="","",売上入力!A11) -> 46113 | G26: 翌月分
A27: =IFERROR(IF(売上入力!A11="","",IF(INDEX(マスター_OTA!$D$4:$D$29,MATCH(売上入力!D11,マスター_OTA!$A$4:$A$29,0))=0,"",DATE(YEAR(売上入力!A11),MONTH(売上入力!A11)+2,IFERROR(INDEX(マスター_OTA!$G$4:$G$29,MATCH(売上入力!D11,マスター_OTA!$A$4:$A$29,0)),25)))),"") -> 46198 | B27: =IF(売上入力!B11="","",売上入力!B11) -> リゾート | C27: =IF(売上入力!C11="","",売上入力!C11) -> フォレストヒルズガーデン | D27: =IF(売上入力!D11="","",売上入力!D11) -> 売上 | E27: =IFERROR(IF(売上入力!E11="",0,売上入力!E11*INDEX(マスター_OTA!$D$4:$D$29,MATCH(売上入力!D11,マスター_OTA!$A$4:$A$29,0))/100),0) -> 0 | F27: =IF(売上入力!A11="","",売上入力!A11) -> 46113 | G27: 翌々月分
A28: =IFERROR(IF(売上入力!A12="","",IF(INDEX(マスター_OTA!$B$4:$B$29,MATCH(売上入力!D12,マスター_OTA!$A$4:$A$29,0))=0,"",DATE(YEAR(売上入力!A12),MONTH(売上入力!A12),IFERROR(INDEX(マスター_OTA!$E$4:$E$29,MATCH(売上入力!D12,マスター_OTA!$A$4:$A$29,0)),28)))),"") -> 46132 | B28: =IF(売上入力!B12="","",売上入力!B12) -> リゾート | C28: =IF(売上入力!C12="","",売上入力!C12) -> 壱番館 | D28: =IF(売上入力!D12="","",売上入力!D12) -> 売上 | E28: =IFERROR(IF(売上入力!E12="",0,売上入力!E12*INDEX(マスター_OTA!$B$4:$B$29,MATCH(売上入力!D12,マスター_OTA!$A$4:$A$29,0))/100),0) -> 0 | F28: =IF(売上入力!A12="","",売上入力!A12) -> 46113 | G28: 当月分
A29: =IFERROR(IF(売上入力!A12="","",IF(INDEX(マスター_OTA!$C$4:$C$29,MATCH(売上入力!D12,マスター_OTA!$A$4:$A$29,0))=0,"",DATE(YEAR(売上入力!A12),MONTH(売上入力!A12)+1,IFERROR(INDEX(マスター_OTA!$F$4:$F$29,MATCH(売上入力!D12,マスター_OTA!$A$4:$A$29,0)),25)))),"") -> 46152 | B29: =IF(売上入力!B12="","",売上入力!B12) -> リゾート | C29: =IF(売上入力!C12="","",売上入力!C12) -> 壱番館 | D29: =IF(売上入力!D12="","",売上入力!D12) -> 売上 | E29: =IFERROR(IF(売上入力!E12="",0,売上入力!E12*INDEX(マスター_OTA!$C$4:$C$29,MATCH(売上入力!D12,マスター_OTA!$A$4:$A$29,0))/100),0) -> 0 | F29: =IF(売上入力!A12="","",売上入力!A12) -> 46113 | G29: 翌月分
A30: =IFERROR(IF(売上入力!A12="","",IF(INDEX(マスター_OTA!$D$4:$D$29,MATCH(売上入力!D12,マスター_OTA!$A$4:$A$29,0))=0,"",DATE(YEAR(売上入力!A12),MONTH(売上入力!A12)+2,IFERROR(INDEX(マスター_OTA!$G$4:$G$29,MATCH(売上入力!D12,マスター_OTA!$A$4:$A$29,0)),25)))),"") -> 46198 | B30: =IF(売上入力!B12="","",売上入力!B12) -> リゾート | C30: =IF(売上入力!C12="","",売上入力!C12) -> 壱番館 | D30: =IF(売上入力!D12="","",売上入力!D12) -> 売上 | E30: =IFERROR(IF(売上入力!E12="",0,売上入力!E12*INDEX(マスター_OTA!$D$4:$D$29,MATCH(売上入力!D12,マスター_OTA!$A$4:$A$29,0))/100),0) -> 0 | F30: =IF(売上入力!A12="","",売上入力!A12) -> 46113 | G30: 翌々月分
A31: =IFERROR(IF(売上入力!A13="","",IF(INDEX(マスター_OTA!$B$4:$B$29,MATCH(売上入力!D13,マスター_OTA!$A$4:$A$29,0))=0,"",DATE(YEAR(売上入力!A13),MONTH(売上入力!A13),IFERROR(INDEX(マスター_OTA!$E$4:$E$29,MATCH(売上入力!D13,マスター_OTA!$A$4:$A$29,0)),28)))),"") -> 46132 | B31: =IF(売上入力!B13="","",売上入力!B13) -> リゾート | C31: =IF(売上入力!C13="","",売上入力!C13) -> 天神 | D31: =IF(売上入力!D13="","",売上入力!D13) -> ホテル売上 | E31: =IFERROR(IF(売上入力!E13="",0,売上入力!E13*INDEX(マスター_OTA!$B$4:$B$29,MATCH(売上入力!D13,マスター_OTA!$A$4:$A$29,0))/100),0) -> 0 | F31: =IF(売上入力!A13="","",売上入力!A13) -> 46113 | G31: 当月分
A32: =IFERROR(IF(売上入力!A13="","",IF(INDEX(マスター_OTA!$C$4:$C$29,MATCH(売上入力!D13,マスター_OTA!$A$4:$A$29,0))=0,"",DATE(YEAR(売上入力!A13),MONTH(売上入力!A13)+1,IFERROR(INDEX(マスター_OTA!$F$4:$F$29,MATCH(売上入力!D13,マスター_OTA!$A$4:$A$29,0)),25)))),"") -> 46152 | B32: =IF(売上入力!B13="","",売上入力!B13) -> リゾート | C32: =IF(売上入力!C13="","",売上入力!C13) -> 天神 | D32: =IF(売上入力!D13="","",売上入力!D13) -> ホテル売上 | E32: =IFERROR(IF(売上入力!E13="",0,売上入力!E13*INDEX(マスター_OTA!$C$4:$C$29,MATCH(売上入力!D13,マスター_OTA!$A$4:$A$29,0))/100),0) -> 0 | F32: =IF(売上入力!A13="","",売上入力!A13) -> 46113 | G32: 翌月分
A33: =IFERROR(IF(売上入力!A13="","",IF(INDEX(マスター_OTA!$D$4:$D$29,MATCH(売上入力!D13,マスター_OTA!$A$4:$A$29,0))=0,"",DATE(YEAR(売上入力!A13),MONTH(売上入力!A13)+2,IFERROR(INDEX(マスター_OTA!$G$4:$G$29,MATCH(売上入力!D13,マスター_OTA!$A$4:$A$29,0)),25)))),"") -> 46198 | B33: =IF(売上入力!B13="","",売上入力!B13) -> リゾート | C33: =IF(売上入力!C13="","",売上入力!C13) -> 天神 | D33: =IF(売上入力!D13="","",売上入力!D13) -> ホテル売上 | E33: =IFERROR(IF(売上入力!E13="",0,売上入力!E13*INDEX(マスター_OTA!$D$4:$D$29,MATCH(売上入力!D13,マスター_OTA!$A$4:$A$29,0))/100),0) -> 0 | F33: =IF(売上入力!A13="","",売上入力!A13) -> 46113 | G33: 翌々月分
A34: =IFERROR(IF(売上入力!A14="","",IF(INDEX(マスター_OTA!$B$4:$B$29,MATCH(売上入力!D14,マスター_OTA!$A$4:$A$29,0))=0,"",DATE(YEAR(売上入力!A14),MONTH(売上入力!A14),IFERROR(INDEX(マスター_OTA!$E$4:$E$29,MATCH(売上入力!D14,マスター_OTA!$A$4:$A$29,0)),28)))),"") -> 46132 | B34: =IF(売上入力!B14="","",売上入力!B14) -> リゾート | C34: =IF(売上入力!C14="","",売上入力!C14) -> 弐番館 | D34: =IF(売上入力!D14="","",売上入力!D14) -> 売上 | E34: =IFERROR(IF(売上入力!E14="",0,売上入力!E14*INDEX(マスター_OTA!$B$4:$B$29,MATCH(売上入力!D14,マスター_OTA!$A$4:$A$29,0))/100),0) -> 0 | F34: =IF(売上入力!A14="","",売上入力!A14) -> 46113 | G34: 当月分
A35: =IFERROR(IF(売上入力!A14="","",IF(INDEX(マスター_OTA!$C$4:$C$29,MATCH(売上入力!D14,マスター_OTA!$A$4:$A$29,0))=0,"",DATE(YEAR(売上入力!A14),MONTH(売上入力!A14)+1,IFERROR(INDEX(マスター_OTA!$F$4:$F$29,MATCH(売上入力!D14,マスター_OTA!$A$4:$A$29,0)),25)))),"") -> 46152 | B35: =IF(売上入力!B14="","",売上入力!B14) -> リゾート | C35: =IF(売上入力!C14="","",売上入力!C14) -> 弐番館 | D35: =IF(売上入力!D14="","",売上入力!D14) -> 売上 | E35: =IFERROR(IF(売上入力!E14="",0,売上入力!E14*INDEX(マスター_OTA!$C$4:$C$29,MATCH(売上入力!D14,マスター_OTA!$A$4:$A$29,0))/100),0) -> 0 | F35: =IF(売上入力!A14="","",売上入力!A14) -> 46113 | G35: 翌月分
A36: =IFERROR(IF(売上入力!A14="","",IF(INDEX(マスター_OTA!$D$4:$D$29,MATCH(売上入力!D14,マスター_OTA!$A$4:$A$29,0))=0,"",DATE(YEAR(売上入力!A14),MONTH(売上入力!A14)+2,IFERROR(INDEX(マスター_OTA!$G$4:$G$29,MATCH(売上入力!D14,マスター_OTA!$A$4:$A$29,0)),25)))),"") -> 46198 | B36: =IF(売上入力!B14="","",売上入力!B14) -> リゾート | C36: =IF(売上入力!C14="","",売上入力!C14) -> 弐番館 | D36: =IF(売上入力!D14="","",売上入力!D14) -> 売上 | E36: =IFERROR(IF(売上入力!E14="",0,売上入力!E14*INDEX(マスター_OTA!$D$4:$D$29,MATCH(売上入力!D14,マスター_OTA!$A$4:$A$29,0))/100),0) -> 0 | F36: =IF(売上入力!A14="","",売上入力!A14) -> 46113 | G36: 翌々月分
A37: =IFERROR(IF(売上入力!A15="","",IF(INDEX(マスター_OTA!$B$4:$B$29,MATCH(売上入力!D15,マスター_OTA!$A$4:$A$29,0))=0,"",DATE(YEAR(売上入力!A15),MONTH(売上入力!A15),IFERROR(INDEX(マスター_OTA!$E$4:$E$29,MATCH(売上入力!D15,マスター_OTA!$A$4:$A$29,0)),28)))),"") -> 46132 | B37: =IF(売上入力!B15="","",売上入力!B15) -> モーテル | C37: =IF(売上入力!C15="","",売上入力!C15) -> 弥山 | D37: =IF(売上入力!D15="","",売上入力!D15) -> ホテル売上 | E37: =IFERROR(IF(売上入力!E15="",0,売上入力!E15*INDEX(マスター_OTA!$B$4:$B$29,MATCH(売上入力!D15,マスター_OTA!$A$4:$A$29,0))/100),0) -> 0 | F37: =IF(売上入力!A15="","",売上入力!A15) -> 46113 | G37: 当月分
A38: =IFERROR(IF(売上入力!A15="","",IF(INDEX(マスター_OTA!$C$4:$C$29,MATCH(売上入力!D15,マスター_OTA!$A$4:$A$29,0))=0,"",DATE(YEAR(売上入力!A15),MONTH(売上入力!A15)+1,IFERROR(INDEX(マスター_OTA!$F$4:$F$29,MATCH(売上入力!D15,マスター_OTA!$A$4:$A$29,0)),25)))),"") -> 46152 | B38: =IF(売上入力!B15="","",売上入力!B15) -> モーテル | C38: =IF(売上入力!C15="","",売上入力!C15) -> 弥山 | D38: =IF(売上入力!D15="","",売上入力!D15) -> ホテル売上 | E38: =IFERROR(IF(売上入力!E15="",0,売上入力!E15*INDEX(マスター_OTA!$C$4:$C$29,MATCH(売上入力!D15,マスター_OTA!$A$4:$A$29,0))/100),0) -> 0 | F38: =IF(売上入力!A15="","",売上入力!A15) -> 46113 | G38: 翌月分
A39: =IFERROR(IF(売上入力!A15="","",IF(INDEX(マスター_OTA!$D$4:$D$29,MATCH(売上入力!D15,マスター_OTA!$A$4:$A$29,0))=0,"",DATE(YEAR(売上入力!A15),MONTH(売上入力!A15)+2,IFERROR(INDEX(マスター_OTA!$G$4:$G$29,MATCH(売上入力!D15,マスター_OTA!$A$4:$A$29,0)),25)))),"") -> 46198 | B39: =IF(売上入力!B15="","",売上入力!B15) -> モーテル | C39: =IF(売上入力!C15="","",売上入力!C15) -> 弥山 | D39: =IF(売上入力!D15="","",売上入力!D15) -> ホテル売上 | E39: =IFERROR(IF(売上入力!E15="",0,売上入力!E15*INDEX(マスター_OTA!$D$4:$D$29,MATCH(売上入力!D15,マスター_OTA!$A$4:$A$29,0))/100),0) -> 0 | F39: =IF(売上入力!A15="","",売上入力!A15) -> 46113 | G39: 翌々月分
A40: =IFERROR(IF(売上入力!A16="","",IF(INDEX(マスター_OTA!$B$4:$B$29,MATCH(売上入力!D16,マスター_OTA!$A$4:$A$29,0))=0,"",DATE(YEAR(売上入力!A16),MONTH(売上入力!A16),IFERROR(INDEX(マスター_OTA!$E$4:$E$29,MATCH(売上入力!D16,マスター_OTA!$A$4:$A$29,0)),28)))),"") -> 46132 | B40: =IF(売上入力!B16="","",売上入力!B16) -> リゾート | C40: =IF(売上入力!C16="","",売上入力!C16) -> 本川 | D40: =IF(売上入力!D16="","",売上入力!D16) -> ホテル売上 | E40: =IFERROR(IF(売上入力!E16="",0,売上入力!E16*INDEX(マスター_OTA!$B$4:$B$29,MATCH(売上入力!D16,マスター_OTA!$A$4:$A$29,0))/100),0) -> 0 | F40: =IF(売上入力!A16="","",売上入力!A16) -> 46113 | G40: 当月分
...

Sheet 未払予定一覧
A1: 未払予定一覧（全社統合・カード枠回復統合・会社列で識別）
A2: 優先度: | B2: 高 | C2: 中 | D2: 低 | E2: 月次 | F2: カード枠回復 | H2: ※ 支払予定日入力で月次サマリー自動反映／状況"済"で支払完了表示／請求書PDFパスをQ列に貼付
A3: 会社 | B3: 種別 | C3: 物件 | D3: 概要 | E3: 勘定科目 | F3: 期日 | G3: 請求先 | H3: 当月分 | I3: 前月繰越 | J3: 前々月繰越 | K3: 前々々月以前 | L3: 累積未払合計 | M3: 優先度 | N3: 支払予定日 | O3: 支払予定額 | P3: 支払状況 | Q3: 請求書ファイル
A4: ザック | B4: 月次予定 | C4: ココユニバース | D4: トラストユアサービス | E4: 通信費 | F4: 46173 | G4: SAUNA | H4: 6050 | I4: 0 | J4: 0 | K4: 0 | L4: 6050 | M4: 月次 | N4: 46173 | O4: 6050
A5: モーテル | B5: 未払繰越 | C5: モーテル | D5: ASKUL（2か月分） | E5: 備品消耗品費 | F5: 46157 | G5: 弥山 | H5: 39871 | I5: 15932 | J5: 0 | K5: 0 | L5: 15932 | M5: 低 | N5: 46157 | O5: 39871
A6: モーテル | B6: 未払繰越 | C6: モーテル | D6: あしたば（4月分） | E6: 業務委託料 | F6: 46157 | G6: 弥山 | H6: 11000 | I6: 11000 | J6: 11000 | K6: 0 | L6: 22000 | M6: 中 | N6: 46157 | O6: 11000
A7: モーテル | B7: 未払繰越 | C7: モーテル | D7: ふくや（3ヶ月分） | E7: 食材費 | F7: 46171 | G7: 弥山 | H7: 6249 | I7: 12741 | J7: 12910 | K7: 0 | L7: 25651 | M7: 中 | N7: 46171 | O7: 6249
A9: モーテル | B9: 月次予定 | C9: モーテル | D9: JTB商事 | E9: 備品消耗品費 | F9: 46157 | G9: 弥山 | H9: 131472 | I9: 0 | J9: 0 | K9: 0 | L9: 131472 | M9: 月次 | N9: 46157 | O9: 131472
A12: モーテル | B12: 月次予定 | C12: モーテル | D12: シーエスプロ | E12: 備品消耗品費 | F12: 46171 | G12: 弥山 | H12: 20240 | I12: 0 | J12: 0 | K12: 0 | L12: 20240 | M12: 月次 | N12: 46171 | O12: 20240
A13: モーテル | B13: 月次予定 | C13: モーテル | D13: トラストユアサービス | E13: 通信費 | F13: 46171 | G13: 弥山 | H13: 5000 | I13: 0 | J13: 0 | K13: 0 | L13: 5000 | M13: 月次 | N13: 46171 | O13: 5000
A14: モーテル | B14: 月次予定 | C14: モーテル | D14: ネットシスジャパン | E14: システム利用料 | F14: 46157 | G14: 弥山 | H14: 13750 | I14: 0 | J14: 0 | K14: 0 | L14: 13750 | M14: 月次 | N14: 46157 | O14: 56100
A16: モーテル | B16: 月次予定 | C16: モーテル | D16: フロンテイアリネン（3月分） | E16: 衛生管理費 | F16: 46157 | G16: 弥山 | H16: 1153421 | I16: 0 | J16: 0 | K16: 0 | L16: 1153421 | M16: 月次 | N16: 46157 | O16: 1153421
A17: モーテル | B17: 月次予定 | C17: モーテル | D17: リクルート（じゃらん） | E17: システム利用料 | F17: 46153 | G17: 弥山 | H17: 144004 | I17: 0 | J17: 0 | K17: 0 | L17: 144004 | M17: 月次 | N17: 46153 | O17: 144004
A18: モーテル | B18: 月次予定 | C18: モーテル | D18: 新宮島観光旅館組合 | E18: 諸会費 | F18: 46171 | G18: 弥山 | H18: 18000 | I18: 0 | J18: 0 | K18: 0 | L18: 18000 | M18: 月次 | N18: 46171 | O18: 18000
A19: モーテル | B19: 月次予定 | C19: モーテル | D19: 日本食研 | E19: 食材費 | F19: 46162 | G19: 弥山 | H19: 10026 | I19: 0 | J19: 0 | K19: 0 | L19: 10026 | M19: 月次 | N19: 46162 | O19: 10026
... A22: リゾート | B22: 未払繰越 | C22: フォレスト | D22: フォワード | E22: 備品消耗品費 | F22: 46171 | G22: フォレストヒルズ | H22: 7346 | I22: 0 | J22: 18648 | K22: 0 | L22: 18648 | M22: 中 | N22: 46171 | O22: 7346
A23: リゾート | B23: 未払繰越 | C23: リゾート | D23: あしたば | E23: 業務委託費 | F23: 46157 | H23: 132000 | I23: 132000 | J23: 132000 | K23: 0 | L23: 264000 | M23: 中 | N23: 46157 | O23: 132000
A24: リゾート | B24: 未払繰越 | C24: リゾート | D24: アイパス | E24: システム利用料 | F24: 46171 | H24: 193050 | I24: 193050 | J24: 303050 | K24: 305800 | L24: 801900 | M24: 高 | N24: 46171 | O24: 193050
A25: リゾート | B25: 未払繰越 | C25: リゾート | D25: アシード（5か月分） | E25: リース料 | F25: 46171 | G25: デルーネ | H25: 17600 | I25: 17600 | J25: 17600 | K25: 35200 | L25: 70400 | M25: 高 | N25: 46171 | O25: 17600
A26: リゾート | B26: 未払繰越 | C26: リゾート | D26: アペックス（3ヶ月分） | E26: 備品消耗品費 | F26: 46171 | G26: たけはら | H26: 13200 | I26: 35340 | J26: 13200 | K26: 0 | L26: 48540 | M26: 中 | N26: 46171 | O26: 46530
A28: リゾート | B28: 未払繰越 | C28: リゾート | D28: イマイチ（3ヶ月分） | E28: 備品消耗品費 | F28: 46171 | G28: たけはら | H28: 13860 | I28: 13860 | J28: 10626 | K28: 0 | L28: 24486 | M28: 中 | N28: 46171 | O28: 13860
A29: リゾート | B29: 未払繰越 | C29: リゾート | D29: キャノン | E29: 備品消耗品費 | F29: 46167 | G29: ビュー | H29: 9852 | I29: 7893 | J29: 15809 | K29: 0 | L29: 23702 | M29: 中 | N29: 46167 | O29: 9852
A30: リゾート | B30: 未払繰越 | C30: リゾート | D30: クリンプロ（4か月分） | E30: 衛生管理費 | F30: 46171 | G30: 温井 | H30: 96800 | I30: 173800 | J30: 194040 | K30: 121000 | L30: 488840 | M30: 高 | N30: 46171 | O30: 96800
A31: リゾート | B31: 未払繰越 | C31: リゾート | D31: 安芸クリーナー（5か月分） | E31: ゴミ収集費 | F31: 46171 | G31: ビュー | H31: 27500 | I31: 27500 | J31: 27500 | K31: 55000 | L31: 110000 | M31: 高 | N31: 46171 | O31: 27500
A32: リゾート | B32: 未払繰越 | C32: リゾート | D32: 百姓屋（4か月分） | E32: 食材費 | F32: 46171 | G32: いこいの村 | H32: 33000 | I32: 82500 | J32: 60500 | K32: 44000 | L32: 187000 | M32: 高 | N32: 46171 | O32: 33000
A33: リゾート | B33: 未払繰越 | C33: リゾート | D33: 竹原クリーナー（5か月分） | E33: ゴミ収集費 | F33: 46171 | G33: たけはら | H33: 22000 | I33: 22000 | J33: 22000 | K33: 44000 | L33: 88000 | M33: 高 | N33: 46171 | O33: 22000
A34: リゾート | B34: 未払繰越 | C34: リゾート | D34: 第一興商 | E34: 通信費 | F34: 46150 | G34: たけはら | H34: 0 | I34: 0 | J34: 22000 | K34: 44000 | L34: 66000 | M34: 高 | N34: 46149 | O34: 100000
A35: リゾート | B35: 未払繰越 | C35: リゾート | D35: 第一興商（5か月分） | E35: 通信費 | F35: 46171 | G35: いこいの村 | H35: 46750 | I35: 46750 | J35: 46750 | K35: 93500 | L35: 187000 | M35: 高 | N35: 46171 | O35: 46750
A36: リゾート | B36: 未払繰越 | C36: リゾート | D36: 西部環境（4か月分） | E36: ゴミ収集費 | F36: 46171 | G36: 温井 | H36: 30800 | I36: 30800 | J36: 30800 | K36: 30800 | L36: 92400 | M36: 高 | O36: 92400
A37: リゾート | B37: 未払繰越 | C37: リゾート | D37: 青原木材（3ヶ月分） | E37: 備品消耗品費 | F37: 46171 | G37: 温井 | H37: 319440 | I37: 372405 | J37: 114015 | K37: 0 | L37: 486420 | M37: 中 | O37: 486420
A38: リゾート | B38: 月次予定 | C38: ほうらい | D38: ネットシスジャパン | E38: システム利用料 | F38: 46157 | H38: 16500 | I38: 0 | J38: 0 | K38: 0 | L38: 16500 | M38: 月次 | N38: 46172 | O38: 89800
A39: リゾート | B39: 月次予定 | C39: ほうらい | D39: 中国電力（1004） | E39: 水道光熱費 | F39: 46160 | H39: 5927 | I39: 0 | J39: 0 | K39: 0 | L39: 5927 | M39: 月次 | N39: 46160 | O39: 5927
A40: リゾート | B40: 月次予定 | C40: ほうらい | D40: 中国電力（残高不足により引落不能） | E40: 水道光熱費 | F40: 46149 | H40: 363435 | I40: 0 | J40: 0 | K40: 0 | L40: 363435 | M40: 月次 | N40: 46149 | O40: 363435
A42: リゾート | B42: 月次予定 | C42: フォレスト | D42: チュウブ(第1回） | E42: 業務委託費 | F42: 46149 | G42: フォレストヒルズ | H42: 660000 | I42: 0 | J42: 0 | K42: 0 | L42: 660000 | M42: 月次 | N42: 46149 | O42: 660000
A43: リゾート | B43: 月次予定 | C43: フォレスト | D43: チュウブ(第2回） | E43: 業務委託費 | F43: 46153 | G43: フォレストヒルズ | H43: 660000 | I43: 0 | J43: 0 | K43: 0 | L43: 660000 | M43: 月次 | N43: 46153 | O43: 660000
A44: リゾート | B44: 月次予定 | C44: フォレスト | D44: チュウブ(第3回） | E44: 業務委託費 | F44: 46160 | G44: フォレストヒルズ | H44: 660000 | I44: 0 | J44: 0 | K44: 0 | L44: 660000 | M44: 月次 | N44: 46160 | O44: 660000
A45: リゾート | B45: 月次予定 | C45: フォレスト | D45: チュウブ(第4回）※計2,640,000 | E45: 業務委託費 | F45: 46171 | G45: フォレストヒルズ | H45: 660000 | I45: 0 | J45: 0 | K45: 0 | L45: 660000 | M45: 月次 | N45: 46171 | O45: 660000
A47: リゾート | B47: 月次予定 | C47: フォレスト | D47: 半田電気管理 | E47: 設備費 | F47: 46171 | G47: フォレストヒルズ | H47: 23100 | I47: 0 | J47: 0 | K47: 0 | L47: 23100 | M47: 月次 | N47: 46171 | O47: 23100
A48: リゾート | B48: 月次予定 | C48: フォレスト | D48: 広島ガスプロパン | E48: 水道光熱費 | F48: 46171 | G48: フォレストヒルズ | H48: 9207 | I48: 0 | J48: 0 | K48: 0 | L48: 9207 | M48: 月次 | N48: 46171 | O48: 9207
A49: リゾート | B49: 月次予定 | C49: フォレスト | D49: 日本基準寝具 | E49: 衛生管理費 | F49: 46157 | G49: フォレストヒルズ | H49: 132929 | I49: 0 | J49: 0 | K49: 0 | L49: 132929 | M49: 月次 | N49: 46157 | O49: 33000
...

Sheet 日次_レジデンス
A1: 日次キャッシュフロー — レジデンス（5月〜8月 縦積み）
A2: 入金=入金入力（会社=本社）+入金予測／支出=未払予定一覧（カード枠回復除く）／使用可能額=累計差引+累計カード枠回復
A3: 日付 | B3: 入金（円） | C3: 支出（円） | D3: 日次差引（円） | E3: 累計差引（円） | F3: カード枠回復額（円） | G3: 使用可能額（円） | H3: 備考
A4: ■ 5月
A5: 46142 | B5: =SUMIFS(入金入力!$E$4:$E$580,入金入力!$B$4:$B$580,A5,入金入力!$A$4:$A$580,"レジデンス")+SUMIFS(入金予測!$E$4:$E$603,入金予測!$A$4:$A$603,A5,入金予測!$B$4:$B$603,"レジデンス") -> 89000 | C5: =SUMIFS(未払予定一覧!$O$4:$O$830,未払予定一覧!$N$4:$N$830,A5,未払予定一覧!$A$4:$A$830,"レジデンス",未払予定一覧!$B$4:$B$830,"未払繰越")+SUMIFS(未払予定一覧!$O$4:$O$830,未払予定一覧!$N$4:$N$830,A5,未払予定一覧!$A$4:$A$830,"レジデンス",未払予定一覧!$B$4:$B$830,"月次予定") -> 976912 | D5: =B5-C5-F5 -> -887912 | E5: =D5 -> -887912 | F5: =SUMIFS(未払予定一覧!$O$4:$O$830,未払予定一覧!$N$4:$N$830,A5,未払予定一覧!$A$4:$A$830,"レジデンス",未払予定一覧!$B$4:$B$830,"カード枠回復") -> 0 | G5: =D5+F5 -> -887912
A6: 46143 | B6: =SUMIFS(入金入力!$E$4:$E$580,入金入力!$B$4:$B$580,A6,入金入力!$A$4:$A$580,"レジデンス")+SUMIFS(入金予測!$E$4:$E$603,入金予測!$A$4:$A$603,A6,入金予測!$B$4:$B$603,"レジデンス") -> 24506 | C6: =SUMIFS(未払予定一覧!$O$4:$O$830,未払予定一覧!$N$4:$N$830,A6,未払予定一覧!$A$4:$A$830,"レジデンス",未払予定一覧!$B$4:$B$830,"未払繰越")+SUMIFS(未払予定一覧!$O$4:$O$830,未払予定一覧!$N$4:$N$830,A6,未払予定一覧!$A$4:$A$830,"レジデンス",未払予定一覧!$B$4:$B$830,"月次予定") -> 0 | D6: =B6-C6-F6 -> 24506 | E6: =E5+D6 -> -863406 | F6: =SUMIFS(未払予定一覧!$O$4:$O$830,未払予定一覧!$N$4:$N$830,A6,未払予定一覧!$A$4:$A$830,"レジデンス",未払予定一覧!$B$4:$B$830,"カード枠回復") -> 0 | G6: =G5+D6+F6 -> -863406
A7: 46144 | B7: =SUMIFS(入金入力!$E$4:$E$580,入金入力!$B$4:$B$580,A7,入金入力!$A$4:$A$580,"レジデンス")+SUMIFS(入金予測!$E$4:$E$603,入金予測!$A$4:$A$603,A7,入金予測!$B$4:$B$603,"レジデンス") -> 0 | C7: =SUMIFS(未払予定一覧!$O$4:$O$830,未払予定一覧!$N$4:$N$830,A7,未払予定一覧!$A$4:$A$830,"レジデンス",未払予定一覧!$B$4:$B$830,"未払繰越")+SUMIFS(未払予定一覧!$O$4:$O$830,未払予定一覧!$N$4:$N$830,A7,未払予定一覧!$A$4:$A$830,"レジデンス",未払予定一覧!$B$4:$B$830,"月次予定") -> 0 | D7: =B7-C7-F7 -> 0 | E7: =E6+D7 -> -863406 | F7: =SUMIFS(未払予定一覧!$O$4:$O$830,未払予定一覧!$N$4:$N$830,A7,未払予定一覧!$A$4:$A$830,"レジデンス",未払予定一覧!$B$4:$B$830,"カード枠回復") -> 0 | G7: =G6+D7+F7 -> -863406 | H7: 土
A8: 46145 | B8: =SUMIFS(入金入力!$E$4:$E$580,入金入力!$B$4:$B$580,A8,入金入力!$A$4:$A$580,"レジデンス")+SUMIFS(入金予測!$E$4:$E$603,入金予測!$A$4:$A$603,A8,入金予測!$B$4:$B$603,"レジデンス") -> 0 | C8: =SUMIFS(未払予定一覧!$O$4:$O$830,未払予定一覧!$N$4:$N$830,A8,未払予定一覧!$A$4:$A$830,"レジデンス",未払予定一覧!$B$4:$B$830,"未払繰越")+SUMIFS(未払予定一覧!$O$4:$O$830,未払予定一覧!$N$4:$N$830,A8,未払予定一覧!$A$4:$A$830,"レジデンス",未払予定一覧!$B$4:$B$830,"月次予定") -> 0 | D8: =B8-C8-F8 -> 0 | E8: =E7+D8 -> -863406 | F8: =SUMIFS(未払予定一覧!$O$4:$O$830,未払予定一覧!$N$4:$N$830,A8,未払予定一覧!$A$4:$A$830,"レジデンス",未払予定一覧!$B$4:$B$830,"カード枠回復") -> 0 | G8: =G7+D8+F8 -> -863406 | H8: 日
A9: 46146 | B9: =SUMIFS(入金入力!$E$4:$E$580,入金入力!$B$4:$B$580,A9,入金入力!$A$4:$A$580,"レジデンス")+SUMIFS(入金予測!$E$4:$E$603,入金予測!$A$4:$A$603,A9,入金予測!$B$4:$B$603,"レジデンス") -> 0 | C9: =SUMIFS(未払予定一覧!$O$4:$O$830,未払予定一覧!$N$4:$N$830,A9,未払予定一覧!$A$4:$A$830,"レジデンス",未払予定一覧!$B$4:$B$830,"未払繰越")+SUMIFS(未払予定一覧!$O$4:$O$830,未払予定一覧!$N$4:$N$830,A9,未払予定一覧!$A$4:$A$830,"レジデンス",未払予定一覧!$B$4:$B$830,"月次予定") -> 0 | D9: =B9-C9-F9 -> 0 | E9: =E8+D9 -> -863406 | F9: =SUMIFS(未払予定一覧!$O$4:$O$830,未払予定一覧!$N$4:$N$830,A9,未払予定一覧!$A$4:$A$830,"レジデンス",未払予定一覧!$B$4:$B$830,"カード枠回復") -> 0 | G9: =G8+D9+F9 -> -863406
A10: 46147 | B10: =SUMIFS(入金入力!$E$4:$E$580,入金入力!$B$4:$B$580,A10,入金入力!$A$4:$A$580,"レジデンス")+SUMIFS(入金予測!$E$4:$E$603,入金予測!$A$4:$A$603,A10,入金予測!$B$4:$B$603,"レジデンス") -> 0 | C10: =SUMIFS(未払予定一覧!$O$4:$O$830,未払予定一覧!$N$4:$N$830,A10,未払予定一覧!$A$4:$A$830,"レジデンス",未払予定一覧!$B$4:$B$830,"未払繰越")+SUMIFS(未払予定一覧!$O$4:$O$830,未払予定一覧!$N$4:$N$830,A10,未払予定一覧!$A$4:$A$830,"レジデンス",未払予定一覧!$B$4:$B$830,"月次予定") -> 0 | D10: =B10-C10-F10 -> 0 | E10: =E9+D10 -> -863406 | F10: =SUMIFS(未払予定一覧!$O$4:$O$830,未払予定一覧!$N$4:$N$830,A10,未払予定一覧!$A$4:$A$830,"レジデンス",未払予定一覧!$B$4:$B$830,"カード枠回復") -> 0 | G10: =G9+D10+F10 -> -863406
A11: 46148 | B11: =SUMIFS(入金入力!$E$4:$E$580,入金入力!$B$4:$B$580,A11,入金入力!$A$4:$A$580,"レジデンス")+SUMIFS(入金予測!$E$4:$E$603,入金予測!$A$4:$A$603,A11,入金予測!$B$4:$B$603,"レジデンス") -> 0 | C11: =SUMIFS(未払予定一覧!$O$4:$O$830,未払予定一覧!$N$4:$N$830,A11,未払予定一覧!$A$4:$A$830,"レジデンス",未払予定一覧!$B$4:$B$830,"未払繰越")+SUMIFS(未払予定一覧!$O$4:$O$830,未払予定一覧!$N$4:$N$830,A11,未払予定一覧!$A$4:$A$830,"レジデンス",未払予定一覧!$B$4:$B$830,"月次予定") -> 0 | D11: =B11-C11-F11 -> 0 | E11: =E10+D11 -> -863406 | F11: =SUMIFS(未払予定一覧!$O$4:$O$830,未払予定一覧!$N$4:$N$830,A11,未払予定一覧!$A$4:$A$830,"レジデンス",未払予定一覧!$B$4:$B$830,"カード枠回復") -> 0 | G11: =G10+D11+F11 -> -863406
