Workbook

Sheet トップ
A1: 全社統合 資金管理ファイル
A3: シート構成
A4: マスター_物件 | C4: 物件→会社マッピング表
A5: マスター_勘定科目 | C5: 勘定科目→資金繰り項目マッピング表
A6: 入金入力_{社名} | C6: 会社別の入金入力（4社分）
A7: 未払一覧_{社名} | C7: 会社別の支出予定／請求書ファイルリンク（4社分）
A8: カード枠回復_{社名} | C8: 会社別のカード枠回復入力（4社分）
A9: 5月_{社名} 〜 8月_{社名} | C9: 会社別×月別の日次キャッシュフロー（16シート）
A10: 全社月次サマリー | C10: 全社・月次集計
A11: 資金繰り表_* | C11: 資金繰り表（マッピング経由でSUMIFS自動連動）

Sheet 全社合算サマリー
A1: 全社合算サマリー（6社合計）
A2: 6社（レジデンス／リゾート／モーテル／ザック／ワールド・レイ／ココ・ユニバース）の月別キャッシュフロー集計
A4: ■ 月別合算（6社合計）
A5: 月 | B5: 入金（円） | C5: 支出（円） | D5: 当月差引（円） | E5: 月末累計差引（円） | F5: カード枠回復額（円） | G5: 月末使用可能額（円）
A6: 5月 | B6: ='5月_レジデンス'!B37+'5月_リゾート'!B37+'5月_モーテル'!B37+'5月_ザック'!B37+'5月_ワールド・レイ'!B37+'5月_ココ・ユニバース'!B37 -> 21100000 | C6: ='5月_レジデンス'!C37+'5月_リゾート'!C37+'5月_モーテル'!C37+'5月_ザック'!C37+'5月_ワールド・レイ'!C37+'5月_ココ・ユニバース'!C37 -> 10478391 | D6: ='5月_レジデンス'!D37+'5月_リゾート'!D37+'5月_モーテル'!D37+'5月_ザック'!D37+'5月_ワールド・レイ'!D37+'5月_ココ・ユニバース'!D37 -> 5351609 | E6: ='5月_レジデンス'!E37+'5月_リゾート'!E37+'5月_モーテル'!E37+'5月_ザック'!E37+'5月_ワールド・レイ'!E37+'5月_ココ・ユニバース'!E37 -> 5351609 | F6: ='5月_レジデンス'!F37+'5月_リゾート'!F37+'5月_モーテル'!F37+'5月_ザック'!F37+'5月_ワールド・レイ'!F37+'5月_ココ・ユニバース'!F37 -> 5270000 | G6: ='5月_レジデンス'!G37+'5月_リゾート'!G37+'5月_モーテル'!G37+'5月_ザック'!G37+'5月_ワールド・レイ'!G37+'5月_ココ・ユニバース'!G37 -> 10621609
A7: 6月 | B7: ='6月_レジデンス'!B35+'6月_リゾート'!B35+'6月_モーテル'!B35+'6月_ザック'!B35+'6月_ワールド・レイ'!B35+'6月_ココ・ユニバース'!B35 -> 0 | C7: ='6月_レジデンス'!C35+'6月_リゾート'!C35+'6月_モーテル'!C35+'6月_ザック'!C35+'6月_ワールド・レイ'!C35+'6月_ココ・ユニバース'!C35 -> 0 | D7: ='6月_レジデンス'!D35+'6月_リゾート'!D35+'6月_モーテル'!D35+'6月_ザック'!D35+'6月_ワールド・レイ'!D35+'6月_ココ・ユニバース'!D35 -> 0 | E7: ='6月_レジデンス'!E35+'6月_リゾート'!E35+'6月_モーテル'!E35+'6月_ザック'!E35+'6月_ワールド・レイ'!E35+'6月_ココ・ユニバース'!E35 -> 5351609 | F7: ='6月_レジデンス'!F35+'6月_リゾート'!F35+'6月_モーテル'!F35+'6月_ザック'!F35+'6月_ワールド・レイ'!F35+'6月_ココ・ユニバース'!F35 -> 0 | G7: ='6月_レジデンス'!G35+'6月_リゾート'!G35+'6月_モーテル'!G35+'6月_ザック'!G35+'6月_ワールド・レイ'!G35+'6月_ココ・ユニバース'!G35 -> 10621609
A8: 7月 | B8: ='7月_レジデンス'!B36+'7月_リゾート'!B36+'7月_モーテル'!B36+'7月_ザック'!B36+'7月_ワールド・レイ'!B36+'7月_ココ・ユニバース'!B36 -> 0 | C8: ='7月_レジデンス'!C36+'7月_リゾート'!C36+'7月_モーテル'!C36+'7月_ザック'!C36+'7月_ワールド・レイ'!C36+'7月_ココ・ユニバース'!C36 -> 0 | D8: ='7月_レジデンス'!D36+'7月_リゾート'!D36+'7月_モーテル'!D36+'7月_ザック'!D36+'7月_ワールド・レイ'!D36+'7月_ココ・ユニバース'!D36 -> 0 | E8: ='7月_レジデンス'!E36+'7月_リゾート'!E36+'7月_モーテル'!E36+'7月_ザック'!E36+'7月_ワールド・レイ'!E36+'7月_ココ・ユニバース'!E36 -> 5351609 | F8: ='7月_レジデンス'!F36+'7月_リゾート'!F36+'7月_モーテル'!F36+'7月_ザック'!F36+'7月_ワールド・レイ'!F36+'7月_ココ・ユニバース'!F36 -> 0 | G8: ='7月_レジデンス'!G36+'7月_リゾート'!G36+'7月_モーテル'!G36+'7月_ザック'!G36+'7月_ワールド・レイ'!G36+'7月_ココ・ユニバース'!G36 -> 10621609
A9: 8月 | B9: ='8月_レジデンス'!B36+'8月_リゾート'!B36+'8月_モーテル'!B36+'8月_ザック'!B36+'8月_ワールド・レイ'!B36+'8月_ココ・ユニバース'!B36 -> 0 | C9: ='8月_レジデンス'!C36+'8月_リゾート'!C36+'8月_モーテル'!C36+'8月_ザック'!C36+'8月_ワールド・レイ'!C36+'8月_ココ・ユニバース'!C36 -> 0 | D9: ='8月_レジデンス'!D36+'8月_リゾート'!D36+'8月_モーテル'!D36+'8月_ザック'!D36+'8月_ワールド・レイ'!D36+'8月_ココ・ユニバース'!D36 -> 0 | E9: ='8月_レジデンス'!E36+'8月_リゾート'!E36+'8月_モーテル'!E36+'8月_ザック'!E36+'8月_ワールド・レイ'!E36+'8月_ココ・ユニバース'!E36 -> 5351609 | F9: ='8月_レジデンス'!F36+'8月_リゾート'!F36+'8月_モーテル'!F36+'8月_ザック'!F36+'8月_ワールド・レイ'!F36+'8月_ココ・ユニバース'!F36 -> 0 | G9: ='8月_レジデンス'!G36+'8月_リゾート'!G36+'8月_モーテル'!G36+'8月_ザック'!G36+'8月_ワールド・レイ'!G36+'8月_ココ・ユニバース'!G36 -> 10621609
A10: 4ヶ月合計 | B10: =SUM(B6:B9) -> 21100000 | C10: =SUM(C6:C9) -> 10478391 | D10: =SUM(D6:D9) -> 5351609 | E10: =E9 -> 5351609 | F10: =SUM(F6:F9) -> 5270000 | G10: =G9 -> 10621609
A12: ■ 会社別 4ヶ月合計
A13: 会社 | B13: 入金（円） | C13: 支出（円） | D13: 4ヶ月差引（円） | E13: 8月末累計差引（円） | F13: カード枠回復額（円） | G13: 8月末使用可能額（円）
A14: レジデンス | B14: ='5月_レジデンス'!B37+'6月_レジデンス'!B35+'7月_レジデンス'!B36+'8月_レジデンス'!B36 -> 0 | C14: ='5月_レジデンス'!C37+'6月_レジデンス'!C35+'7月_レジデンス'!C36+'8月_レジデンス'!C36 -> 0 | D14: ='5月_レジデンス'!D37+'6月_レジデンス'!D35+'7月_レジデンス'!D36+'8月_レジデンス'!D36 -> 0 | E14: ='8月_レジデンス'!E36 -> 0 | F14: ='5月_レジデンス'!F37+'6月_レジデンス'!F35+'7月_レジデンス'!F36+'8月_レジデンス'!F36 -> 0 | G14: ='8月_レジデンス'!G36 -> 0
A15: リゾート | B15: ='5月_リゾート'!B37+'6月_リゾート'!B35+'7月_リゾート'!B36+'8月_リゾート'!B36 -> 21100000 | C15: ='5月_リゾート'!C37+'6月_リゾート'!C35+'7月_リゾート'!C36+'8月_リゾート'!C36 -> 10478391 | D15: ='5月_リゾート'!D37+'6月_リゾート'!D35+'7月_リゾート'!D36+'8月_リゾート'!D36 -> 5351609 | E15: ='8月_リゾート'!E36 -> 5351609 | F15: ='5月_リゾート'!F37+'6月_リゾート'!F35+'7月_リゾート'!F36+'8月_リゾート'!F36 -> 5270000 | G15: ='8月_リゾート'!G36 -> 10621609
A16: モーテル | B16: ='5月_モーテル'!B37+'6月_モーテル'!B35+'7月_モーテル'!B36+'8月_モーテル'!B36 -> 0 | C16: ='5月_モーテル'!C37+'6月_モーテル'!C35+'7月_モーテル'!C36+'8月_モーテル'!C36 -> 0 | D16: ='5月_モーテル'!D37+'6月_モーテル'!D35+'7月_モーテル'!D36+'8月_モーテル'!D36 -> 0 | E16: ='8月_モーテル'!E36 -> 0 | F16: ='5月_モーテル'!F37+'6月_モーテル'!F35+'7月_モーテル'!F36+'8月_モーテル'!F36 -> 0 | G16: ='8月_モーテル'!G36 -> 0
A17: ザック | B17: ='5月_ザック'!B37+'6月_ザック'!B35+'7月_ザック'!B36+'8月_ザック'!B36 -> 0 | C17: ='5月_ザック'!C37+'6月_ザック'!C35+'7月_ザック'!C36+'8月_ザック'!C36 -> 0 | D17: ='5月_ザック'!D37+'6月_ザック'!D35+'7月_ザック'!D36+'8月_ザック'!D36 -> 0 | E17: ='8月_ザック'!E36 -> 0 | F17: ='5月_ザック'!F37+'6月_ザック'!F35+'7月_ザック'!F36+'8月_ザック'!F36 -> 0 | G17: ='8月_ザック'!G36 -> 0
A18: ワールド・レイ | B18: ='5月_ワールド・レイ'!B37+'6月_ワールド・レイ'!B35+'7月_ワールド・レイ'!B36+'8月_ワールド・レイ'!B36 -> 0 | C18: ='5月_ワールド・レイ'!C37+'6月_ワールド・レイ'!C35+'7月_ワールド・レイ'!C36+'8月_ワールド・レイ'!C36 -> 0 | D18: ='5月_ワールド・レイ'!D37+'6月_ワールド・レイ'!D35+'7月_ワールド・レイ'!D36+'8月_ワールド・レイ'!D36 -> 0 | E18: ='8月_ワールド・レイ'!E36 -> 0 | F18: ='5月_ワールド・レイ'!F37+'6月_ワールド・レイ'!F35+'7月_ワールド・レイ'!F36+'8月_ワールド・レイ'!F36 -> 0 | G18: ='8月_ワールド・レイ'!G36 -> 0
A19: ココ・ユニバース | B19: ='5月_ココ・ユニバース'!B37+'6月_ココ・ユニバース'!B35+'7月_ココ・ユニバース'!B36+'8月_ココ・ユニバース'!B36 -> 0 | C19: ='5月_ココ・ユニバース'!C37+'6月_ココ・ユニバース'!C35+'7月_ココ・ユニバース'!C36+'8月_ココ・ユニバース'!C36 -> 0 | D19: ='5月_ココ・ユニバース'!D37+'6月_ココ・ユニバース'!D35+'7月_ココ・ユニバース'!D36+'8月_ココ・ユニバース'!D36 -> 0 | E19: ='8月_ココ・ユニバース'!E36 -> 0 | F19: ='5月_ココ・ユニバース'!F37+'6月_ココ・ユニバース'!F35+'7月_ココ・ユニバース'!F36+'8月_ココ・ユニバース'!F36 -> 0 | G19: ='8月_ココ・ユニバース'!G36 -> 0
A20: 合計 | B20: =SUM(B14:B19) -> 21100000 | C20: =SUM(C14:C19) -> 10478391 | D20: =SUM(D14:D19) -> 5351609 | E20: =SUM(E14:E19) -> 5351609 | F20: =SUM(F14:F19) -> 5270000 | G20: =SUM(G14:G19) -> 10621609

Sheet 全社月次サマリー
A1: 全社月次サマリー（6社×4ヶ月）
A3: 会社 | B3: 月 | C3: 入金（円） | D3: 支出（円） | E3: 当月差引（円） | F3: 月末累計差引（円） | G3: カード枠回復額（円） | H3: 月末使用可能額（円）
A4: レジデンス | B4: 5月 | C4: ='5月_レジデンス'!B37 -> 0 | D4: ='5月_レジデンス'!C37 -> 0 | E4: ='5月_レジデンス'!D37 -> 0 | F4: ='5月_レジデンス'!E37 -> 0 | G4: ='5月_レジデンス'!F37 -> 0 | H4: ='5月_レジデンス'!G37 -> 0
A5: レジデンス | B5: 6月 | C5: ='6月_レジデンス'!B35 -> 0 | D5: ='6月_レジデンス'!C35 -> 0 | E5: ='6月_レジデンス'!D35 -> 0 | F5: ='6月_レジデンス'!E35 -> 0 | G5: ='6月_レジデンス'!F35 -> 0 | H5: ='6月_レジデンス'!G35 -> 0
A6: レジデンス | B6: 7月 | C6: ='7月_レジデンス'!B36 -> 0 | D6: ='7月_レジデンス'!C36 -> 0 | E6: ='7月_レジデンス'!D36 -> 0 | F6: ='7月_レジデンス'!E36 -> 0 | G6: ='7月_レジデンス'!F36 -> 0 | H6: ='7月_レジデンス'!G36 -> 0
A7: レジデンス | B7: 8月 | C7: ='8月_レジデンス'!B36 -> 0 | D7: ='8月_レジデンス'!C36 -> 0 | E7: ='8月_レジデンス'!D36 -> 0 | F7: ='8月_レジデンス'!E36 -> 0 | G7: ='8月_レジデンス'!F36 -> 0 | H7: ='8月_レジデンス'!G36 -> 0
A8: レジデンス | B8: 4ヶ月合計 | C8: =SUM(C4:C7) -> 0 | D8: =SUM(D4:D7) -> 0 | E8: =SUM(E4:E7) -> 0 | F8: =F7 -> 0 | G8: =SUM(G4:G7) -> 0 | H8: =H7 -> 0
A10: リゾート | B10: 5月 | C10: ='5月_リゾート'!B37 -> 21100000 | D10: ='5月_リゾート'!C37 -> 10478391 | E10: ='5月_リゾート'!D37 -> 5351609 | F10: ='5月_リゾート'!E37 -> 5351609 | G10: ='5月_リゾート'!F37 -> 5270000 | H10: ='5月_リゾート'!G37 -> 10621609
A11: リゾート | B11: 6月 | C11: ='6月_リゾート'!B35 -> 0 | D11: ='6月_リゾート'!C35 -> 0 | E11: ='6月_リゾート'!D35 -> 0 | F11: ='6月_リゾート'!E35 -> 5351609 | G11: ='6月_リゾート'!F35 -> 0 | H11: ='6月_リゾート'!G35 -> 10621609
A12: リゾート | B12: 7月 | C12: ='7月_リゾート'!B36 -> 0 | D12: ='7月_リゾート'!C36 -> 0 | E12: ='7月_リゾート'!D36 -> 0 | F12: ='7月_リゾート'!E36 -> 5351609 | G12: ='7月_リゾート'!F36 -> 0 | H12: ='7月_リゾート'!G36 -> 10621609
A13: リゾート | B13: 8月 | C13: ='8月_リゾート'!B36 -> 0 | D13: ='8月_リゾート'!C36 -> 0 | E13: ='8月_リゾート'!D36 -> 0 | F13: ='8月_リゾート'!E36 -> 5351609 | G13: ='8月_リゾート'!F36 -> 0 | H13: ='8月_リゾート'!G36 -> 10621609
A14: リゾート | B14: 4ヶ月合計 | C14: =SUM(C10:C13) -> 21100000 | D14: =SUM(D10:D13) -> 10478391 | E14: =SUM(E10:E13) -> 5351609 | F14: =F13 -> 5351609 | G14: =SUM(G10:G13) -> 5270000 | H14: =H13 -> 10621609
A16: モーテル | B16: 5月 | C16: ='5月_モーテル'!B37 -> 0 | D16: ='5月_モーテル'!C37 -> 0 | E16: ='5月_モーテル'!D37 -> 0 | F16: ='5月_モーテル'!E37 -> 0 | G16: ='5月_モーテル'!F37 -> 0 | H16: ='5月_モーテル'!G37 -> 0
A17: モーテル | B17: 6月 | C17: ='6月_モーテル'!B35 -> 0 | D17: ='6月_モーテル'!C35 -> 0 | E17: ='6月_モーテル'!D35 -> 0 | F17: ='6月_モーテル'!E35 -> 0 | G17: ='6月_モーテル'!F35 -> 0 | H17: ='6月_モーテル'!G35 -> 0
A18: モーテル | B18: 7月 | C18: ='7月_モーテル'!B36 -> 0 | D18: ='7月_モーテル'!C36 -> 0 | E18: ='7月_モーテル'!D36 -> 0 | F18: ='7月_モーテル'!E36 -> 0 | G18: ='7月_モーテル'!F36 -> 0 | H18: ='7月_モーテル'!G36 -> 0
A19: モーテル | B19: 8月 | C19: ='8月_モーテル'!B36 -> 0 | D19: ='8月_モーテル'!C36 -> 0 | E19: ='8月_モーテル'!D36 -> 0 | F19: ='8月_モーテル'!E36 -> 0 | G19: ='8月_モーテル'!F36 -> 0 | H19: ='8月_モーテル'!G36 -> 0
A20: モーテル | B20: 4ヶ月合計 | C20: =SUM(C16:C19) -> 0 | D20: =SUM(D16:D19) -> 0 | E20: =SUM(E16:E19) -> 0 | F20: =F19 -> 0 | G20: =SUM(G16:G19) -> 0 | H20: =H19 -> 0
A22: ザック | B22: 5月 | C22: ='5月_ザック'!B37 -> 0 | D22: ='5月_ザック'!C37 -> 0 | E22: ='5月_ザック'!D37 -> 0 | F22: ='5月_ザック'!E37 -> 0 | G22: ='5月_ザック'!F37 -> 0 | H22: ='5月_ザック'!G37 -> 0
A23: ザック | B23: 6月 | C23: ='6月_ザック'!B35 -> 0 | D23: ='6月_ザック'!C35 -> 0 | E23: ='6月_ザック'!D35 -> 0 | F23: ='6月_ザック'!E35 -> 0 | G23: ='6月_ザック'!F35 -> 0 | H23: ='6月_ザック'!G35 -> 0
A24: ザック | B24: 7月 | C24: ='7月_ザック'!B36 -> 0 | D24: ='7月_ザック'!C36 -> 0 | E24: ='7月_ザック'!D36 -> 0 | F24: ='7月_ザック'!E36 -> 0 | G24: ='7月_ザック'!F36 -> 0 | H24: ='7月_ザック'!G36 -> 0
A25: ザック | B25: 8月 | C25: ='8月_ザック'!B36 -> 0 | D25: ='8月_ザック'!C36 -> 0 | E25: ='8月_ザック'!D36 -> 0 | F25: ='8月_ザック'!E36 -> 0 | G25: ='8月_ザック'!F36 -> 0 | H25: ='8月_ザック'!G36 -> 0
A26: ザック | B26: 4ヶ月合計 | C26: =SUM(C22:C25) -> 0 | D26: =SUM(D22:D25) -> 0 | E26: =SUM(E22:E25) -> 0 | F26: =F25 -> 0 | G26: =SUM(G22:G25) -> 0 | H26: =H25 -> 0
A28: ワールド・レイ | B28: 5月 | C28: ='5月_ワールド・レイ'!B37 -> 0 | D28: ='5月_ワールド・レイ'!C37 -> 0 | E28: ='5月_ワールド・レイ'!D37 -> 0 | F28: ='5月_ワールド・レイ'!E37 -> 0 | G28: ='5月_ワールド・レイ'!F37 -> 0 | H28: ='5月_ワールド・レイ'!G37 -> 0
A29: ワールド・レイ | B29: 6月 | C29: ='6月_ワールド・レイ'!B35 -> 0 | D29: ='6月_ワールド・レイ'!C35 -> 0 | E29: ='6月_ワールド・レイ'!D35 -> 0 | F29: ='6月_ワールド・レイ'!E35 -> 0 | G29: ='6月_ワールド・レイ'!F35 -> 0 | H29: ='6月_ワールド・レイ'!G35 -> 0
A30: ワールド・レイ | B30: 7月 | C30: ='7月_ワールド・レイ'!B36 -> 0 | D30: ='7月_ワールド・レイ'!C36 -> 0 | E30: ='7月_ワールド・レイ'!D36 -> 0 | F30: ='7月_ワールド・レイ'!E36 -> 0 | G30: ='7月_ワールド・レイ'!F36 -> 0 | H30: ='7月_ワールド・レイ'!G36 -> 0
A31: ワールド・レイ | B31: 8月 | C31: ='8月_ワールド・レイ'!B36 -> 0 | D31: ='8月_ワールド・レイ'!C36 -> 0 | E31: ='8月_ワールド・レイ'!D36 -> 0 | F31: ='8月_ワールド・レイ'!E36 -> 0 | G31: ='8月_ワールド・レイ'!F36 -> 0 | H31: ='8月_ワールド・レイ'!G36 -> 0
A32: ワールド・レイ | B32: 4ヶ月合計 | C32: =SUM(C28:C31) -> 0 | D32: =SUM(D28:D31) -> 0 | E32: =SUM(E28:E31) -> 0 | F32: =F31 -> 0 | G32: =SUM(G28:G31) -> 0 | H32: =H31 -> 0
A34: ココ・ユニバース | B34: 5月 | C34: ='5月_ココ・ユニバース'!B37 -> 0 | D34: ='5月_ココ・ユニバース'!C37 -> 0 | E34: ='5月_ココ・ユニバース'!D37 -> 0 | F34: ='5月_ココ・ユニバース'!E37 -> 0 | G34: ='5月_ココ・ユニバース'!F37 -> 0 | H34: ='5月_ココ・ユニバース'!G37 -> 0
A35: ココ・ユニバース | B35: 6月 | C35: ='6月_ココ・ユニバース'!B35 -> 0 | D35: ='6月_ココ・ユニバース'!C35 -> 0 | E35: ='6月_ココ・ユニバース'!D35 -> 0 | F35: ='6月_ココ・ユニバース'!E35 -> 0 | G35: ='6月_ココ・ユニバース'!F35 -> 0 | H35: ='6月_ココ・ユニバース'!G35 -> 0
A36: ココ・ユニバース | B36: 7月 | C36: ='7月_ココ・ユニバース'!B36 -> 0 | D36: ='7月_ココ・ユニバース'!C36 -> 0 | E36: ='7月_ココ・ユニバース'!D36 -> 0 | F36: ='7月_ココ・ユニバース'!E36 -> 0 | G36: ='7月_ココ・ユニバース'!F36 -> 0 | H36: ='7月_ココ・ユニバース'!G36 -> 0
A37: ココ・ユニバース | B37: 8月 | C37: ='8月_ココ・ユニバース'!B36 -> 0 | D37: ='8月_ココ・ユニバース'!C36 -> 0 | E37: ='8月_ココ・ユニバース'!D36 -> 0 | F37: ='8月_ココ・ユニバース'!E36 -> 0 | G37: ='8月_ココ・ユニバース'!F36 -> 0 | H37: ='8月_ココ・ユニバース'!G36 -> 0
A38: ココ・ユニバース | B38: 4ヶ月合計 | C38: =SUM(C34:C37) -> 0 | D38: =SUM(D34:D37) -> 0 | E38: =SUM(E34:E37) -> 0 | F38: =F37 -> 0 | G38: =SUM(G34:G37) -> 0 | H38: =H37 -> 0
A40: 全社合計 | C40: =SUM(C4:C7)+SUM(C10:C13)+SUM(C16:C19)+SUM(C22:C25)+SUM(C28:C31)+SUM(C34:C37) -> 21100000 | D40: =SUM(D4:D7)+SUM(D10:D13)+SUM(D16:D19)+SUM(D22:D25)+SUM(D28:D31)+SUM(D34:D37) -> 10478391 | E40: =SUM(E4:E7)+SUM(E10:E13)+SUM(E16:E19)+SUM(E22:E25)+SUM(E28:E31)+SUM(E34:E37) -> 5351609 | G40: =SUM(G4:G7)+SUM(G10:G13)+SUM(G16:G19)+SUM(G22:G25)+SUM(G28:G31)+SUM(G34:G37) -> 5270000

Sheet マスター_物件
A1: 物件→会社 マッピング表（B列の会社名を変更すると全シートに反映）
A3: 物件名 | B3: 所属会社 | C3: 備考
A4: リゾート | B4: リゾート
A5: ほうらい | B5: リゾート
A6: フォレスト | B6: リゾート
A7: ｸﾞﾘｰﾝｼｬﾜｰ | B7: リゾート
A8: 周防大島 | B8: リゾート
A9: モーテル | B9: モーテル
A10: レジデンス | B10: レジデンス
A11: ココユニバース | B11: ザック

Sheet マスター_勘定科目
A1: 勘定科目→資金繰り項目 マッピング表
A3: 勘定科目 | B3: 資金繰り項目 | C3: 備考
A4: 水道光熱費 | B4: 買掛金支払
A5: 設備費 | B5: 買掛金支払
A6: 通信費 | B6: 買掛金支払
A7: 衛生管理費 | B7: 買掛金支払
A8: 食材費 | B8: 買掛金支払
A9: システム利用料 | B9: 買掛金支払
A10: 業務委託料 | B10: 買掛金支払
A11: 備品消耗品費 | B11: 買掛金支払
A12: ゴミ収集費 | B12: 買掛金支払
A13: 租税公課 | B13: 税金・社会保険料
A14: 保険 | B14: その他経費
A15: 手数料 | B15: その他経費
... A22: 社員給与 | B22: 従業員給与

Sheet 入金入力_レジデンス
A1: 入金入力 — レジデンス（黄色セルに入力 → 月次サマリーへ自動反映）
A2: 区分は資金繰り表の収入項目と連動します（現金売上／売掛金回収／手形入金／その他収入／借入金／設備売却）
A3: 日付 | B3: 項目 | C3: 区分 | D3: 金額（円） | E3: 備考 | F3: 入金確認
A105: 合計 | D105: =SUM(D4:D103) -> 0

Sheet 未払一覧_レジデンス
A1: 支払予定一覧 — レジデンス（黄色セルに入力／請求書ファイルパスをO列に貼付）
A2: 優先度: | B2: 高（3ヶ月以上滞留） | C2: 中（2ヶ月滞留） | D2: 低（前月のみ） | E2: 月次（経常支出） | G2: ※ 支払予定日に日付を入れると月次サマリーへ自動反映／勘定科目は資金繰り表へ自動マッピング／O列に請求書PDFのフルパスを貼ると右下にリンクが出ます
A3: 種別 | B3: 物件 | C3: 概要 | D3: 勘定科目 | E3: 期日 | F3: 請求先 | G3: 当月分 | H3: 前月繰越 | I3: 前々月繰越 | J3: 前々々月以前 | K3: 累積未払合計 | L3: 優先度 | M3: 支払予定日 | N3: 支払予定額 | O3: 支払状況 | P3: 請求書ファイル
A4: 未払繰越 | B4: レジデンス | C4: トラストユアサービス（2か月分） | D4: 通信費 | E4: 46142 | F4: レジデンス | G4: 114589 | H4: 114589 | I4: 0 | J4: 0 | K4: 114589 | L4: 低 | M4: 済 | N4: 114589
A5: 未払繰越 | B5: レジデンス | C5: あしたば（4ヶ月分） | D5: 業務委託料 | E5: 46142 | F5: レジデンス | G5: 33000 | H5: 33000 | I5: 33000 | J5: 33000 | K5: 99000 | L5: 高 | N5: 99000
A104: 合計 | G104: =SUM(G4:G103) -> 147589 | H104: =SUM(H4:H103) -> 147589 | I104: =SUM(I4:I103) -> 33000 | J104: =SUM(J4:J103) -> 33000 | K104: =SUM(K4:K103) -> 213589 | L104: =COUNTA(L4:L103)&"件" -> 2件 | M104: =COUNTA(M4:M103)&"件予定" -> 1件予定 | N104: =SUM(N4:N103) -> 213589
A106: 支払済合計 | M106: =COUNTIF(O4:O103,"済")&"件" -> 0件 | N106: =SUMIF(O4:O103,"済",N4:N103) -> 0
A107: 未払残高（予定） | M107: =COUNTIFS(N4:N103,">0",O4:O103,"")&"件" -> 2件 | N107: =SUMIFS(N4:N103,O4:O103,"") -> 213589
A108: 取消 | M108: =COUNTIF(O4:O103,"取消")&"件" -> 0件 | N108: =SUMIF(O4:O103,"取消",N4:N103) -> 0

Sheet カード枠回復_レジデンス
A1: カード枠回復入力 — レジデンス
A2: ※ 支払日に金額が反映 → カード枠回復額として月次サマリーへ計上（支出には含めません）
A3: 支払日 | B3: カード会社 / 項目 | C3: 回復額（円） | D3: 区分 | E3: 備考
A55: 合計 | C55: =SUM(C4:C53) -> 0

Sheet 入金入力_リゾート
A1: 入金入力 — リゾート（黄色セルに入力 → 月次サマリーへ自動反映）
A2: 区分は資金繰り表の収入項目と連動します（現金売上／売掛金回収／手形入金／その他収入／借入金／設備売却）
A3: 日付 | B3: 項目 | C3: 区分 | D3: 金額（円） | E3: 備考 | F3: 入金確認
A4: 46149 | B4: Booking | C4: 現金売上 | D4: 3000000 | E4: 予測
A5: 46149 | B5: PayPay | C5: 現金売上 | D5: 150000 | E5: 予測
A6: 46149 | B6: ホテル売上 | C6: 現金売上 | D6: 2200000 | E6: 予測
A7: 46153 | B7: 楽天 | C7: 現金売上 | D7: 3500000 | E7: 予測
A8: 46157 | B8: JCB | C8: 現金売上 | D8: 200000 | E8: 予測
A9: 46157 | B9: GMO | C9: 現金売上 | D9: 1200000 | E9: 予測
A10: 46157 | B10: JMS | C10: 現金売上 | D10: 400000 | E10: 予測
A11: 46157 | B11: スマレジ | C11: 現金売上 | D11: 1200000 | E11: 予測
A12: 46162 | B12: 売上 | C12: 現金売上 | D12: 1000000 | E12: 予測
A13: 46167 | B13: 楽天 | C13: 現金売上 | D13: 1000000 | E13: 予測
A14: 46167 | B14: じゃらん | C14: 現金売上 | D14: 800000 | E14: 予測
A15: 46171 | B15: カード | C15: 現金売上 | D15: 1500000 | E15: 予測
... A19: 46171 | B19: 売上 | C19: 現金売上 | D19: 1500000 | E19: 予測
A105: 合計 | D105: =SUM(D4:D103) -> 21100000

Sheet 未払一覧_リゾート
A1: 支払予定一覧 — リゾート（黄色セルに入力／請求書ファイルパスをO列に貼付）
A2: 優先度: | B2: 高（3ヶ月以上滞留） | C2: 中（2ヶ月滞留） | D2: 低（前月のみ） | E2: 月次（経常支出） | G2: ※ 支払予定日に日付を入れると月次サマリーへ自動反映／勘定科目は資金繰り表へ自動マッピング／O列に請求書PDFのフルパスを貼ると右下にリンクが出ます
A3: 種別 | B3: 物件 | C3: 概要 | D3: 勘定科目 | E3: 期日 | F3: 請求先 | G3: 当月分 | H3: 前月繰越 | I3: 前々月繰越 | J3: 前々々月以前 | K3: 累積未払合計 | L3: 優先度 | M3: 支払予定日 | N3: 支払予定額 | O3: 支払状況 | P3: 請求書ファイル
A4: 未払繰越 | B4: リゾート | C4: 第一興商（3か月分） | D4: 通信費 | E4: 46120 | F4: たけはら | G4: 0 | H4: 22000 | I4: 22000 | J4: 22000 | K4: 66000 | L4: 高 | N4: 66000
A5: 未払繰越 | B5: リゾート | C5: キャノン※再引落あり | D5: 備品消耗品費 | E5: 46135 | F5: ビュー | G5: 7893 | H5: 15809 | I5: 0 | J5: 0 | K5: 15809 | L5: 低 | N5: 15809
A6: 未払繰越 | B6: リゾート | C6: 安芸クリーナー（4か月分） | D6: ゴミ収集費 | E6: 46142 | F6: ビュー | G6: 27500 | H6: 27500 | I6: 27500 | J6: 27500 | K6: 82500 | L6: 高 | N6: 82500
A7: 未払繰越 | B7: リゾート | C7: アシード（4か月分） | D7: リース料 | E7: 46142 | F7: デルーネ | G7: 17600 | H7: 17600 | I7: 17600 | J7: 17600 | K7: 52800 | L7: 高 | N7: 52800
A8: 未払繰越 | B8: リゾート | C8: IPPO（4か月分） | D8: 業務委託費 | E8: 46142 | F8: デルーネ | G8: 140800 | H8: 43200 | I8: 95600 | J8: 110800 | K8: 249600 | L8: 高 | N8: 249600
A9: 未払繰越 | B9: リゾート | C9: クリンプロ（3ヶ月分） | D9: 衛生管理費 | E9: 46142 | F9: 温井 | G9: 173800 | H9: 194040 | I9: 121000 | J9: 0 | K9: 315040 | L9: 中 | N9: 315040
A10: 未払繰越 | B10: リゾート | C10: 富田肥料（3ヶ月分） | D10: 備品消耗品費 | E10: 46142 | F10: 温井 | G10: 0 | H10: 19051 | I10: 76449 | J10: 142269 | K10: 237769 | L10: 高 | N10: 237769
A11: 未払繰越 | B11: リゾート | C11: 百姓屋 | D11: 食材費 | E11: 46142 | F11: 温井 | G11: 0 | H11: 16500 | I11: 0 | J11: 0 | K11: 16500 | L11: 低 | N11: 16500
A12: 未払繰越 | B12: リゾート | C12: アペックス（2か月分） | D12: 備品消耗品費 | E12: 46142 | F12: 温井 | G12: 56055 | H12: 36440 | I12: 0 | J12: 0 | K12: 36440 | L12: 低 | N12: 36440
A13: 未払繰越 | B13: リゾート | C13: 西部環境（4か月分） | D13: 衛生管理費 | E13: 46142 | F13: 温井 | G13: 30800 | H13: 30800 | I13: 30800 | J13: 30800 | K13: 92400 | L13: 高 | N13: 92400
A14: 未払繰越 | B14: リゾート | C14: 木下商会（2か月分） | D14: 水道光熱費 | E14: 46142 | F14: いこいの村 | G14: 27583 | H14: 21972 | I14: 0 | J14: 0 | K14: 21972 | L14: 低 | N14: 21972
A15: 未払繰越 | B15: リゾート | C15: 青原木材（2か月分） | D15: 備品消耗品費 | E15: 46142 | F15: いこいの村 | G15: 372405 | H15: 114015 | I15: 0 | J15: 0 | K15: 114015 | L15: 低 | N15: 114015
... A24: 未払繰越 | B24: リゾート | C24: 竹原クリーナー（4か月分） | D24: 衛生管理費 | E24: 46142 | F24: たけはら | G24: 22000 | H24: 22000 | I24: 22000 | J24: 22000 | K24: 66000 | L24: 高 | N24: 66000
A25: 未払繰越 | B25: リゾート | C25: トラストユアサービス（2カ月分） | D25: 通信費 | E25: 46142 | G25: 56250 | H25: 56250 | I25: 0 | J25: 0 | K25: 56250 | L25: 低 | N25: 56250
A26: 未払繰越 | B26: リゾート | C26: アイパス（4か月分） | D26: システム利用料 | E26: 46142 | G26: 193050 | H26: 303050 | I26: 152900 | J26: 152900 | K26: 608850 | L26: 高 | N26: 608850
A27: 未払繰越 | B27: リゾート | C27: あしたば（2か月分） | D27: 業務委託費 | E27: 46142 | G27: 132000 | H27: 132000 | I27: 0 | J27: 0 | K27: 132000 | L27: 低 | N27: 132000
A28: 未払繰越 | B28: リゾート | C28: 入江さん(2カ月分） | D28: 業務委託費 | E28: 46142 | G28: 100000 | H28: 100000 | I28: 0 | J28: 0 | K28: 100000 | L28: 低 | N28: 100000
A29: 未払繰越 | B29: リゾート | C29: アペックス（2か月分） | D29: 備品消耗品費 | E29: 46142 | F29: たけはら | G29: 35340 | H29: 13200 | I29: 0 | J29: 0 | K29: 13200 | L29: 低 | N29: 13200
A30: 未払繰越 | B30: リゾート | C30: アズブレインオフィス（5か月分） | D30: 食材費 | E30: 46142 | F30: いこいの村 | G30: 11650 | H30: 34341 | I30: 21151 | J30: 24854 | K30: 80346 | L30: 高 | N30: 80346
A31: 未払繰越 | B31: リゾート | C31: キンヤ（4か月分） | D31: 食材費 | E31: 46142 | F31: いこいの村 | G31: 19302 | H31: 33035 | I31: 8775 | J31: 24970 | K31: 66780 | L31: 高 | N31: 66780
A32: 未払繰越 | B32: リゾート | C32: ライフサービス(4か月分） | D32: 衛生管理費 | E32: 46142 | F32: 温井 | G32: 255233 | H32: 409035 | I32: 387063 | J32: 108644 | K32: 904742 | L32: 高 | N32: 904742
A33: 未払繰越 | B33: リゾート | C33: 川本酒造場（4か月分） | D33: 備品消耗品費 | E33: 46142 | F33: いこいの村 | G33: 7670 | H33: 0 | I33: 55764 | J33: 188088 | K33: 243852 | L33: 高 | N33: 243852
A34: 未払繰越 | B34: リゾート | C34: クミアイ燃料（3ヶ月分) | D34: 燃料費 | E34: 46142 | F34: いこいの村 | G34: 35596 | H34: 44528 | I34: 44088 | J34: 0 | K34: 88616 | L34: 中 | N34: 88616
A35: 未払繰越 | B35: リゾート | C35: E-MAN（4か月分） | D35: 業務委託費 | E35: 46157 | G35: 0 | H35: 262500 | I35: 262500 | J35: 262500 | K35: 787500 | L35: 高 | N35: 787500
A36: 未払繰越 | B36: リゾート | C36: 広島市県民税（1月2月不能分） | D36: 租税公課 | G36: 56200 | H36: 56200 | I36: 0 | J36: 0 | K36: 56200 | L36: 低 | N36: 56200
A37: 未払繰越 | B37: フォレスト | C37: 東芝エレベータ（4か月分） | D37: 設備費 | E37: 46142 | F37: フォレストヒルズ | G37: 19140 | H37: 19140 | I37: 19140 | J37: 19140 | K37: 57420 | L37: 高 | N37: 57420
A38: 未払繰越 | B38: フォレスト | C38: 不二ビルサービス(4か月分） | D38: 設備費 | E38: 46142 | F38: フォレストヒルズ | G38: 77000 | H38: 77000 | I38: 77000 | J38: 77000 | K38: 231000 | L38: 高 | N38: 231000
A39: 未払繰越 | B39: フォレスト | C39: チュウブ（4か月分） | D39: 業務委託料 | E39: 46142 | F39: フォレストヒルズ | G39: 1155000 | H39: 1155000 | I39: 1155000 | J39: 1155000 | K39: 3465000 | L39: 高 | N39: 3465000
A40: 未払繰越 | B40: フォレスト | C40: 三原総和（4か月分） | D40: ごみ収集 | E40: 46142 | F40: フォレストヒルズ | G40: 52800 | H40: 52800 | I40: 52800 | J40: 52800 | K40: 158400 | L40: 高 | N40: 158400
A41: 未払繰越 | B41: 周防大島 | C41: 柳井地域水道企業団 | D41: 水道光熱費 | E41: 46132 | F41: 周防大島 | G41: 37272 | H41: 31964 | I41: 0 | J41: 0 | K41: 31964 | L41: 低 | N41: 31964
B42: リゾート | C42: ファクタリング返済 | G42: 0 | H42: 0 | I42: 0 | J42: 0 | K42: 0 | L42: 低 | M42: 46153 | N42: 0
A43: 月次予定 | C43: ライフサービス | G43: 200000 | H43: 0 | I43: 0 | J43: 0 | K43: 200000 | L43: 月次 | M43: 46142 | N43: 200000
A44: 月次予定 | C44: 広島組合燃料 | G44: 44088 | H44: 0 | I44: 0 | J44: 0 | K44: 44088 | L44: 月次 | M44: 46149 | N44: 44088
A45: 月次予定 | C45: チュウブ | G45: 660000 | H45: 0 | I45: 0 | J45: 0 | K45: 660000 | L45: 月次 | M45: 46149 | N45: 660000
A46: 月次予定 | C46: エムケイ興産 | G46: 260000 | H46: 0 | I46: 0 | J46: 0 | K46: 260000 | L46: 月次 | M46: 46149 | N46: 260000
A47: 月次予定 | C47: 第一興商 | G47: 100000 | H47: 0 | I47: 0 | J47: 0 | K47: 100000 | L47: 月次 | M47: 46149 | N47: 100000
A48: 月次予定 | C48: アズブレイン | G48: 80000 | H48: 0 | I48: 0 | J48: 0 | K48: 80000 | L48: 月次 | M48: 46149 | N48: 80000
...

Sheet カード枠回復_リゾート
A1: カード枠回復入力 — リゾート
A2: ※ 支払日に金額が反映 → カード枠回復額として月次サマリーへ計上（支出には含めません）
A3: 支払日 | B3: カード会社 / 項目 | C3: 回復額（円） | D3: 区分 | E3: 備考
A4: 46149 | B4: セゾンYUSO | C4: 2600000
A5: 46149 | B5: セゾンパルコ | C5: 1700000
A6: 46153 | B6: JCB | C6: 970000
A55: 合計 | C55: =SUM(C4:C53) -> 5270000

Sheet 入金入力_モーテル
A1: 入金入力 — モーテル（黄色セルに入力 → 月次サマリーへ自動反映）
A2: 区分は資金繰り表の収入項目と連動します（現金売上／売掛金回収／手形入金／その他収入／借入金／設備売却）
A3: 日付 | B3: 項目 | C3: 区分 | D3: 金額（円） | E3: 備考 | F3: 入金確認
A105: 合計 | D105: =SUM(D4:D103) -> 0

Sheet 未払一覧_モーテル
A1: 支払予定一覧 — モーテル（黄色セルに入力／請求書ファイルパスをO列に貼付）
A2: 優先度: | B2: 高（3ヶ月以上滞留） | C2: 中（2ヶ月滞留） | D2: 低（前月のみ） | E2: 月次（経常支出） | G2: ※ 支払予定日に日付を入れると月次サマリーへ自動反映／勘定科目は資金繰り表へ自動マッピング／O列に請求書PDFのフルパスを貼ると右下にリンクが出ます
A3: 種別 | B3: 物件 | C3: 概要 | D3: 勘定科目 | E3: 期日 | F3: 請求先 | G3: 当月分 | H3: 前月繰越 | I3: 前々月繰越 | J3: 前々々月以前 | K3: 累積未払合計 | L3: 優先度 | M3: 支払予定日 | N3: 支払予定額 | O3: 支払状況 | P3: 請求書ファイル
A4: 未払繰越 | B4: モーテル | C4: T.OLABO(2カ月分） | D4: 食材費 | E4: 46127 | F4: 弥山 | G4: 85142 | H4: 121954 | I4: 0 | J4: 0 | K4: 121954 | L4: 低 | N4: 121954
A5: 未払繰越 | B5: モーテル | C5: 富士企業（3ヶ月分） | D5: 衛生管理費 | E5: 46142 | F5: 弥山 | G5: 44000 | H5: 44000 | I5: 44000 | J5: 0 | K5: 88000 | L5: 中 | N5: 88000
A6: 未払繰越 | B6: モーテル | C6: トラストユアサービス（2カ月分） | D6: 通信費 | E6: 46142 | F6: 弥山 | G6: 5000 | H6: 5000 | I6: 0 | J6: 0 | K6: 5000 | L6: 低 | N6: 5000
A7: 未払繰越 | B7: モーテル | C7: あしたば（2ヶ月分） | D7: 業務委託料 | E7: 46142 | F7: 弥山 | G7: 11000 | H7: 11000 | I7: 11000 | J7: 11000 | K7: 33000 | L7: 高 | N7: 33000
A8: 未払繰越 | B8: モーテル | C8: ふくや | D8: 食材費 | E8: 46142 | F8: 弥山 | G8: 12741 | H8: 12910 | I8: 0 | J8: 0 | K8: 12910 | L8: 低 | N8: 12910
A104: 合計 | G104: =SUM(G4:G103) -> 157883 | H104: =SUM(H4:H103) -> 194864 | I104: =SUM(I4:I103) -> 55000 | J104: =SUM(J4:J103) -> 11000 | K104: =SUM(K4:K103) -> 260864 | L104: =COUNTA(L4:L103)&"件" -> 5件 | M104: =COUNTA(M4:M103)&"件予定" -> 0件予定 | N104: =SUM(N4:N103) -> 260864
A106: 支払済合計 | M106: =COUNTIF(O4:O103,"済")&"件" -> 0件 | N106: =SUMIF(O4:O103,"済",N4:N103) -> 0
A107: 未払残高（予定） | M107: =COUNTIFS(N4:N103,">0",O4:O103,"")&"件" -> 5件 | N107: =SUMIFS(N4:N103,O4:O103,"") -> 260864
A108: 取消 | M108: =COUNTIF(O4:O103,"取消")&"件" -> 0件 | N108: =SUMIF(O4:O103,"取消",N4:N103) -> 0

Sheet カード枠回復_モーテル
A1: カード枠回復入力 — モーテル
A2: ※ 支払日に金額が反映 → カード枠回復額として月次サマリーへ計上（支出には含めません）
A3: 支払日 | B3: カード会社 / 項目 | C3: 回復額（円） | D3: 区分 | E3: 備考
A55: 合計 | C55: =SUM(C4:C53) -> 0

Sheet 入金入力_ザック
A1: 入金入力 — ザック（黄色セルに入力 → 月次サマリーへ自動反映）
A2: 区分は資金繰り表の収入項目と連動します（現金売上／売掛金回収／手形入金／その他収入／借入金／設備売却）
A3: 日付 | B3: 項目 | C3: 区分 | D3: 金額（円） | E3: 備考 | F3: 入金確認
A105: 合計 | D105: =SUM(D4:D103) -> 0

Sheet 未払一覧_ザック
A1: 支払予定一覧 — ザック（黄色セルに入力／請求書ファイルパスをO列に貼付）
A2: 優先度: | B2: 高（3ヶ月以上滞留） | C2: 中（2ヶ月滞留） | D2: 低（前月のみ） | E2: 月次（経常支出） | G2: ※ 支払予定日に日付を入れると月次サマリーへ自動反映／勘定科目は資金繰り表へ自動マッピング／O列に請求書PDFのフルパスを貼ると右下にリンクが出ます
A3: 種別 | B3: 物件 | C3: 概要 | D3: 勘定科目 | E3: 期日 | F3: 請求先 | G3: 当月分 | H3: 前月繰越 | I3: 前々月繰越 | J3: 前々々月以前 | K3: 累積未払合計 | L3: 優先度 | M3: 支払予定日 | N3: 支払予定額 | O3: 支払状況 | P3: 請求書ファイル
A104: 合計 | G104: =SUM(G4:G103) -> 0 | H104: =SUM(H4:H103) -> 0 | I104: =SUM(I4:I103) -> 0 | J104: =SUM(J4:J103) -> 0 | K104: =SUM(K4:K103) -> 0 | L104: =COUNTA(L4:L103)&"件" -> 0件 | M104: =COUNTA(M4:M103)&"件予定" -> 0件予定 | N104: =SUM(N4:N103) -> 0
A106: 支払済合計 | M106: =COUNTIF(O4:O103,"済")&"件" -> 0件 | N106: =SUMIF(O4:O103,"済",N4:N103) -> 0
A107: 未払残高（予定） | M107: =COUNTIFS(N4:N103,">0",O4:O103,"")&"件" -> 0件 | N107: =SUMIFS(N4:N103,O4:O103,"") -> 0
A108: 取消 | M108: =COUNTIF(O4:O103,"取消")&"件" -> 0件 | N108: =SUMIF(O4:O103,"取消",N4:N103) -> 0

Sheet カード枠回復_ザック
A1: カード枠回復入力 — ザック
A2: ※ 支払日に金額が反映 → カード枠回復額として月次サマリーへ計上（支出には含めません）
A3: 支払日 | B3: カード会社 / 項目 | C3: 回復額（円） | D3: 区分 | E3: 備考
A55: 合計 | C55: =SUM(C4:C53) -> 0

Sheet 入金入力_ワールド・レイ
A1: 入金入力 — ワールド・レイ（黄色セルに入力 → 月次サマリーへ自動反映）
A2: 区分は資金繰り表の収入項目（参考）／本社の資金繰り表には反映しません
A3: 日付 | B3: 項目 | C3: 区分 | D3: 金額（円） | E3: 備考 | F3: 入金確認
A105: 合計 | D105: =SUM(D4:D103) -> 0

Sheet 未払一覧_ワールド・レイ
A1: 支払予定一覧 — ワールド・レイ（黄色セルに入力／請求書ファイルパスをO列に貼付）
A2: 優先度: | B2: 高（3ヶ月以上滞留） | C2: 中（2ヶ月滞留） | D2: 低（前月のみ） | E2: 月次（経常支出） | G2: ※ 支払予定日入力で月次サマリーへ自動反映／勘定科目→資金繰り表マッピング／O列にPDFのフルパス
A3: 種別 | B3: 物件 | C3: 概要 | D3: 勘定科目 | E3: 期日 | F3: 請求先 | G3: 当月分 | H3: 前月繰越 | I3: 前々月繰越 | J3: 前々々月以前 | K3: 累積未払合計 | L3: 優先度 | M3: 支払予定日 | N3: 支払予定額 | O3: 支払状況 | P3: 請求書ファイル
A104: 合計 | G104: =SUM(G4:G103) -> 0 | H104: =SUM(H4:H103) -> 0 | I104: =SUM(I4:I103) -> 0 | J104: =SUM(J4:J103) -> 0 | K104: =SUM(K4:K103) -> 0 | L104: =COUNTA(L4:L103)&"件" -> 0件 | M104: =COUNTA(M4:M103)&"件予定" -> 0件予定 | N104: =SUM(N4:N103) -> 0
A106: 支払済合計 | M106: =COUNTIF(O4:O103,"済")&"件" -> 0件 | N106: =SUMIF(O4:O103,"済",N4:N103) -> 0
A107: 未払残高（予定） | M107: =COUNTIFS(N4:N103,">0",O4:O103,"")&"件" -> 0件 | N107: =SUMIFS(N4:N103,O4:O103,"") -> 0
A108: 取消 | M108: =COUNTIF(O4:O103,"取消")&"件" -> 0件 | N108: =SUMIF(O4:O103,"取消",N4:N103) -> 0

Sheet カード枠回復_ワールド・レイ
A1: カード枠回復入力 — ワールド・レイ
A2: ※ 支払日に金額が反映 → カード枠回復額として月次サマリーへ計上（支出には含めません）
A3: 支払日 | B3: カード会社 / 項目 | C3: 回復額（円） | D3: 区分 | E3: 備考
A55: 合計 | C55: =SUM(C4:C53) -> 0

Sheet 入金入力_ココ・ユニバース
A1: 入金入力 — ココ・ユニバース（黄色セルに入力 → 月次サマリーへ自動反映）
A2: 区分は資金繰り表の収入項目（参考）／本社の資金繰り表には反映しません
A3: 日付 | B3: 項目 | C3: 区分 | D3: 金額（円） | E3: 備考 | F3: 入金確認
A105: 合計 | D105: =SUM(D4:D103) -> 0

Sheet 未払一覧_ココ・ユニバース
A1: 支払予定一覧 — ココ・ユニバース（黄色セルに入力／請求書ファイルパスをO列に貼付）
A2: 優先度: | B2: 高（3ヶ月以上滞留） | C2: 中（2ヶ月滞留） | D2: 低（前月のみ） | E2: 月次（経常支出） | G2: ※ 支払予定日入力で月次サマリーへ自動反映／勘定科目→資金繰り表マッピング／O列にPDFのフルパス
A3: 種別 | B3: 物件 | C3: 概要 | D3: 勘定科目 | E3: 期日 | F3: 請求先 | G3: 当月分 | H3: 前月繰越 | I3: 前々月繰越 | J3: 前々々月以前 | K3: 累積未払合計 | L3: 優先度 | M3: 支払予定日 | N3: 支払予定額 | O3: 支払状況 | P3: 請求書ファイル
A104: 合計 | G104: =SUM(G4:G103) -> 0 | H104: =SUM(H4:H103) -> 0 | I104: =SUM(I4:I103) -> 0 | J104: =SUM(J4:J103) -> 0 | K104: =SUM(K4:K103) -> 0 | L104: =COUNTA(L4:L103)&"件" -> 0件 | M104: =COUNTA(M4:M103)&"件予定" -> 0件予定 | N104: =SUM(N4:N103) -> 0
A106: 支払済合計 | M106: =COUNTIF(O4:O103,"済")&"件" -> 0件 | N106: =SUMIF(O4:O103,"済",N4:N103) -> 0
A107: 未払残高（予定） | M107: =COUNTIFS(N4:N103,">0",O4:O103,"")&"件" -> 0件 | N107: =SUMIFS(N4:N103,O4:O103,"") -> 0
A108: 取消 | M108: =COUNTIF(O4:O103,"取消")&"件" -> 0件 | N108: =SUMIF(O4:O103,"取消",N4:N103) -> 0

Sheet カード枠回復_ココ・ユニバース
A1: カード枠回復入力 — ココ・ユニバース
A2: ※ 支払日に金額が反映 → カード枠回復額として月次サマリーへ計上（支出には含めません）
A3: 支払日 | B3: カード会社 / 項目 | C3: 回復額（円） | D3: 区分 | E3: 備考
A55: 合計 | C55: =SUM(C4:C53) -> 0

Sheet 5月_レジデンス
A1: 5月 日次キャッシュフロー — レジデンス
A2: 入金=入金入力_レジデンス／支出=未払一覧_レジデンス（カード枠回復は除く）／使用可能額=累計差引+累計カード枠回復
A3: 日付 | B3: 入金（円） | C3: 支出（円） | D3: 日次差引（円） | E3: 累計差引（円） | F3: カード枠回復額（円） | G3: 使用可能額（円） | H3: 備考
A4: 46142 | B4: =SUMIFS(入金入力_レジデンス!$D$4:$D$103,入金入力_レジデンス!$A$4:$A$103,A4) -> 0 | C4: =SUMIFS(未払一覧_レジデンス!$N$4:$N$103,未払一覧_レジデンス!$M$4:$M$103,A4) -> 0 | D4: =B4-C4-F4 -> 0 | E4: =D4 -> 0 | F4: =SUMIFS(カード枠回復_レジデンス!$C$4:$C$53,カード枠回復_レジデンス!$A$4:$A$53,A4) -> 0 | G4: =D4+F4 -> 0
A5: 46143 | B5: =SUMIFS(入金入力_レジデンス!$D$4:$D$103,入金入力_レジデンス!$A$4:$A$103,A5) -> 0 | C5: =SUMIFS(未払一覧_レジデンス!$N$4:$N$103,未払一覧_レジデンス!$M$4:$M$103,A5) -> 0 | D5: =B5-C5-F5 -> 0 | E5: =E4+D5 -> 0 | F5: =SUMIFS(カード枠回復_レジデンス!$C$4:$C$53,カード枠回復_レジデンス!$A$4:$A$53,A5) -> 0 | G5: =G4+D5+F5 -> 0
A6: 46144 | B6: =SUMIFS(入金入力_レジデンス!$D$4:$D$103,入金入力_レジデンス!$A$4:$A$103,A6) -> 0 | C6: =SUMIFS(未払一覧_レジデンス!$N$4:$N$103,未払一覧_レジデンス!$M$4:$M$103,A6) -> 0 | D6: =B6-C6-F6 -> 0 | E6: =E5+D6 -> 0 | F6: =SUMIFS(カード枠回復_レジデンス!$C$4:$C$53,カード枠回復_レジデンス!$A$4:$A$53,A6) -> 0 | G6: =G5+D6+F6 -> 0 | H6: 土
A7: 46145 | B7: =SUMIFS(入金入力_レジデンス!$D$4:$D$103,入金入力_レジデンス!$A$4:$A$103,A7) -> 0 | C7: =SUMIFS(未払一覧_レジデンス!$N$4:$N$103,未払一覧_レジデンス!$M$4:$M$103,A7) -> 0 | D7: =B7-C7-F7 -> 0 | E7: =E6+D7 -> 0 | F7: =SUMIFS(カード枠回復_レジデンス!$C$4:$C$53,カード枠回復_レジデンス!$A$4:$A$53,A7) -> 0 | G7: =G6+D7+F7 -> 0 | H7: 日
A8: 46146 | B8: =SUMIFS(入金入力_レジデンス!$D$4:$D$103,入金入力_レジデンス!$A$4:$A$103,A8) -> 0 | C8: =SUMIFS(未払一覧_レジデンス!$N$4:$N$103,未払一覧_レジデンス!$M$4:$M$103,A8) -> 0 | D8: =B8-C8-F8 -> 0 | E8: =E7+D8 -> 0 | F8: =SUMIFS(カード枠回復_レジデンス!$C$4:$C$53,カード枠回復_レジデンス!$A$4:$A$53,A8) -> 0 | G8: =G7+D8+F8 -> 0
A9: 46147 | B9: =SUMIFS(入金入力_レジデンス!$D$4:$D$103,入金入力_レジデンス!$A$4:$A$103,A9) -> 0 | C9: =SUMIFS(未払一覧_レジデンス!$N$4:$N$103,未払一覧_レジデンス!$M$4:$M$103,A9) -> 0 | D9: =B9-C9-F9 -> 0 | E9: =E8+D9 -> 0 | F9: =SUMIFS(カード枠回復_レジデンス!$C$4:$C$53,カード枠回復_レジデンス!$A$4:$A$53,A9) -> 0 | G9: =G8+D9+F9 -> 0
A10: 46148 | B10: =SUMIFS(入金入力_レジデンス!$D$4:$D$103,入金入力_レジデンス!$A$4:$A$103,A10) -> 0 | C10: =SUMIFS(未払一覧_レジデンス!$N$4:$N$103,未払一覧_レジデンス!$M$4:$M$103,A10) -> 0 | D10: =B10-C10-F10 -> 0 | E10: =E9+D10 -> 0 | F10: =SUMIFS(カード枠回復_レジデンス!$C$4:$C$53,カード枠回復_レジデンス!$A$4:$A$53,A10) -> 0 | G10: =G9+D10+F10 -> 0
A11: 46149 | B11: =SUMIFS(入金入力_レジデンス!$D$4:$D$103,入金入力_レジデンス!$A$4:$A$103,A11) -> 0 | C11: =SUMIFS(未払一覧_レジデンス!$N$4:$N$103,未払一覧_レジデンス!$M$4:$M$103,A11) -> 0 | D11: =B11-C11-F11 -> 0 | E11: =E10+D11 -> 0 | F11: =SUMIFS(カード枠回復_レジデンス!$C$4:$C$53,カード枠回復_レジデンス!$A$4:$A$53,A11) -> 0 | G11: =G10+D11+F11 -> 0
A12: 46150 | B12: =SUMIFS(入金入力_レジデンス!$D$4:$D$103,入金入力_レジデンス!$A$4:$A$103,A12) -> 0 | C12: =SUMIFS(未払一覧_レジデンス!$N$4:$N$103,未払一覧_レジデンス!$M$4:$M$103,A12) -> 0 | D12: =B12-C12-F12 -> 0 | E12: =E11+D12 -> 0 | F12: =SUMIFS(カード枠回復_レジデンス!$C$4:$C$53,カード枠回復_レジデンス!$A$4:$A$53,A12) -> 0 | G12: =G11+D12+F12 -> 0
A13: 46151 | B13: =SUMIFS(入金入力_レジデンス!$D$4:$D$103,入金入力_レジデンス!$A$4:$A$103,A13) -> 0 | C13: =SUMIFS(未払一覧_レジデンス!$N$4:$N$103,未払一覧_レジデンス!$M$4:$M$103,A13) -> 0 | D13: =B13-C13-F13 -> 0 | E13: =E12+D13 -> 0 | F13: =SUMIFS(カード枠回復_レジデンス!$C$4:$C$53,カード枠回復_レジデンス!$A$4:$A$53,A13) -> 0 | G13: =G12+D13+F13 -> 0 | H13: 土
A14: 46152 | B14: =SUMIFS(入金入力_レジデンス!$D$4:$D$103,入金入力_レジデンス!$A$4:$A$103,A14) -> 0 | C14: =SUMIFS(未払一覧_レジデンス!$N$4:$N$103,未払一覧_レジデンス!$M$4:$M$103,A14) -> 0 | D14: =B14-C14-F14 -> 0 | E14: =E13+D14 -> 0 | F14: =SUMIFS(カード枠回復_レジデンス!$C$4:$C$53,カード枠回復_レジデンス!$A$4:$A$53,A14) -> 0 | G14: =G13+D14+F14 -> 0 | H14: 日
A15: 46153 | B15: =SUMIFS(入金入力_レジデンス!$D$4:$D$103,入金入力_レジデンス!$A$4:$A$103,A15) -> 0 | C15: =SUMIFS(未払一覧_レジデンス!$N$4:$N$103,未払一覧_レジデンス!$M$4:$M$103,A15) -> 0 | D15: =B15-C15-F15 -> 0 | E15: =E14+D15 -> 0 | F15: =SUMIFS(カード枠回復_レジデンス!$C$4:$C$53,カード枠回復_レジデンス!$A$4:$A$53,A15) -> 0 | G15: =G14+D15+F15 -> 0
A16: 46154 | B16: =SUMIFS(入金入力_レジデンス!$D$4:$D$103,入金入力_レジデンス!$A$4:$A$103,A16) -> 0 | C16: =SUMIFS(未払一覧_レジデンス!$N$4:$N$103,未払一覧_レジデンス!$M$4:$M$103,A16) -> 0 | D16: =B16-C16-F16 -> 0 | E16: =E15+D16 -> 0 | F16: =SUMIFS(カード枠回復_レジデンス!$C$4:$C$53,カード枠回復_レジデンス!$A$4:$A$53,A16) -> 0 | G16: =G15+D16+F16 -> 0
A17: 46155 | B17: =SUMIFS(入金入力_レジデンス!$D$4:$D$103,入金入力_レジデンス!$A$4:$A$103,A17) -> 0 | C17: =SUMIFS(未払一覧_レジデンス!$N$4:$N$103,未払一覧_レジデンス!$M$4:$M$103,A17) -> 0 | D17: =B17-C17-F17 -> 0 | E17: =E16+D17 -> 0 | F17: =SUMIFS(カード枠回復_レジデンス!$C$4:$C$53,カード枠回復_レジデンス!$A$4:$A$53,A17) -> 0 | G17: =G16+D17+F17 -> 0
A18: 46156 | B18: =SUMIFS(入金入力_レジデンス!$D$4:$D$103,入金入力_レジデンス!$A$4:$A$103,A18) -> 0 | C18: =SUMIFS(未払一覧_レジデンス!$N$4:$N$103,未払一覧_レジデンス!$M$4:$M$103,A18) -> 0 | D18: =B18-C18-F18 -> 0 | E18: =E17+D18 -> 0 | F18: =SUMIFS(カード枠回復_レジデンス!$C$4:$C$53,カード枠回復_レジデンス!$A$4:$A$53,A18) -> 0 | G18: =G17+D18+F18 -> 0
A19: 46157 | B19: =SUMIFS(入金入力_レジデンス!$D$4:$D$103,入金入力_レジデンス!$A$4:$A$103,A19) -> 0 | C19: =SUMIFS(未払一覧_レジデンス!$N$4:$N$103,未払一覧_レジデンス!$M$4:$M$103,A19) -> 0 | D19: =B19-C19-F19 -> 0 | E19: =E18+D19 -> 0 | F19: =SUMIFS(カード枠回復_レジデンス!$C$4:$C$53,カード枠回復_レジデンス!$A$4:$A$53,A19) -> 0 | G19: =G18+D19+F19 -> 0
A20: 46158 | B20: =SUMIFS(入金入力_レジデンス!$D$4:$D$103,入金入力_レジデンス!$A$4:$A$103,A20) -> 0 | C20: =SUMIFS(未払一覧_レジデンス!$N$4:$N$103,未払一覧_レジデンス!$M$4:$M$103,A20) -> 0 | D20: =B20-C20-F20 -> 0 | E20: =E19+D20 -> 0 | F20: =SUMIFS(カード枠回復_レジデンス!$C$4:$C$53,カード枠回復_レジデンス!$A$4:$A$53,A20) -> 0 | G20: =G19+D20+F20 -> 0 | H20: 土
A21: 46159 | B21: =SUMIFS(入金入力_レジデンス!$D$4:$D$103,入金入力_レジデンス!$A$4:$A$103,A21) -> 0 | C21: =SUMIFS(未払一覧_レジデンス!$N$4:$N$103,未払一覧_レジデンス!$M$4:$M$103,A21) -> 0 | D21: =B21-C21-F21 -> 0 | E21: =E20+D21 -> 0 | F21: =SUMIFS(カード枠回復_レジデンス!$C$4:$C$53,カード枠回復_レジデンス!$A$4:$A$53,A21) -> 0 | G21: =G20+D21+F21 -> 0 | H21: 日
A22: 46160 | B22: =SUMIFS(入金入力_レジデンス!$D$4:$D$103,入金入力_レジデンス!$A$4:$A$103,A22) -> 0 | C22: =SUMIFS(未払一覧_レジデンス!$N$4:$N$103,未払一覧_レジデンス!$M$4:$M$103,A22) -> 0 | D22: =B22-C22-F22 -> 0 | E22: =E21+D22 -> 0 | F22: =SUMIFS(カード枠回復_レジデンス!$C$4:$C$53,カード枠回復_レジデンス!$A$4:$A$53,A22) -> 0 | G22: =G21+D22+F22 -> 0
A23: 46161 | B23: =SUMIFS(入金入力_レジデンス!$D$4:$D$103,入金入力_レジデンス!$A$4:$A$103,A23) -> 0 | C23: =SUMIFS(未払一覧_レジデンス!$N$4:$N$103,未払一覧_レジデンス!$M$4:$M$103,A23) -> 0 | D23: =B23-C23-F23 -> 0 | E23: =E22+D23 -> 0 | F23: =SUMIFS(カード枠回復_レジデンス!$C$4:$C$53,カード枠回復_レジデンス!$A$4:$A$53,A23) -> 0 | G23: =G22+D23+F23 -> 0
A24: 46162 | B24: =SUMIFS(入金入力_レジデンス!$D$4:$D$103,入金入力_レジデンス!$A$4:$A$103,A24) -> 0 | C24: =SUMIFS(未払一覧_レジデンス!$N$4:$N$103,未払一覧_レジデンス!$M$4:$M$103,A24) -> 0 | D24: =B24-C24-F24 -> 0 | E24: =E23+D24 -> 0 | F24: =SUMIFS(カード枠回復_レジデンス!$C$4:$C$53,カード枠回復_レジデンス!$A$4:$A$53,A24) -> 0 | G24: =G23+D24+F24 -> 0
A25: 46163 | B25: =SUMIFS(入金入力_レジデンス!$D$4:$D$103,入金入力_レジデンス!$A$4:$A$103,A25) -> 0 | C25: =SUMIFS(未払一覧_レジデンス!$N$4:$N$103,未払一覧_レジデンス!$M$4:$M$103,A25) -> 0 | D25: =B25-C25-F25 -> 0 | E25: =E24+D25 -> 0 | F25: =SUMIFS(カード枠回復_レジデンス!$C$4:$C$53,カード枠回復_レジデンス!$A$4:$A$53,A25) -> 0 | G25: =G24+D25+F25 -> 0
A26: 46164 | B26: =SUMIFS(入金入力_レジデンス!$D$4:$D$103,入金入力_レジデンス!$A$4:$A$103,A26) -> 0 | C26: =SUMIFS(未払一覧_レジデンス!$N$4:$N$103,未払一覧_レジデンス!$M$4:$M$103,A26) -> 0 | D26: =B26-C26-F26 -> 0 | E26: =E25+D26 -> 0 | F26: =SUMIFS(カード枠回復_レジデンス!$C$4:$C$53,カード枠回復_レジデンス!$A$4:$A$53,A26) -> 0 | G26: =G25+D26+F26 -> 0
A27: 46165 | B27: =SUMIFS(入金入力_レジデンス!$D$4:$D$103,入金入力_レジデンス!$A$4:$A$103,A27) -> 0 | C27: =SUMIFS(未払一覧_レジデンス!$N$4:$N$103,未払一覧_レジデンス!$M$4:$M$103,A27) -> 0 | D27: =B27-C27-F27 -> 0 | E27: =E26+D27 -> 0 | F27: =SUMIFS(カード枠回復_レジデンス!$C$4:$C$53,カード枠回復_レジデンス!$A$4:$A$53,A27) -> 0 | G27: =G26+D27+F27 -> 0 | H27: 土
A28: 46166 | B28: =SUMIFS(入金入力_レジデンス!$D$4:$D$103,入金入力_レジデンス!$A$4:$A$103,A28) -> 0 | C28: =SUMIFS(未払一覧_レジデンス!$N$4:$N$103,未払一覧_レジデンス!$M$4:$M$103,A28) -> 0 | D28: =B28-C28-F28 -> 0 | E28: =E27+D28 -> 0 | F28: =SUMIFS(カード枠回復_レジデンス!$C$4:$C$53,カード枠回復_レジデンス!$A$4:$A$53,A28) -> 0 | G28: =G27+D28+F28 -> 0 | H28: 日
A29: 46167 | B29: =SUMIFS(入金入力_レジデンス!$D$4:$D$103,入金入力_レジデンス!$A$4:$A$103,A29) -> 0 | C29: =SUMIFS(未払一覧_レジデンス!$N$4:$N$103,未払一覧_レジデンス!$M$4:$M$103,A29) -> 0 | D29: =B29-C29-F29 -> 0 | E29: =E28+D29 -> 0 | F29: =SUMIFS(カード枠回復_レジデンス!$C$4:$C$53,カード枠回復_レジデンス!$A$4:$A$53,A29) -> 0 | G29: =G28+D29+F29 -> 0
A30: 46168 | B30: =SUMIFS(入金入力_レジデンス!$D$4:$D$103,入金入力_レジデンス!$A$4:$A$103,A30) -> 0 | C30: =SUMIFS(未払一覧_レジデンス!$N$4:$N$103,未払一覧_レジデンス!$M$4:$M$103,A30) -> 0 | D30: =B30-C30-F30 -> 0 | E30: =E29+D30 -> 0 | F30: =SUMIFS(カード枠回復_レジデンス!$C$4:$C$53,カード枠回復_レジデンス!$A$4:$A$53,A30) -> 0 | G30: =G29+D30+F30 -> 0
A31: 46169 | B31: =SUMIFS(入金入力_レジデンス!$D$4:$D$103,入金入力_レジデンス!$A$4:$A$103,A31) -> 0 | C31: =SUMIFS(未払一覧_レジデンス!$N$4:$N$103,未払一覧_レジデンス!$M$4:$M$103,A31) -> 0 | D31: =B31-C31-F31 -> 0 | E31: =E30+D31 -> 0 | F31: =SUMIFS(カード枠回復_レジデンス!$C$4:$C$53,カード枠回復_レジデンス!$A$4:$A$53,A31) -> 0 | G31: =G30+D31+F31 -> 0
A32: 46170 | B32: =SUMIFS(入金入力_レジデンス!$D$4:$D$103,入金入力_レジデンス!$A$4:$A$103,A32) -> 0 | C32: =SUMIFS(未払一覧_レジデンス!$N$4:$N$103,未払一覧_レジデンス!$M$4:$M$103,A32) -> 0 | D32: =B32-C32-F32 -> 0 | E32: =E31+D32 -> 0 | F32: =SUMIFS(カード枠回復_レジデンス!$C$4:$C$53,カード枠回復_レジデンス!$A$4:$A$53,A32) -> 0 | G32: =G31+D32+F32 -> 0
A33: 46171 | B33: =SUMIFS(入金入力_レジデンス!$D$4:$D$103,入金入力_レジデンス!$A$4:$A$103,A33) -> 0 | C33: =SUMIFS(未払一覧_レジデンス!$N$4:$N$103,未払一覧_レジデンス!$M$4:$M$103,A33) -> 0 | D33: =B33-C33-F33 -> 0 | E33: =E32+D33 -> 0 | F33: =SUMIFS(カード枠回復_レジデンス!$C$4:$C$53,カード枠回復_レジデンス!$A$4:$A$53,A33) -> 0 | G33: =G32+D33+F33 -> 0
A34: 46172 | B34: =SUMIFS(入金入力_レジデンス!$D$4:$D$103,入金入力_レジデンス!$A$4:$A$103,A34) -> 0 | C34: =SUMIFS(未払一覧_レジデンス!$N$4:$N$103,未払一覧_レジデンス!$M$4:$M$103,A34) -> 0 | D34: =B34-C34-F34 -> 0 | E34: =E33+D34 -> 0 | F34: =SUMIFS(カード枠回復_レジデンス!$C$4:$C$53,カード枠回復_レジデンス!$A$4:$A$53,A34) -> 0 | G34: =G33+D34+F34 -> 0 | H34: 土
A35: 46173 | B35: =SUMIFS(入金入力_レジデンス!$D$4:$D$103,入金入力_レジデンス!$A$4:$A$103,A35) -> 0 | C35: =SUMIFS(未払一覧_レジデンス!$N$4:$N$103,未払一覧_レジデンス!$M$4:$M$103,A35) -> 0 | D35: =B35-C35-F35 -> 0 | E35: =E34+D35 -> 0 | F35: =SUMIFS(カード枠回復_レジデンス!$C$4:$C$53,カード枠回復_レジデンス!$A$4:$A$53,A35) -> 0 | G35: =G34+D35+F35 -> 0 | H35: 日
A37: 5月合計 | B37: =SUM(B4:B35) -> 0 | C37: =SUM(C4:C35) -> 0 | D37: =B37-C37-F37 -> 0 | E37: =E35 -> 0 | F37: =SUM(F4:F35) -> 0 | G37: =G35 -> 0 | H37: 当月合計

Sheet 6月_レジデンス
A1: 6月 日次キャッシュフロー — レジデンス
A2: 入金=入金入力_レジデンス／支出=未払一覧_レジデンス（カード枠回復は除く）／使用可能額=累計差引+累計カード枠回復
A3: 日付 | B3: 入金（円） | C3: 支出（円） | D3: 日次差引（円） | E3: 累計差引（円） | F3: カード枠回復額（円） | G3: 使用可能額（円） | H3: 備考
A4: 46174 | B4: =SUMIFS(入金入力_レジデンス!$D$4:$D$103,入金入力_レジデンス!$A$4:$A$103,A4) -> 0 | C4: =SUMIFS(未払一覧_レジデンス!$N$4:$N$103,未払一覧_レジデンス!$M$4:$M$103,A4) -> 0 | D4: =B4-C4-F4 -> 0 | E4: ='5月_レジデンス'!E35+D4 -> 0 | F4: =SUMIFS(カード枠回復_レジデンス!$C$4:$C$53,カード枠回復_レジデンス!$A$4:$A$53,A4) -> 0 | G4: ='5月_レジデンス'!G35+D4+F4 -> 0
A5: 46175 | B5: =SUMIFS(入金入力_レジデンス!$D$4:$D$103,入金入力_レジデンス!$A$4:$A$103,A5) -> 0 | C5: =SUMIFS(未払一覧_レジデンス!$N$4:$N$103,未払一覧_レジデンス!$M$4:$M$103,A5) -> 0 | D5: =B5-C5-F5 -> 0 | E5: =E4+D5 -> 0 | F5: =SUMIFS(カード枠回復_レジデンス!$C$4:$C$53,カード枠回復_レジデンス!$A$4:$A$53,A5) -> 0 | G5: =G4+D5+F5 -> 0
A6: 46176 | B6: =SUMIFS(入金入力_レジデンス!$D$4:$D$103,入金入力_レジデンス!$A$4:$A$103,A6) -> 0 | C6: =SUMIFS(未払一覧_レジデンス!$N$4:$N$103,未払一覧_レジデンス!$M$4:$M$103,A6) -> 0 | D6: =B6-C6-F6 -> 0 | E6: =E5+D6 -> 0 | F6: =SUMIFS(カード枠回復_レジデンス!$C$4:$C$53,カード枠回復_レジデンス!$A$4:$A$53,A6) -> 0 | G6: =G5+D6+F6 -> 0
A7: 46177 | B7: =SUMIFS(入金入力_レジデンス!$D$4:$D$103,入金入力_レジデンス!$A$4:$A$103,A7) -> 0 | C7: =SUMIFS(未払一覧_レジデンス!$N$4:$N$103,未払一覧_レジデンス!$M$4:$M$103,A7) -> 0 | D7: =B7-C7-F7 -> 0 | E7: =E6+D7 -> 0 | F7: =SUMIFS(カード枠回復_レジデンス!$C$4:$C$53,カード枠回復_レジデンス!$A$4:$A$53,A7) -> 0 | G7: =G6+D7+F7 -> 0
A8: 46178 | B8: =SUMIFS(入金入力_レジデンス!$D$4:$D$103,入金入力_レジデンス!$A$4:$A$103,A8) -> 0 | C8: =SUMIFS(未払一覧_レジデンス!$N$4:$N$103,未払一覧_レジデンス!$M$4:$M$103,A8) -> 0 | D8: =B8-C8-F8 -> 0 | E8: =E7+D8 -> 0 | F8: =SUMIFS(カード枠回復_レジデンス!$C$4:$C$53,カード枠回復_レジデンス!$A$4:$A$53,A8) -> 0 | G8: =G7+D8+F8 -> 0
A9: 46179 | B9: =SUMIFS(入金入力_レジデンス!$D$4:$D$103,入金入力_レジデンス!$A$4:$A$103,A9) -> 0 | C9: =SUMIFS(未払一覧_レジデンス!$N$4:$N$103,未払一覧_レジデンス!$M$4:$M$103,A9) -> 0 | D9: =B9-C9-F9 -> 0 | E9: =E8+D9 -> 0 | F9: =SUMIFS(カード枠回復_レジデンス!$C$4:$C$53,カード枠回復_レジデンス!$A$4:$A$53,A9) -> 0 | G9: =G8+D9+F9 -> 0 | H9: 土
A10: 46180 | B10: =SUMIFS(入金入力_レジデンス!$D$4:$D$103,入金入力_レジデンス!$A$4:$A$103,A10) -> 0 | C10: =SUMIFS(未払一覧_レジデンス!$N$4:$N$103,未払一覧_レジデンス!$M$4:$M$103,A10) -> 0 | D10: =B10-C10-F10 -> 0 | E10: =E9+D10 -> 0 | F10: =SUMIFS(カード枠回復_レジデンス!$C$4:$C$53,カード枠回復_レジデンス!$A$4:$A$53,A10) -> 0 | G10: =G9+D10+F10 -> 0 | H10: 日
A11: 46181 | B11: =SUMIFS(入金入力_レジデンス!$D$4:$D$103,入金入力_レジデンス!$A$4:$A$103,A11) -> 0 | C11: =SUMIFS(未払一覧_レジデンス!$N$4:$N$103,未払一覧_レジデンス!$M$4:$M$103,A11) -> 0 | D11: =B11-C11-F11 -> 0 | E11: =E10+D11 -> 0 | F11: =SUMIFS(カード枠回復_レジデンス!$C$4:$C$53,カード枠回復_レジデンス!$A$4:$A$53,A11) -> 0 | G11: =G10+D11+F11 -> 0
A12: 46182 | B12: =SUMIFS(入金入力_レジデンス!$D$4:$D$103,入金入力_レジデンス!$A$4:$A$103,A12) -> 0 | C12: =SUMIFS(未払一覧_レジデンス!$N$4:$N$103,未払一覧_レジデンス!$M$4:$M$103,A12) -> 0 | D12: =B12-C12-F12 -> 0 | E12: =E11+D12 -> 0 | F12: =SUMIFS(カード枠回復_レジデンス!$C$4:$C$53,カード枠回復_レジデンス!$A$4:$A$53,A12) -> 0 | G12: =G11+D12+F12 -> 0
A13: 46183 | B13: =SUMIFS(入金入力_レジデンス!$D$4:$D$103,入金入力_レジデンス!$A$4:$A$103,A13) -> 0 | C13: =SUMIFS(未払一覧_レジデンス!$N$4:$N$103,未払一覧_レジデンス!$M$4:$M$103,A13) -> 0 | D13: =B13-C13-F13 -> 0 | E13: =E12+D13 -> 0 | F13: =SUMIFS(カード枠回復_レジデンス!$C$4:$C$53,カード枠回復_レジデンス!$A$4:$A$53,A13) -> 0 | G13: =G12+D13+F13 -> 0
A14: 46184 | B14: =SUMIFS(入金入力_レジデンス!$D$4:$D$103,入金入力_レジデンス!$A$4:$A$103,A14) -> 0 | C14: =SUMIFS(未払一覧_レジデンス!$N$4:$N$103,未払一覧_レジデンス!$M$4:$M$103,A14) -> 0 | D14: =B14-C14-F14 -> 0 | E14: =E13+D14 -> 0 | F14: =SUMIFS(カード枠回復_レジデンス!$C$4:$C$53,カード枠回復_レジデンス!$A$4:$A$53,A14) -> 0 | G14: =G13+D14+F14 -> 0
A15: 46185 | B15: =SUMIFS(入金入力_レジデンス!$D$4:$D$103,入金入力_レジデンス!$A$4:$A$103,A15) -> 0 | C15: =SUMIFS(未払一覧_レジデンス!$N$4:$N$103,未払一覧_レジデンス!$M$4:$M$103,A15) -> 0 | D15: =B15-C15-F15 -> 0 | E15: =E14+D15 -> 0 | F15: =SUMIFS(カード枠回復_レジデンス!$C$4:$C$53,カード枠回復_レジデンス!$A$4:$A$53,A15) -> 0 | G15: =G14+D15+F15 -> 0
A16: 46186 | B16: =SUMIFS(入金入力_レジデンス!$D$4:$D$103,入金入力_レジデンス!$A$4:$A$103,A16) -> 0 | C16: =SUMIFS(未払一覧_レジデンス!$N$4:$N$103,未払一覧_レジデンス!$M$4:$M$103,A16) -> 0 | D16: =B16-C16-F16 -> 0 | E16: =E15+D16 -> 0 | F16: =SUMIFS(カード枠回復_レジデンス!$C$4:$C$53,カード枠回復_レジデンス!$A$4:$A$53,A16) -> 0 | G16: =G15+D16+F16 -> 0 | H16: 土
A17: 46187 | B17: =SUMIFS(入金入力_レジデンス!$D$4:$D$103,入金入力_レジデンス!$A$4:$A$103,A17) -> 0 | C17: =SUMIFS(未払一覧_レジデンス!$N$4:$N$103,未払一覧_レジデンス!$M$4:$M$103,A17) -> 0 | D17: =B17-C17-F17 -> 0 | E17: =E16+D17 -> 0 | F17: =SUMIFS(カード枠回復_レジデンス!$C$4:$C$53,カード枠回復_レジデンス!$A$4:$A$53,A17) -> 0 | G17: =G16+D17+F17 -> 0 | H17: 日
A18: 46188 | B18: =SUMIFS(入金入力_レジデンス!$D$4:$D$103,入金入力_レジデンス!$A$4:$A$103,A18) -> 0 | C18: =SUMIFS(未払一覧_レジデンス!$N$4:$N$103,未払一覧_レジデンス!$M$4:$M$103,A18) -> 0 | D18: =B18-C18-F18 -> 0 | E18: =E17+D18 -> 0 | F18: =SUMIFS(カード枠回復_レジデンス!$C$4:$C$53,カード枠回復_レジデンス!$A$4:$A$53,A18) -> 0 | G18: =G17+D18+F18 -> 0
A19: 46189 | B19: =SUMIFS(入金入力_レジデンス!$D$4:$D$103,入金入力_レジデンス!$A$4:$A$103,A19) -> 0 | C19: =SUMIFS(未払一覧_レジデンス!$N$4:$N$103,未払一覧_レジデンス!$M$4:$M$103,A19) -> 0 | D19: =B19-C19-F19 -> 0 | E19: =E18+D19 -> 0 | F19: =SUMIFS(カード枠回復_レジデンス!$C$4:$C$53,カード枠回復_レジデンス!$A$4:$A$53,A19) -> 0 | G19: =G18+D19+F19 -> 0
A20: 46190 | B20: =SUMIFS(入金入力_レジデンス!$D$4:$D$103,入金入力_レジデンス!$A$4:$A$103,A20) -> 0 | C20: =SUMIFS(未払一覧_レジデンス!$N$4:$N$103,未払一覧_レジデンス!$M$4:$M$103,A20) -> 0 | D20: =B20-C20-F20 -> 0 | E20: =E19+D20 -> 0 | F20: =SUMIFS(カード枠回復_レジデンス!$C$4:$C$53,カード枠回復_レジデンス!$A$4:$A$53,A20) -> 0 | G20: =G19+D20+F20 -> 0
A21: 46191 | B21: =SUMIFS(入金入力_レジデンス!$D$4:$D$103,入金入力_レジデンス!$A$4:$A$103,A21) -> 0 | C21: =SUMIFS(未払一覧_レジデンス!$N$4:$N$103,未払一覧_レジデンス!$M$4:$M$103,A21) -> 0 | D21: =B21-C21-F21 -> 0 | E21: =E20+D21 -> 0 | F21: =SUMIFS(カード枠回復_レジデンス!$C$4:$C$53,カード枠回復_レジデンス!$A$4:$A$53,A21) -> 0 | G21: =G20+D21+F21 -> 0
A22: 46192 | B22: =SUMIFS(入金入力_レジデンス!$D$4:$D$103,入金入力_レジデンス!$A$4:$A$103,A22) -> 0 | C22: =SUMIFS(未払一覧_レジデンス!$N$4:$N$103,未払一覧_レジデンス!$M$4:$M$103,A22) -> 0 | D22: =B22-C22-F22 -> 0 | E22: =E21+D22 -> 0 | F22: =SUMIFS(カード枠回復_レジデンス!$C$4:$C$53,カード枠回復_レジデンス!$A$4:$A$53,A22) -> 0 | G22: =G21+D22+F22 -> 0
A23: 46193 | B23: =SUMIFS(入金入力_レジデンス!$D$4:$D$103,入金入力_レジデンス!$A$4:$A$103,A23) -> 0 | C23: =SUMIFS(未払一覧_レジデンス!$N$4:$N$103,未払一覧_レジデンス!$M$4:$M$103,A23) -> 0 | D23: =B23-C23-F23 -> 0 | E23: =E22+D23 -> 0 | F23: =SUMIFS(カード枠回復_レジデンス!$C$4:$C$53,カード枠回復_レジデンス!$A$4:$A$53,A23) -> 0 | G23: =G22+D23+F23 -> 0 | H23: 土
A24: 46194 | B24: =SUMIFS(入金入力_レジデンス!$D$4:$D$103,入金入力_レジデンス!$A$4:$A$103,A24) -> 0 | C24: =SUMIFS(未払一覧_レジデンス!$N$4:$N$103,未払一覧_レジデンス!$M$4:$M$103,A24) -> 0 | D24: =B24-C24-F24 -> 0 | E24: =E23+D24 -> 0 | F24: =SUMIFS(カード枠回復_レジデンス!$C$4:$C$53,カード枠回復_レジデンス!$A$4:$A$53,A24) -> 0 | G24: =G23+D24+F24 -> 0 | H24: 日
A25: 46195 | B25: =SUMIFS(入金入力_レジデンス!$D$4:$D$103,入金入力_レジデンス!$A$4:$A$103,A25) -> 0 | C25: =SUMIFS(未払一覧_レジデンス!$N$4:$N$103,未払一覧_レジデンス!$M$4:$M$103,A25) -> 0 | D25: =B25-C25-F25 -> 0 | E25: =E24+D25 -> 0 | F25: =SUMIFS(カード枠回復_レジデンス!$C$4:$C$53,カード枠回復_レジデンス!$A$4:$A$53,A25) -> 0 | G25: =G24+D25+F25 -> 0
A26: 46196 | B26: =SUMIFS(入金入力_レジデンス!$D$4:$D$103,入金入力_レジデンス!$A$4:$A$103,A26) -> 0 | C26: =SUMIFS(未払一覧_レジデンス!$N$4:$N$103,未払一覧_レジデンス!$M$4:$M$103,A26) -> 0 | D26: =B26-C26-F26 -> 0 | E26: =E25+D26 -> 0 | F26: =SUMIFS(カード枠回復_レジデンス!$C$4:$C$53,カード枠回復_レジデンス!$A$4:$A$53,A26) -> 0 | G26: =G25+D26+F26 -> 0
A27: 46197 | B27: =SUMIFS(入金入力_レジデンス!$D$4:$D$103,入金入力_レジデンス!$A$4:$A$103,A27) -> 0 | C27: =SUMIFS(未払一覧_レジデンス!$N$4:$N$103,未払一覧_レジデンス!$M$4:$M$103,A27) -> 0 | D27: =B27-C27-F27 -> 0 | E27: =E26+D27 -> 0 | F27: =SUMIFS(カード枠回復_レジデンス!$C$4:$C$53,カード枠回復_レジデンス!$A$4:$A$53,A27) -> 0 | G27: =G26+D27+F27 -> 0
A28: 46198 | B28: =SUMIFS(入金入力_レジデンス!$D$4:$D$103,入金入力_レジデンス!$A$4:$A$103,A28) -> 0 | C28: =SUMIFS(未払一覧_レジデンス!$N$4:$N$103,未払一覧_レジデンス!$M$4:$M$103,A28) -> 0 | D28: =B28-C28-F28 -> 0 | E28: =E27+D28 -> 0 | F28: =SUMIFS(カード枠回復_レジデンス!$C$4:$C$53,カード枠回復_レジデンス!$A$4:$A$53,A28) -> 0 | G28: =G27+D28+F28 -> 0
A29: 46199 | B29: =SUMIFS(入金入力_レジデンス!$D$4:$D$103,入金入力_レジデンス!$A$4:$A$103,A29) -> 0 | C29: =SUMIFS(未払一覧_レジデンス!$N$4:$N$103,未払一覧_レジデンス!$M$4:$M$103,A29) -> 0 | D29: =B29-C29-F29 -> 0 | E29: =E28+D29 -> 0 | F29: =SUMIFS(カード枠回復_レジデンス!$C$4:$C$53,カード枠回復_レジデンス!$A$4:$A$53,A29) -> 0 | G29: =G28+D29+F29 -> 0
A30: 46200 | B30: =SUMIFS(入金入力_レジデンス!$D$4:$D$103,入金入力_レジデンス!$A$4:$A$103,A30) -> 0 | C30: =SUMIFS(未払一覧_レジデンス!$N$4:$N$103,未払一覧_レジデンス!$M$4:$M$103,A30) -> 0 | D30: =B30-C30-F30 -> 0 | E30: =E29+D30 -> 0 | F30: =SUMIFS(カード枠回復_レジデンス!$C$4:$C$53,カード枠回復_レジデンス!$A$4:$A$53,A30) -> 0 | G30: =G29+D30+F30 -> 0 | H30: 土
A31: 46201 | B31: =SUMIFS(入金入力_レジデンス!$D$4:$D$103,入金入力_レジデンス!$A$4:$A$103,A31) -> 0 | C31: =SUMIFS(未払一覧_レジデンス!$N$4:$N$103,未払一覧_レジデンス!$M$4:$M$103,A31) -> 0 | D31: =B31-C31-F31 -> 0 | E31: =E30+D31 -> 0 | F31: =SUMIFS(カード枠回復_レジデンス!$C$4:$C$53,カード枠回復_レジデンス!$A$4:$A$53,A31) -> 0 | G31: =G30+D31+F31 -> 0 | H31: 日
A32: 46202 | B32: =SUMIFS(入金入力_レジデンス!$D$4:$D$103,入金入力_レジデンス!$A$4:$A$103,A32) -> 0 | C32: =SUMIFS(未払一覧_レジデンス!$N$4:$N$103,未払一覧_レジデンス!$M$4:$M$103,A32) -> 0 | D32: =B32-C32-F32 -> 0 | E32: =E31+D32 -> 0 | F32: =SUMIFS(カード枠回復_レジデンス!$C$4:$C$53,カード枠回復_レジデンス!$A$4:$A$53,A32) -> 0 | G32: =G31+D32+F32 -> 0
A33: 46203 | B33: =SUMIFS(入金入力_レジデンス!$D$4:$D$103,入金入力_レジデンス!$A$4:$A$103,A33) -> 0 | C33: =SUMIFS(未払一覧_レジデンス!$N$4:$N$103,未払一覧_レジデンス!$M$4:$M$103,A33) -> 0 | D33: =B33-C33-F33 -> 0 | E33: =E32+D33 -> 0 | F33: =SUMIFS(カード枠回復_レジデンス!$C$4:$C$53,カード枠回復_レジデンス!$A$4:$A$53,A33) -> 0 | G33: =G32+D33+F33 -> 0
A35: 6月合計 | B35: =SUM(B4:B33) -> 0 | C35: =SUM(C4:C33) -> 0 | D35: =B35-C35-F35 -> 0 | E35: =E33 -> 0 | F35: =SUM(F4:F33) -> 0 | G35: =G33 -> 0 | H35: 当月合計

Sheet 7月_レジデンス
A1: 7月 日次キャッシュフロー — レジデンス
A2: 入金=入金入力_レジデンス／支出=未払一覧_レジデンス（カード枠回復は除く）／使用可能額=累計差引+累計カード枠回復
A3: 日付 | B3: 入金（円） | C3: 支出（円） | D3: 日次差引（円） | E3: 累計差引（円） | F3: カード枠回復額（円） | G3: 使用可能額（円） | H3: 備考
A4: 46204 | B4: =SUMIFS(入金入力_レジデンス!$D$4:$D$103,入金入力_レジデンス!$A$4:$A$103,A4) -> 0 | C4: =SUMIFS(未払一覧_レジデンス!$N$4:$N$103,未払一覧_レジデンス!$M$4:$M$103,A4) -> 0 | D4: =B4-C4-F4 -> 0 | E4: ='6月_レジデンス'!E33+D4 -> 0 | F4: =SUMIFS(カード枠回復_レジデンス!$C$4:$C$53,カード枠回復_レジデンス!$A$4:$A$53,A4) -> 0 | G4: ='6月_レジデンス'!G33+D4+F4 -> 0
A5: 46205 | B5: =SUMIFS(入金入力_レジデンス!$D$4:$D$103,入金入力_レジデンス!$A$4:$A$103,A5) -> 0 | C5: =SUMIFS(未払一覧_レジデンス!$N$4:$N$103,未払一覧_レジデンス!$M$4:$M$103,A5) -> 0 | D5: =B5-C5-F5 -> 0 | E5: =E4+D5 -> 0 | F5: =SUMIFS(カード枠回復_レジデンス!$C$4:$C$53,カード枠回復_レジデンス!$A$4:$A$53,A5) -> 0 | G5: =G4+D5+F5 -> 0
A6: 46206 | B6: =SUMIFS(入金入力_レジデンス!$D$4:$D$103,入金入力_レジデンス!$A$4:$A$103,A6) -> 0 | C6: =SUMIFS(未払一覧_レジデンス!$N$4:$N$103,未払一覧_レジデンス!$M$4:$M$103,A6) -> 0 | D6: =B6-C6-F6 -> 0 | E6: =E5+D6 -> 0 | F6: =SUMIFS(カード枠回復_レジデンス!$C$4:$C$53,カード枠回復_レジデンス!$A$4:$A$53,A6) -> 0 | G6: =G5+D6+F6 -> 0
A7: 46207 | B7: =SUMIFS(入金入力_レジデンス!$D$4:$D$103,入金入力_レジデンス!$A$4:$A$103,A7) -> 0 | C7: =SUMIFS(未払一覧_レジデンス!$N$4:$N$103,未払一覧_レジデンス!$M$4:$M$103,A7) -> 0 | D7: =B7-C7-F7 -> 0 | E7: =E6+D7 -> 0 | F7: =SUMIFS(カード枠回復_レジデンス!$C$4:$C$53,カード枠回復_レジデンス!$A$4:$A$53,A7) -> 0 | G7: =G6+D7+F7 -> 0 | H7: 土
A8: 46208 | B8: =SUMIFS(入金入力_レジデンス!$D$4:$D$103,入金入力_レジデンス!$A$4:$A$103,A8) -> 0 | C8: =SUMIFS(未払一覧_レジデンス!$N$4:$N$103,未払一覧_レジデンス!$M$4:$M$103,A8) -> 0 | D8: =B8-C8-F8 -> 0 | E8: =E7+D8 -> 0 | F8: =SUMIFS(カード枠回復_レジデンス!$C$4:$C$53,カード枠回復_レジデンス!$A$4:$A$53,A8) -> 0 | G8: =G7+D8+F8 -> 0 | H8: 日
A9: 46209 | B9: =SUMIFS(入金入力_レジデンス!$D$4:$D$103,入金入力_レジデンス!$A$4:$A$103,A9) -> 0 | C9: =SUMIFS(未払一覧_レジデンス!$N$4:$N$103,未払一覧_レジデンス!$M$4:$M$103,A9) -> 0 | D9: =B9-C9-F9 -> 0 | E9: =E8+D9 -> 0 | F9: =SUMIFS(カード枠回復_レジデンス!$C$4:$C$53,カード枠回復_レジデンス!$A$4:$A$53,A9) -> 0 | G9: =G8+D9+F9 -> 0
A10: 46210 | B10: =SUMIFS(入金入力_レジデンス!$D$4:$D$103,入金入力_レジデンス!$A$4:$A$103,A10) -> 0 | C10: =SUMIFS(未払一覧_レジデンス!$N$4:$N$103,未払一覧_レジデンス!$M$4:$M$103,A10) -> 0 | D10: =B10-C10-F10 -> 0 | E10: =E9+D10 -> 0 | F10: =SUMIFS(カード枠回復_レジデンス!$C$4:$C$53,カード枠回復_レジデンス!$A$4:$A$53,A10) -> 0 | G10: =G9+D10+F10 -> 0
A11: 46211 | B11: =SUMIFS(入金入力_レジデンス!$D$4:$D$103,入金入力_レジデンス!$A$4:$A$103,A11) -> 0 | C11: =SUMIFS(未払一覧_レジデンス!$N$4:$N$103,未払一覧_レジデンス!$M$4:$M$103,A11) -> 0 | D11: =B11-C11-F11 -> 0 | E11: =E10+D11 -> 0 | F11: =SUMIFS(カード枠回復_レジデンス!$C$4:$C$53,カード枠回復_レジデンス!$A$4:$A$53,A11) -> 0 | G11: =G10+D11+F11 -> 0
A12: 46212 | B12: =SUMIFS(入金入力_レジデンス!$D$4:$D$103,入金入力_レジデンス!$A$4:$A$103,A12) -> 0 | C12: =SUMIFS(未払一覧_レジデンス!$N$4:$N$103,未払一覧_レジデンス!$M$4:$M$103,A12) -> 0 | D12: =B12-C12-F12 -> 0 | E12: =E11+D12 -> 0 | F12: =SUMIFS(カード枠回復_レジデンス!$C$4:$C$53,カード枠回復_レジデンス!$A$4:$A$53,A12) -> 0 | G12: =G11+D12+F12 -> 0
A13: 46213 | B13: =SUMIFS(入金入力_レジデンス!$D$4:$D$103,入金入力_レジデンス!$A$4:$A$103,A13) -> 0 | C13: =SUMIFS(未払一覧_レジデンス!$N$4:$N$103,未払一覧_レジデンス!$M$4:$M$103,A13) -> 0 | D13: =B13-C13-F13 -> 0 | E13: =E12+D13 -> 0 | F13: =SUMIFS(カード枠回復_レジデンス!$C$4:$C$53,カード枠回復_レジデンス!$A$4:$A$53,A13) -> 0 | G13: =G12+D13+F13 -> 0
A14: 46214 | B14: =SUMIFS(入金入力_レジデンス!$D$4:$D$103,入金入力_レジデンス!$A$4:$A$103,A14) -> 0 | C14: =SUMIFS(未払一覧_レジデンス!$N$4:$N$103,未払一覧_レジデンス!$M$4:$M$103,A14) -> 0 | D14: =B14-C14-F14 -> 0 | E14: =E13+D14 -> 0 | F14: =SUMIFS(カード枠回復_レジデンス!$C$4:$C$53,カード枠回復_レジデンス!$A$4:$A$53,A14) -> 0 | G14: =G13+D14+F14 -> 0 | H14: 土
A15: 46215 | B15: =SUMIFS(入金入力_レジデンス!$D$4:$D$103,入金入力_レジデンス!$A$4:$A$103,A15) -> 0 | C15: =SUMIFS(未払一覧_レジデンス!$N$4:$N$103,未払一覧_レジデンス!$M$4:$M$103,A15) -> 0 | D15: =B15-C15-F15 -> 0 | E15: =E14+D15 -> 0 | F15: =SUMIFS(カード枠回復_レジデンス!$C$4:$C$53,カード枠回復_レジデンス!$A$4:$A$53,A15) -> 0 | G15: =G14+D15+F15 -> 0 | H15: 日
A16: 46216 | B16: =SUMIFS(入金入力_レジデンス!$D$4:$D$103,入金入力_レジデンス!$A$4:$A$103,A16) -> 0 | C16: =SUMIFS(未払一覧_レジデンス!$N$4:$N$103,未払一覧_レジデンス!$M$4:$M$103,A16) -> 0 | D16: =B16-C16-F16 -> 0 | E16: =E15+D16 -> 0 | F16: =SUMIFS(カード枠回復_レジデンス!$C$4:$C$53,カード枠回復_レジデンス!$A$4:$A$53,A16) -> 0 | G16: =G15+D16+F16 -> 0
A17: 46217 | B17: =SUMIFS(入金入力_レジデンス!$D$4:$D$103,入金入力_レジデンス!$A$4:$A$103,A17) -> 0 | C17: =SUMIFS(未払一覧_レジデンス!$N$4:$N$103,未払一覧_レジデンス!$M$4:$M$103,A17) -> 0 | D17: =B17-C17-F17 -> 0 | E17: =E16+D17 -> 0 | F17: =SUMIFS(カード枠回復_レジデンス!$C$4:$C$53,カード枠回復_レジデンス!$A$4:$A$53,A17) -> 0 | G17: =G16+D17+F17 -> 0
A18: 46218 | B18: =SUMIFS(入金入力_レジデンス!$D$4:$D$103,入金入力_レジデンス!$A$4:$A$103,A18) -> 0 | C18: =SUMIFS(未払一覧_レジデンス!$N$4:$N$103,未払一覧_レジデンス!$M$4:$M$103,A18) -> 0 | D18: =B18-C18-F18 -> 0 | E18: =E17+D18 -> 0 | F18: =SUMIFS(カード枠回復_レジデンス!$C$4:$C$53,カード枠回復_レジデンス!$A$4:$A$53,A18) -> 0 | G18: =G17+D18+F18 -> 0
A19: 46219 | B19: =SUMIFS(入金入力_レジデンス!$D$4:$D$103,入金入力_レジデンス!$A$4:$A$103,A19) -> 0 | C19: =SUMIFS(未払一覧_レジデンス!$N$4:$N$103,未払一覧_レジデンス!$M$4:$M$103,A19) -> 0 | D19: =B19-C19-F19 -> 0 | E19: =E18+D19 -> 0 | F19: =SUMIFS(カード枠回復_レジデンス!$C$4:$C$53,カード枠回復_レジデンス!$A$4:$A$53,A19) -> 0 | G19: =G18+D19+F19 -> 0
A20: 46220 | B20: =SUMIFS(入金入力_レジデンス!$D$4:$D$103,入金入力_レジデンス!$A$4:$A$103,A20) -> 0 | C20: =SUMIFS(未払一覧_レジデンス!$N$4:$N$103,未払一覧_レジデンス!$M$4:$M$103,A20) -> 0 | D20: =B20-C20-F20 -> 0 | E20: =E19+D20 -> 0 | F20: =SUMIFS(カード枠回復_レジデンス!$C$4:$C$53,カード枠回復_レジデンス!$A$4:$A$53,A20) -> 0 | G20: =G19+D20+F20 -> 0
A21: 46221 | B21: =SUMIFS(入金入力_レジデンス!$D$4:$D$103,入金入力_レジデンス!$A$4:$A$103,A21) -> 0 | C21: =SUMIFS(未払一覧_レジデンス!$N$4:$N$103,未払一覧_レジデンス!$M$4:$M$103,A21) -> 0 | D21: =B21-C21-F21 -> 0 | E21: =E20+D21 -> 0 | F21: =SUMIFS(カード枠回復_レジデンス!$C$4:$C$53,カード枠回復_レジデンス!$A$4:$A$53,A21) -> 0 | G21: =G20+D21+F21 -> 0 | H21: 土
A22: 46222 | B22: =SUMIFS(入金入力_レジデンス!$D$4:$D$103,入金入力_レジデンス!$A$4:$A$103,A22) -> 0 | C22: =SUMIFS(未払一覧_レジデンス!$N$4:$N$103,未払一覧_レジデンス!$M$4:$M$103,A22) -> 0 | D22: =B22-C22-F22 -> 0 | E22: =E21+D22 -> 0 | F22: =SUMIFS(カード枠回復_レジデンス!$C$4:$C$53,カード枠回復_レジデンス!$A$4:$A$53,A22) -> 0 | G22: =G21+D22+F22 -> 0 | H22: 日
A23: 46223 | B23: =SUMIFS(入金入力_レジデンス!$D$4:$D$103,入金入力_レジデンス!$A$4:$A$103,A23) -> 0 | C23: =SUMIFS(未払一覧_レジデンス!$N$4:$N$103,未払一覧_レジデンス!$M$4:$M$103,A23) -> 0 | D23: =B23-C23-F23 -> 0 | E23: =E22+D23 -> 0 | F23: =SUMIFS(カード枠回復_レジデンス!$C$4:$C$53,カード枠回復_レジデンス!$A$4:$A$53,A23) -> 0 | G23: =G22+D23+F23 -> 0
A24: 46224 | B24: =SUMIFS(入金入力_レジデンス!$D$4:$D$103,入金入力_レジデンス!$A$4:$A$103,A24) -> 0 | C24: =SUMIFS(未払一覧_レジデンス!$N$4:$N$103,未払一覧_レジデンス!$M$4:$M$103,A24) -> 0 | D24: =B24-C24-F24 -> 0 | E24: =E23+D24 -> 0 | F24: =SUMIFS(カード枠回復_レジデンス!$C$4:$C$53,カード枠回復_レジデンス!$A$4:$A$53,A24) -> 0 | G24: =G23+D24+F24 -> 0
A25: 46225 | B25: =SUMIFS(入金入力_レジデンス!$D$4:$D$103,入金入力_レジデンス!$A$4:$A$103,A25) -> 0 | C25: =SUMIFS(未払一覧_レジデンス!$N$4:$N$103,未払一覧_レジデンス!$M$4:$M$103,A25) -> 0 | D25: =B25-C25-F25 -> 0 | E25: =E24+D25 -> 0 | F25: =SUMIFS(カード枠回復_レジデンス!$C$4:$C$53,カード枠回復_レジデンス!$A$4:$A$53,A25) -> 0 | G25: =G24+D25+F25 -> 0
A26: 46226 | B26: =SUMIFS(入金入力_レジデンス!$D$4:$D$103,入金入力_レジデンス!$A$4:$A$103,A26) -> 0 | C26: =SUMIFS(未払一覧_レジデンス!$N$4:$N$103,未払一覧_レジデンス!$M$4:$M$103,A26) -> 0 | D26: =B26-C26-F26 -> 0 | E26: =E25+D26 -> 0 | F26: =SUMIFS(カード枠回復_レジデンス!$C$4:$C$53,カード枠回復_レジデンス!$A$4:$A$53,A26) -> 0 | G26: =G25+D26+F26 -> 0
A27: 46227 | B27: =SUMIFS(入金入力_レジデンス!$D$4:$D$103,入金入力_レジデンス!$A$4:$A$103,A27) -> 0 | C27: =SUMIFS(未払一覧_レジデンス!$N$4:$N$103,未払一覧_レジデンス!$M$4:$M$103,A27) -> 0 | D27: =B27-C27-F27 -> 0 | E27: =E26+D27 -> 0 | F27: =SUMIFS(カード枠回復_レジデンス!$C$4:$C$53,カード枠回復_レジデンス!$A$4:$A$53,A27) -> 0 | G27: =G26+D27+F27 -> 0
A28: 46228 | B28: =SUMIFS(入金入力_レジデンス!$D$4:$D$103,入金入力_レジデンス!$A$4:$A$103,A28) -> 0 | C28: =SUMIFS(未払一覧_レジデンス!$N$4:$N$103,未払一覧_レジデンス!$M$4:$M$103,A28) -> 0 | D28: =B28-C28-F28 -> 0 | E28: =E27+D28 -> 0 | F28: =SUMIFS(カード枠回復_レジデンス!$C$4:$C$53,カード枠回復_レジデンス!$A$4:$A$53,A28) -> 0 | G28: =G27+D28+F28 -> 0 | H28: 土
A29: 46229 | B29: =SUMIFS(入金入力_レジデンス!$D$4:$D$103,入金入力_レジデンス!$A$4:$A$103,A29) -> 0 | C29: =SUMIFS(未払一覧_レジデンス!$N$4:$N$103,未払一覧_レジデンス!$M$4:$M$103,A29) -> 0 | D29: =B29-C29-F29 -> 0 | E29: =E28+D29 -> 0 | F29: =SUMIFS(カード枠回復_レジデンス!$C$4:$C$53,カード枠回復_レジデンス!$A$4:$A$53,A29) -> 0 | G29: =G28+D29+F29 -> 0 | H29: 日
A30: 46230 | B30: =SUMIFS(入金入力_レジデンス!$D$4:$D$103,入金入力_レジデンス!$A$4:$A$103,A30) -> 0 | C30: =SUMIFS(未払一覧_レジデンス!$N$4:$N$103,未払一覧_レジデンス!$M$4:$M$103,A30) -> 0 | D30: =B30-C30-F30 -> 0 | E30: =E29+D30 -> 0 | F30: =SUMIFS(カード枠回復_レジデンス!$C$4:$C$53,カード枠回復_レジデンス!$A$4:$A$53,A30) -> 0 | G30: =G29+D30+F30 -> 0
A31: 46231 | B31: =SUMIFS(入金入力_レジデンス!$D$4:$D$103,入金入力_レジデンス!$A$4:$A$103,A31) -> 0 | C31: =SUMIFS(未払一覧_レジデンス!$N$4:$N$103,未払一覧_レジデンス!$M$4:$M$103,A31) -> 0 | D31: =B31-C31-F31 -> 0 | E31: =E30+D31 -> 0 | F31: =SUMIFS(カード枠回復_レジデンス!$C$4:$C$53,カード枠回復_レジデンス!$A$4:$A$53,A31) -> 0 | G31: =G30+D31+F31 -> 0
A32: 46232 | B32: =SUMIFS(入金入力_レジデンス!$D$4:$D$103,入金入力_レジデンス!$A$4:$A$103,A32) -> 0 | C32: =SUMIFS(未払一覧_レジデンス!$N$4:$N$103,未払一覧_レジデンス!$M$4:$M$103,A32) -> 0 | D32: =B32-C32-F32 -> 0 | E32: =E31+D32 -> 0 | F32: =SUMIFS(カード枠回復_レジデンス!$C$4:$C$53,カード枠回復_レジデンス!$A$4:$A$53,A32) -> 0 | G32: =G31+D32+F32 -> 0
A33: 46233 | B33: =SUMIFS(入金入力_レジデンス!$D$4:$D$103,入金入力_レジデンス!$A$4:$A$103,A33) -> 0 | C33: =SUMIFS(未払一覧_レジデンス!$N$4:$N$103,未払一覧_レジデンス!$M$4:$M$103,A33) -> 0 | D33: =B33-C33-F33 -> 0 | E33: =E32+D33 -> 0 | F33: =SUMIFS(カード枠回復_レジデンス!$C$4:$C$53,カード枠回復_レジデンス!$A$4:$A$53,A33) -> 0 | G33: =G32+D33+F33 -> 0
A34: 46234 | B34: =SUMIFS(入金入力_レジデンス!$D$4:$D$103,入金入力_レジデンス!$A$4:$A$103,A34) -> 0 | C34: =SUMIFS(未払一覧_レジデンス!$N$4:$N$103,未払一覧_レジデンス!$M$4:$M$103,A34) -> 0 | D34: =B34-C34-F34 -> 0 | E34: =E33+D34 -> 0 | F34: =SUMIFS(カード枠回復_レジデンス!$C$4:$C$53,カード枠回復_レジデンス!$A$4:$A$53,A34) -> 0 | G34: =G33+D34+F34 -> 0
A36: 7月合計 | B36: =SUM(B4:B34) -> 0 | C36: =SUM(C4:C34) -> 0 | D36: =B36-C36-F36 -> 0 | E36: =E34 -> 0 | F36: =SUM(F4:F34) -> 0 | G36: =G34 -> 0 | H36: 当月合計

Sheet 8月_レジデンス
A1: 8月 日次キャッシュフロー — レジデンス
A2: 入金=入金入力_レジデンス／支出=未払一覧_レジデンス（カード枠回復は除く）／使用可能額=累計差引+累計カード枠回復
A3: 日付 | B3: 入金（円） | C3: 支出（円） | D3: 日次差引（円） | E3: 累計差引（円） | F3: カード枠回復額（円） | G3: 使用可能額（円） | H3: 備考
A4: 46235 | B4: =SUMIFS(入金入力_レジデンス!$D$4:$D$103,入金入力_レジデンス!$A$4:$A$103,A4) -> 0 | C4: =SUMIFS(未払一覧_レジデンス!$N$4:$N$103,未払一覧_レジデンス!$M$4:$M$103,A4) -> 0 | D4: =B4-C4-F4 -> 0 | E4: ='7月_レジデンス'!E34+D4 -> 0 | F4: =SUMIFS(カード枠回復_レジデンス!$C$4:$C$53,カード枠回復_レジデンス!$A$4:$A$53,A4) -> 0 | G4: ='7月_レジデンス'!G34+D4+F4 -> 0 | H4: 土
A5: 46236 | B5: =SUMIFS(入金入力_レジデンス!$D$4:$D$103,入金入力_レジデンス!$A$4:$A$103,A5) -> 0 | C5: =SUMIFS(未払一覧_レジデンス!$N$4:$N$103,未払一覧_レジデンス!$M$4:$M$103,A5) -> 0 | D5: =B5-C5-F5 -> 0 | E5: =E4+D5 -> 0 | F5: =SUMIFS(カード枠回復_レジデンス!$C$4:$C$53,カード枠回復_レジデンス!$A$4:$A$53,A5) -> 0 | G5: =G4+D5+F5 -> 0 | H5: 日
A6: 46237 | B6: =SUMIFS(入金入力_レジデンス!$D$4:$D$103,入金入力_レジデンス!$A$4:$A$103,A6) -> 0 | C6: =SUMIFS(未払一覧_レジデンス!$N$4:$N$103,未払一覧_レジデンス!$M$4:$M$103,A6) -> 0 | D6: =B6-C6-F6 -> 0 | E6: =E5+D6 -> 0 | F6: =SUMIFS(カード枠回復_レジデンス!$C$4:$C$53,カード枠回復_レジデンス!$A$4:$A$53,A6) -> 0 | G6: =G5+D6+F6 -> 0
A7: 46238 | B7: =SUMIFS(入金入力_レジデンス!$D$4:$D$103,入金入力_レジデンス!$A$4:$A$103,A7) -> 0 | C7: =SUMIFS(未払一覧_レジデンス!$N$4:$N$103,未払一覧_レジデンス!$M$4:$M$103,A7) -> 0 | D7: =B7-C7-F7 -> 0 | E7: =E6+D7 -> 0 | F7: =SUMIFS(カード枠回復_レジデンス!$C$4:$C$53,カード枠回復_レジデンス!$A$4:$A$53,A7) -> 0 | G7: =G6+D7+F7 -> 0
A8: 46239 | B8: =SUMIFS(入金入力_レジデンス!$D$4:$D$103,入金入力_レジデンス!$A$4:$A$103,A8) -> 0 | C8: =SUMIFS(未払一覧_レジデンス!$N$4:$N$103,未払一覧_レジデンス!$M$4:$M$103,A8) -> 0 | D8: =B8-C8-F8 -> 0 | E8: =E7+D8 -> 0 | F8: =SUMIFS(カード枠回復_レジデンス!$C$4:$C$53,カード枠回復_レジデンス!$A$4:$A$53,A8) -> 0 | G8: =G7+D8+F8 -> 0
A9: 46240 | B9: =SUMIFS(入金入力_レジデンス!$D$4:$D$103,入金入力_レジデンス!$A$4:$A$103,A9) -> 0 | C9: =SUMIFS(未払一覧_レジデンス!$N$4:$N$103,未払一覧_レジデンス!$M$4:$M$103,A9) -> 0 | D9: =B9-C9-F9 -> 0 | E9: =E8+D9 -> 0 | F9: =SUMIFS(カード枠回復_レジデンス!$C$4:$C$53,カード枠回復_レジデンス!$A$4:$A$53,A9) -> 0 | G9: =G8+D9+F9 -> 0
A10: 46241 | B10: =SUMIFS(入金入力_レジデンス!$D$4:$D$103,入金入力_レジデンス!$A$4:$A$103,A10) -> 0 | C10: =SUMIFS(未払一覧_レジデンス!$N$4:$N$103,未払一覧_レジデンス!$M$4:$M$103,A10) -> 0 | D10: =B10-C10-F10 -> 0 | E10: =E9+D10 -> 0 | F10: =SUMIFS(カード枠回復_レジデンス!$C$4:$C$53,カード枠回復_レジデンス!$A$4:$A$53,A10) -> 0 | G10: =G9+D10+F10 -> 0
A11: 46242 | B11: =SUMIFS(入金入力_レジデンス!$D$4:$D$103,入金入力_レジデンス!$A$4:$A$103,A11) -> 0 | C11: =SUMIFS(未払一覧_レジデンス!$N$4:$N$103,未払一覧_レジデンス!$M$4:$M$103,A11) -> 0 | D11: =B11-C11-F11 -> 0 | E11: =E10+D11 -> 0 | F11: =SUMIFS(カード枠回復_レジデンス!$C$4:$C$53,カード枠回復_レジデンス!$A$4:$A$53,A11) -> 0 | G11: =G10+D11+F11 -> 0 | H11: 土
A12: 46243 | B12: =SUMIFS(入金入力_レジデンス!$D$4:$D$103,入金入力_レジデンス!$A$4:$A$103,A12) -> 0 | C12: =SUMIFS(未払一覧_レジデンス!$N$4:$N$103,未払一覧_レジデンス!$M$4:$M$103,A12) -> 0 | D12: =B12-C12-F12 -> 0 | E12: =E11+D12 -> 0 | F12: =SUMIFS(カード枠回復_レジデンス!$C$4:$C$53,カード枠回復_レジデンス!$A$4:$A$53,A12) -> 0 | G12: =G11+D12+F12 -> 0 | H12: 日
A13: 46244 | B13: =SUMIFS(入金入力_レジデンス!$D$4:$D$103,入金入力_レジデンス!$A$4:$A$103,A13) -> 0 | C13: =SUMIFS(未払一覧_レジデンス!$N$4:$N$103,未払一覧_レジデンス!$M$4:$M$103,A13) -> 0 | D13: =B13-C13-F13 -> 0 | E13: =E12+D13 -> 0 | F13: =SUMIFS(カード枠回復_レジデンス!$C$4:$C$53,カード枠回復_レジデンス!$A$4:$A$53,A13) -> 0 | G13: =G12+D13+F13 -> 0
A14: 46245 | B14: =SUMIFS(入金入力_レジデンス!$D$4:$D$103,入金入力_レジデンス!$A$4:$A$103,A14) -> 0 | C14: =SUMIFS(未払一覧_レジデンス!$N$4:$N$103,未払一覧_レジデンス!$M$4:$M$103,A14) -> 0 | D14: =B14-C14-F14 -> 0 | E14: =E13+D14 -> 0 | F14: =SUMIFS(カード枠回復_レジデンス!$C$4:$C$53,カード枠回復_レジデンス!$A$4:$A$53,A14) -> 0 | G14: =G13+D14+F14 -> 0
A15: 46246 | B15: =SUMIFS(入金入力_レジデンス!$D$4:$D$103,入金入力_レジデンス!$A$4:$A$103,A15) -> 0 | C15: =SUMIFS(未払一覧_レジデンス!$N$4:$N$103,未払一覧_レジデンス!$M$4:$M$103,A15) -> 0 | D15: =B15-C15-F15 -> 0 | E15: =E14+D15 -> 0 | F15: =SUMIFS(カード枠回復_レジデンス!$C$4:$C$53,カード枠回復_レジデンス!$A$4:$A$53,A15) -> 0 | G15: =G14+D15+F15 -> 0
